Workbook

Sheet Contracting
A1: CALCULATION FOR CITY OF FLAGSTAFF CONTRACTING TAX
A2: FILL IN BLOCKED CELLS ONLY. USE TAB KEY TO MOVE TO NEXT CELL.
A3: PLEASE COMPLETE THE FOLLOWING INFORMATION FROM THE BLANK RETURN MAILED TO YOU BY THE CITY:
A4: TAXPAYER NAME | D4: TAX RATE | E4: 0.09446
A5: MAILING ADDRESS
A6: CITY, ST ZIP
A7: CITY LICENSE NO.
A8: REPORT PERIOD
A9: DELINQUENT IF NOT RECEIVED BY
A10: BUSINESS DESCRIPTION LINE 1
A11: BUSINESS DESCRIPTION LINE 2
A12: BUS. CLASS LINE 1
A13: BUS. CLASS LINE 2
A14: SFX LINE 1
A15: SFX LINE 2
A16: PLEASE COMPLETE THE FOLLOWING INFORMATION FROM YOUR INCOME RECORDS:
... A25: STATE LAND DEDUCTION LINE 2
A26: INCOME SUBJECT TO CITY TAX: 1500 | B26: =+B17-B20-B22 -> 0
A27: INCOME SUBJECT TO CITY TAX: 1600 | B27: =+B18-B21-B23 -> 0
A28: TAX AMOUNT YOU OWE | B28: ='TPT Return Front Page'!$M$30 -> 0
A29: ENTER AMOUNT OF CHECK
A30: IN CITY JOBS SUBJECT TO CITY TPT - 1 | B30: =+B17-B20-B22 -> 0
A31: IN CITY JOBS SUBJECT TO STATE TPT - 1 | B31: =+B17-B20-B22-B24 -> 0
A32: IN CITY JOBS SUBJECT TO CITY TPT - 2 | B32: =+B18-B21-B23 -> 0
A33: IN CITY JOBS SUBJECT TO STATE TPT - 2 | B33: =+B18-B21-B23-B25 -> 0
A34: TAX FACTOR FOR 9.446% TAX RATE | B34: 0.05784724
A35: TAX FACTOR 7.725% | B35: 0.04781175
A36: CITY TAX RATE | B36: 0.01721
A37: CITY TAX ON LAND LINE 1 | B37: =ROUND((+B24*0.65*B36),2) -> 0
A38: COMMON BASE LINE 1 | B38: =+B17-B20-B22-B24-B37 -> 0
A39: CITY TAX ON LAND LINE 2 | B39: =ROUND((+B25*0.65*B36),2) -> 0
A40: COMMON BASE LINE 2 | B40: =+B18-B21-B23-B25-B39 -> 0
A41: DEDUCTIONS | B41: SUBCONTRACTOR | C41: OUT-OF-CITY | D41: LAND | E41: TAX COLLECTED | F41: STD 35%
A42: DEDUCTIONS CODE | B42: # 7 | C42: # 9 | D42: # 8 | E42: # 11 | F42: # 6
A43: LINE 1 | B43: =IF(B20="","",B20) | C43: =IF(B22="","",B22) | E43: =IF(B19="YES",IF(B26<=0,"",ROUND(((+B38*B34)+B37),2)),0) -> 0 | F43: =IF(B26<=0,"",ROUND(((+B26-E43)*0.35),2))
A44: LINE 2 | B44: =IF(B21="","",B21) | C44: =IF(B23="","",B23) | E44: =IF(B19="YES",IF(B27<=0,"",ROUND(((+B40*B34)+B39),2)),0) -> 0 | F44: =IF(B27<=0,"",ROUND(((+B27-E44)*0.35),2))
A45: PRINTING INSTRUCTIONS:
A46: 1. GO TO WORKSHEET TAB 'TPT Return Front Page' AND PRESS PRINT ICON ON THE TOOLBAR.
A47: 2. GO TO WORKSHEET TAB 'TPT Return Back Page' AND PRESS PRINT ICON ON THE TOOLBAR.
A48: 3. PRINT THIS WORKSHEET FOR YOUR RECORDS BY PRESSING THE PRINT ICON ON THE TOOLBAR.
...

Sheet TPT Return Front Page
B3: CITY OF FLAGSTAFF TRANSACTION PRIVILEGE (SALES) TAX RETURN
B4: PO BOX 22518 FLAGSTAFF, AZ 86002-2518
A7: CITY LICENSE NO. | D7: =IF(Contracting!$B$7="", "",Contracting!$B$7)
A8: REPORT PERIOD | D8: =IF(Contracting!$B$8="", "",Contracting!$B$8)
A9: THIS RETURN IS DUE ON THE 20TH OF THE MONTH
A10: DELINQUENT IF NOT RECEIVED BY
D11: =IF(Contracting!$B$9="", "",Contracting!$B$9)
A12: =IF(Contracting!$B$4="", "",Contracting!$B$4)
A13: =IF(Contracting!$B$5="", "",Contracting!$B$5)
A14: =IF(Contracting!$B$6="", "",Contracting!$B$6)
F19: Column 1 | H19: Column 2 | J19: Column 3 | L19: Column 4 | M19: Column 5
A20: Business Description | C20: Line | D20: Bus. Class | E20: Sfx | F20: Gross Income | H20: Less: Deductions | J20: =Taxable Income | L20: x Tax Rate | M20: = Tax Amount
A21: =IF(Contracting!$B$10="", "",Contracting!$B$10) | C21: 1 | D21: =IF(Contracting!$B$12="", "",Contracting!$B$12) | E21: =IF(Contracting!$B$14="", "",Contracting!$B$14) | F21: =IF(Contracting!$B$17>0,Contracting!$B$17,0) -> 0 | H21: ='TPT Return Back Page'!$F$54 -> 0 | J21: =IF((+F21-H21)>=0,(+F21-H21),"") -> 0 | L21: 0.01721 | M21: =IF(ROUND((+F21-H21),2)>=0,ROUND((+J21*L21),2),0) -> 0
A22: =IF(Contracting!$B$11="", "",Contracting!$B$11) | C22: 2 | D22: =IF(Contracting!$B$13="", "",Contracting!$B$13) | E22: =IF(Contracting!$B$15="", "",Contracting!$B$15) | F22: =IF(Contracting!$B$18>0,Contracting!$B$18,0) -> 0 | H22: ='TPT Return Back Page'!$G$54 -> 0 | J22: =IF((+F22-H22)>=0,(+F22-H22),"") -> 0 | L22: 0.01721 | M22: =IF(ROUND((+F22-H22),2)>=0,ROUND((+J22*L22),2),0) -> 0
C23: 3
C24: 4
C25: 5 | D25: TOTAL FROM ADDITIONAL PAGES
C26: 6 | D26: ENTER EXCESS CITY TAX COLLECTED | L26: Plus (+)
C27: 7 | D27: GRAND TOTAL (Add Column 5, Lines 1 Through 6) | L27: Equals (=) | M27: =SUM(M21:M26) -> 0
C28: 8 | D28: PENALTY & INTEREST (see instructions) | L28: Plus (+)
C29: 9 | D29: ENTER CREDIT BALANCE OR BALANCE DUE TO BE APPLIED | L29: Minus (-) Plus (+)
C30: 10 | D30: ENTER NET AMOUNT DUE | L30: Equals (=) | M30: =SUM(M27:M29) -> 0
C31: 11 | D31: ENTER TOTAL AMOUNT PAID | M31: =IF(Contracting!$B$29>0,Contracting!$B$29,"")
A33: Under penalties of perjury, I declare that I have examined this return and to the best of my knowledge and belief is true, correct and complete.
A34: Declaration of preparer (other than taxpayer) is based on all information of which preparer has any knowledge.
A42: THIS RETURN MUST BE FILED EVEN IF YOU HAVE NO TAXES TO REPORT
A44: Return original with remittance in envelope provided.
A45: Please make check payable to: CITY OF FLAGSTAFF and include city tax license number on your check.
A46: PLEASE DO NOT STAPLE OR TAPE PAYMENT TO YOUR RETURN. DO NOT SEND CASH.
A47: TPT-080107 | F47: www.flagstaff.az.gov

Sheet TPT Return Back Page
B1: CITY OF FLAGSTAFF, ARIZONA
B2: DUE DATE: | C2: The due date for the city privilege tax is the 20th of the month following the reporting period. A return is considered timely if received | D2: The due date for the city privilege tax is the 20th of the month following the reporting period. A return is considered timely if received
B3: by the last business day of the month. A business day is any day except Saturday, Sunday or a legal city holiday.
F4: POSTMARKS ARE NOT EVIDENCE OF TIMELY FILING.
B5: PENALTIES | C5: 1. Late Filing/Failure to File - A penalty of 5% of the tax due will be assessed for each month, or fraction elapsing between the | D5: 1. Late Filing/Failure to File - A penalty of 5% of the tax will be assessed for each month, or fraction elapsing between the
C6: delinquency date of the return and the date on which it is filed. Filing your return on time, whether or not you pay the tax due, | D6: delinquency date of the return and the date on which it is filled. Filing your return on time, whether or not you pay the tax due, will
C7: will avoid the late filing penalty. | D7: avoid the late filing penalty.
C8: 2. Failure to Pay - A penalty of 10% of the unpaid tax will be assessed if the tax is not paid timely. | D8: 2. Failure to Pay - A penalty of 10% of the unpaid tax will be assessed if the tax is not paid timely.
C9: 3. Total Penalty - Total penalties assessed will not exceed 25%. | D9: 3. Total Penalty - Total penalties assessed will not exceed 25%.
B11: INTEREST: Taxes received after the delinquency date will be assessed interest at the federal short-term rate plus three percentage points. | C11: Taxes received after the delinquency date will be assessed interest at a rate of 1% per month until paid.
B12: The interest CAN NOT be abated by the Tax Collector.
B14: CHECK YOUR RETURN Check the amounts recorded by type of income for each line item as follows.
C15: * | D15: * Itemized deductions equal the total deductions recorded.
C16: * | D16: * Taxable income equals gross income less total deductions.
C17: * | D17: * Tax due is equal to the amount obtained by applying the preprinted tax rate to the taxable income amount.
C18: * | D18: * Total tax due equals tax due plus any excess tax collected.
B20: FOR ASSISTANCE, CALL: City of Flagstaff (928) 779-7614
B21: SCHEDULE A - DETAILS OF DEDUCTIONS: Enter below the deductions and exclusions you used in computing your city transaction privilege tax.
B22: You must keep a detailed record of all deductions and exclusions. Failure to maintain proper documentation and records required by city ordinance may
B23: result in their disallowance. A separate detail of city records and documentation must be maintained only when the income, deductions or exemptions
B24: are different from state requirements.
B25: Please note: Not all deductions are available to all business classifications.
B26: NOTE: The line numbers at the top of each column below correspond with the line numbers of the business descriptions listed on the front page.
F28: Bus. Class | G28: Bus. Class | H28: Bus. Class | I28: Bus. Class
F29: =IF(Contracting!$B$12="", "",Contracting!$B$12) | G29: =IF(Contracting!$B$13="", "",Contracting!$B$13)
A30: Deductions | B30: Deductions | E30: Code | F30: LINE 1 | G30: LINE 2 | H30: LINE 3 | I30: LINE 4
A31: Total Tax Collected or Factored | B31: Total Tax Collected or Factored | E31: 11 | F31: =IF(Contracting!$E$43>0,Contracting!$E$43,"") | G31: =IF(Contracting!$E$44>0,Contracting!$E$44,"")
A33: 12 | B33: Bad Debts Write-Offs | E33: 12
A34: 3 | B34: Sales for resale | E34: 3
A35: 5 | B35: Service Labor | E35: 5
A36: 2 | B36: Returns and Discounts | E36: 2
A37: 13 | B37: Exempt Institutes | E37: 13
A38: 16 | B38: Gasoline Sales | E38: 16
A39: 4 | B39: Federal Government Sales | E39: 4
A41: 9 | B41: Out of City Sales | E41: 9 | F41: =IF(Contracting!$C$43="", "",Contracting!$C$43) | G41: =IF(Contracting!$C$44="", "",Contracting!$C$44)
A42: 10 | B42: Out of State Sales | E42: 10
A43: 8 | B43: Std 35% Contractors Deduction | E43: 6 | F43: =IF(Contracting!$F$43="", "",Contracting!$F$43) | G43: =IF(Contracting!$F$44="", "",Contracting!$F$44)
A44: 6 | B44: Subcontracting | E44: 7 | F44: =IF(Contracting!$B$43="", "",Contracting!$B$43) | G44: =IF(Contracting!$B$44="", "",Contracting!$B$44)
A45: 7 | B45: Exempt Food Sales | E45: 1
A46: 1 | B46: Prescribed Drugs | E46: 18
...
