Workbook

Sheet Info
A1: Project Information Sheet
A2: Concrete Ramps
A4: Report Number
A5: Date
A6: Project Ref. Number
A7: Project Number
A8: Contract Number
A9: Project Engineer
A10: Contractor
A11: Region
A12: County
A13: Route
... A21: Fill in the Yellow Squares and Do Not Delete This Page from the File

Sheet Page1
A1: State of Tennessee
D2: Department of Transportation
A3: Report Number | C3: =IF(Info!D4=""," ",Info!D4) | D3: Division of Materials and Tests | J3: Date | K3: =IF(Info!D5=""," ",Info!D5)
A4: Page Number | C4: 1 | D4: Ramp Concrete Pavemant Surface | K4: F53
D5: Roughness Evaluation
A7: Project Ref. No. | C7: =IF(Info!D6=""," ",Info!D6) | G7: Contract No. | I7: =IF(Info!D8=""," ",Info!D8)
A8: Project No. | C8: =IF(Info!D7=""," ",Info!D7) | G8: Region | I8: =IF(Info!D11=""," ",Info!D11)
A9: Contractor | C9: =IF(Info!D10=""," ",Info!D10) | G9: County | I9: =IF(Info!D12=""," ",Info!D12)
A10: Weather / Temp. | C10: =IF(Info!D15=""," ",Info!D15) | G10: Route | I10: =IF(Info!D13=""," ",Info!D13)
A11: Equip. Calib. Date | C11: =IF(Info!D19=""," ",Info!D19) | G11: Test Date | I11: =IF(Info!D14=""," ",Info!D14)
A12: Spec. Requirements | C12: =IF(Info!D18=""," ",Info!D18) | D12: Inches per Mile | G12: Test No. | I12: =IF(Info!D16=""," ",Info!D16)
A14: Test Performed by TDOT Road Profiler
A15: Test Limits | C15: Direction and Measured Roughness ( Inches per Mile )
A16: Feet | C16: N S E W | D16: Ramp | E16: Track 1 | F16: Pass / | G16: Track 2 | H16: Pass / | I16: Profile Index (P.I.)
A17: From | B17: To | C17: & Lane # | D17: # | E17: P.I. | F17: Fail | G17: P.I. | H17: Fail | I17: Calculation:
F18: =IF(E18=""," ",IF(E18<=Info!D18,"Pass","Fail")) | H18: =IF(G18=""," ",IF(G18<=Info!F18,"Pass","Fail")) | I18: A=5280 Divided by Total Ft. In Tests Limits
F19: =IF(E19=""," ",IF(E19<=Info!D19,"Pass","Fail")) | H19: =IF(G19=""," ",IF(G19<=Info!F19,"Pass","Fail")) | I19: B=Total Roughness of Wheel Paths
F20: =IF(E20=""," ",IF(E20<=Info!D20,"Pass","Fail")) | H20: =IF(G20=""," ",IF(G20<=Info!F20,"Pass","Fail")) | I20: P.I. = ( B/2 ) x A
F21: =IF(E21=""," ",IF(E21<=Info!D21,"Pass","Fail")) | H21: =IF(G21=""," ",IF(G21<=Info!F21,"Pass","Fail"))
F22: =IF(E22=""," ",IF(E22<=Info!D22,"Pass","Fail")) | H22: =IF(G22=""," ",IF(G22<=Info!F22,"Pass","Fail"))
F23: =IF(E23=""," ",IF(E23<=Info!D23,"Pass","Fail")) | H23: =IF(G23=""," ",IF(G23<=Info!F23,"Pass","Fail")) | I23: These Lanes
F24: =IF(E24=""," ",IF(E24<=Info!D24,"Pass","Fail")) | H24: =IF(G24=""," ",IF(G24<=Info!F24,"Pass","Fail")) | I24: =IF(A18=""," ",IF(F56=0,"Do Meet","Do Not Meet"))
F25: =IF(E25=""," ",IF(E25<=Info!D25,"Pass","Fail")) | H25: =IF(G25=""," ",IF(G25<=Info!F25,"Pass","Fail"))
F26: =IF(E26=""," ",IF(E26<=Info!D26,"Pass","Fail")) | H26: =IF(G26=""," ",IF(G26<=Info!F26,"Pass","Fail")) | I26: The Surface Roughness Requirements
F27: =IF(E27=""," ",IF(E27<=Info!D27,"Pass","Fail")) | H27: =IF(G27=""," ",IF(G27<=Info!F27,"Pass","Fail")) | I27: For Specification 501.17
F28: =IF(E28=""," ",IF(E28<=Info!D28,"Pass","Fail")) | H28: =IF(G28=""," ",IF(G28<=Info!F28,"Pass","Fail"))
F29: =IF(E29=""," ",IF(E29<=Info!D29,"Pass","Fail")) | H29: =IF(G29=""," ",IF(G29<=Info!F29,"Pass","Fail")) | I29: Remarks
F30: =IF(E30=""," ",IF(E30<=Info!D30,"Pass","Fail")) | H30: =IF(G30=""," ",IF(G30<=Info!F30,"Pass","Fail"))
F31: =IF(E31=""," ",IF(E31<=Info!D31,"Pass","Fail")) | H31: =IF(G31=""," ",IF(G31<=Info!F31,"Pass","Fail"))
F32: =IF(E32=""," ",IF(E32<=Info!D32,"Pass","Fail")) | H32: =IF(G32=""," ",IF(G32<=Info!F32,"Pass","Fail"))
F33: =IF(E33=""," ",IF(E33<=Info!D33,"Pass","Fail")) | H33: =IF(G33=""," ",IF(G33<=Info!F33,"Pass","Fail"))
F34: =IF(E34=""," ",IF(E34<=Info!D34,"Pass","Fail")) | H34: =IF(G34=""," ",IF(G34<=Info!F34,"Pass","Fail"))
F35: =IF(E35=""," ",IF(E35<=Info!D35,"Pass","Fail")) | H35: =IF(G35=""," ",IF(G35<=Info!F35,"Pass","Fail"))
F36: =IF(E36=""," ",IF(E36<=Info!D36,"Pass","Fail")) | H36: =IF(G36=""," ",IF(G36<=Info!F36,"Pass","Fail"))
F37: =IF(E37=""," ",IF(E37<=Info!D37,"Pass","Fail")) | H37: =IF(G37=""," ",IF(G37<=Info!F37,"Pass","Fail"))
F38: =IF(E38=""," ",IF(E38<=Info!D38,"Pass","Fail")) | H38: =IF(G38=""," ",IF(G38<=Info!F38,"Pass","Fail"))
F39: =IF(E39=""," ",IF(E39<=Info!D39,"Pass","Fail")) | H39: =IF(G39=""," ",IF(G39<=Info!F39,"Pass","Fail"))
F40: =IF(E40=""," ",IF(E40<=Info!D40,"Pass","Fail")) | H40: =IF(G40=""," ",IF(G40<=Info!F40,"Pass","Fail"))
F41: =IF(E41=""," ",IF(E41<=Info!D41,"Pass","Fail")) | H41: =IF(G41=""," ",IF(G41<=Info!F41,"Pass","Fail"))
... F54: =IF(E54=""," ",IF(E54<=Info!D54,"Pass","Fail")) | H54: =IF(G54=""," ",IF(G54<=Info!F54,"Pass","Fail"))
...

Sheet Page2
A1: State of Tennessee
D2: Department of Transportation
A3: Report Number | C3: =IF(Info!D4=""," ",Info!D4) | D3: Division of Materials and Tests | J3: Date | K3: =IF(Info!D5=""," ",Info!D5)
A4: Page Number | C4: 2 | D4: Ramp Concrete Pavemant Surface | K4: F53
D5: Roughness Evaluation
A7: Project Ref. No. | C7: =IF(Info!D6=""," ",Info!D6) | G7: Contract No. | I7: =IF(Info!D8=""," ",Info!D8)
A8: Project No. | C8: =IF(Info!D7=""," ",Info!D7) | G8: Region | I8: =IF(Info!D11=""," ",Info!D11)
A9: Contractor | C9: =IF(Info!D10=""," ",Info!D10) | G9: County | I9: =IF(Info!D12=""," ",Info!D12)
A10: Weather / Temp. | C10: =IF(Info!D15=""," ",Info!D15) | G10: Route | I10: =IF(Info!D13=""," ",Info!D13)
A11: Equip. Calib. Date | C11: =IF(Info!D19=""," ",Info!D19) | G11: Test Date | I11: =IF(Info!D14=""," ",Info!D14)
A12: Spec. Requirements | C12: =IF(Info!D18=""," ",Info!D18) | D12: Inches per Mile | G12: Test No. | I12: =IF(Info!D16=""," ",Info!D16)
A14: Test Performed by TDOT Road Profiler
A15: Test Limits | C15: Direction and Measured Roughness ( Inches per Mile )
A16: Feet | C16: N S E W | D16: Ramp | E16: Track 1 | F16: Pass / | G16: Track 2 | H16: Pass / | I16: Profile Index (P.I.)
A17: From | B17: To | C17: & Lane # | D17: # | E17: P.I. | F17: Fail | G17: P.I. | H17: Fail | I17: Calculation:
F18: =IF(E18=""," ",IF(E18<=Info!D18,"Pass","Fail")) | H18: =IF(G18=""," ",IF(G18<=Info!F18,"Pass","Fail")) | I18: A=5280 Divided by Total Ft. In Tests Limits
F19: =IF(E19=""," ",IF(E19<=Info!D19,"Pass","Fail")) | H19: =IF(G19=""," ",IF(G19<=Info!F19,"Pass","Fail")) | I19: B=Total Roughness of Wheel Paths
F20: =IF(E20=""," ",IF(E20<=Info!D20,"Pass","Fail")) | H20: =IF(G20=""," ",IF(G20<=Info!F20,"Pass","Fail")) | I20: P.I. = ( B/2 ) x A
F21: =IF(E21=""," ",IF(E21<=Info!D21,"Pass","Fail")) | H21: =IF(G21=""," ",IF(G21<=Info!F21,"Pass","Fail"))
F22: =IF(E22=""," ",IF(E22<=Info!D22,"Pass","Fail")) | H22: =IF(G22=""," ",IF(G22<=Info!F22,"Pass","Fail"))
F23: =IF(E23=""," ",IF(E23<=Info!D23,"Pass","Fail")) | H23: =IF(G23=""," ",IF(G23<=Info!F23,"Pass","Fail")) | I23: These Lanes
F24: =IF(E24=""," ",IF(E24<=Info!D24,"Pass","Fail")) | H24: =IF(G24=""," ",IF(G24<=Info!F24,"Pass","Fail")) | I24: =IF(A18=""," ",IF(F56=0,"Do Meet","Do Not Meet"))
F25: =IF(E25=""," ",IF(E25<=Info!D25,"Pass","Fail")) | H25: =IF(G25=""," ",IF(G25<=Info!F25,"Pass","Fail"))
F26: =IF(E26=""," ",IF(E26<=Info!D26,"Pass","Fail")) | H26: =IF(G26=""," ",IF(G26<=Info!F26,"Pass","Fail")) | I26: The Surface Roughness Requirements
F27: =IF(E27=""," ",IF(E27<=Info!D27,"Pass","Fail")) | H27: =IF(G27=""," ",IF(G27<=Info!F27,"Pass","Fail")) | I27: For Specification 501.17
F28: =IF(E28=""," ",IF(E28<=Info!D28,"Pass","Fail")) | H28: =IF(G28=""," ",IF(G28<=Info!F28,"Pass","Fail"))
F29: =IF(E29=""," ",IF(E29<=Info!D29,"Pass","Fail")) | H29: =IF(G29=""," ",IF(G29<=Info!F29,"Pass","Fail")) | I29: Remarks
F30: =IF(E30=""," ",IF(E30<=Info!D30,"Pass","Fail")) | H30: =IF(G30=""," ",IF(G30<=Info!F30,"Pass","Fail"))
F31: =IF(E31=""," ",IF(E31<=Info!D31,"Pass","Fail")) | H31: =IF(G31=""," ",IF(G31<=Info!F31,"Pass","Fail"))
F32: =IF(E32=""," ",IF(E32<=Info!D32,"Pass","Fail")) | H32: =IF(G32=""," ",IF(G32<=Info!F32,"Pass","Fail"))
F33: =IF(E33=""," ",IF(E33<=Info!D33,"Pass","Fail")) | H33: =IF(G33=""," ",IF(G33<=Info!F33,"Pass","Fail"))
F34: =IF(E34=""," ",IF(E34<=Info!D34,"Pass","Fail")) | H34: =IF(G34=""," ",IF(G34<=Info!F34,"Pass","Fail"))
F35: =IF(E35=""," ",IF(E35<=Info!D35,"Pass","Fail")) | H35: =IF(G35=""," ",IF(G35<=Info!F35,"Pass","Fail"))
F36: =IF(E36=""," ",IF(E36<=Info!D36,"Pass","Fail")) | H36: =IF(G36=""," ",IF(G36<=Info!F36,"Pass","Fail"))
F37: =IF(E37=""," ",IF(E37<=Info!D37,"Pass","Fail")) | H37: =IF(G37=""," ",IF(G37<=Info!F37,"Pass","Fail"))
F38: =IF(E38=""," ",IF(E38<=Info!D38,"Pass","Fail")) | H38: =IF(G38=""," ",IF(G38<=Info!F38,"Pass","Fail"))
F39: =IF(E39=""," ",IF(E39<=Info!D39,"Pass","Fail")) | H39: =IF(G39=""," ",IF(G39<=Info!F39,"Pass","Fail"))
F40: =IF(E40=""," ",IF(E40<=Info!D40,"Pass","Fail")) | H40: =IF(G40=""," ",IF(G40<=Info!F40,"Pass","Fail"))
F41: =IF(E41=""," ",IF(E41<=Info!D41,"Pass","Fail")) | H41: =IF(G41=""," ",IF(G41<=Info!F41,"Pass","Fail"))
... F54: =IF(E54=""," ",IF(E54<=Info!D54,"Pass","Fail")) | H54: =IF(G54=""," ",IF(G54<=Info!F54,"Pass","Fail"))
...

Sheet Page3
A1: State of Tennessee
D2: Department of Transportation
A3: Report Number | C3: =IF(Info!D4=""," ",Info!D4) | D3: Division of Materials and Tests | J3: Date | K3: =IF(Info!D5=""," ",Info!D5)
A4: Page Number | C4: 3 | D4: Ramp Concrete Pavemant Surface | K4: F53
D5: Roughness Evaluation
A7: Project Ref. No. | C7: =IF(Info!D6=""," ",Info!D6) | G7: Contract No. | I7: =IF(Info!D8=""," ",Info!D8)
A8: Project No. | C8: =IF(Info!D7=""," ",Info!D7) | G8: Region | I8: =IF(Info!D11=""," ",Info!D11)
A9: Contractor | C9: =IF(Info!D10=""," ",Info!D10) | G9: County | I9: =IF(Info!D12=""," ",Info!D12)
A10: Weather / Temp. | C10: =IF(Info!D15=""," ",Info!D15) | G10: Route | I10: =IF(Info!D13=""," ",Info!D13)
A11: Equip. Calib. Date | C11: =IF(Info!D19=""," ",Info!D19) | G11: Test Date | I11: =IF(Info!D14=""," ",Info!D14)
A12: Spec. Requirements | C12: =IF(Info!D18=""," ",Info!D18) | D12: Inches per Mile | G12: Test No. | I12: =IF(Info!D16=""," ",Info!D16)
A14: Test Performed by TDOT Road Profiler
A15: Test Limits | C15: Direction and Measured Roughness ( Inches per Mile )
A16: Feet | C16: N S E W | D16: Ramp | E16: Track 1 | F16: Pass / | G16: Track 2 | H16: Pass / | I16: Profile Index (P.I.)
A17: From | B17: To | C17: & Lane # | D17: # | E17: P.I. | F17: Fail | G17: P.I. | H17: Fail | I17: Calculation:
F18: =IF(E18=""," ",IF(E18<=Info!D18,"Pass","Fail")) | H18: =IF(G18=""," ",IF(G18<=Info!F18,"Pass","Fail")) | I18: A=5280 Divided by Total Ft. In Tests Limits
F19: =IF(E19=""," ",IF(E19<=Info!D19,"Pass","Fail")) | H19: =IF(G19=""," ",IF(G19<=Info!F19,"Pass","Fail")) | I19: B=Total Roughness of Wheel Paths
F20: =IF(E20=""," ",IF(E20<=Info!D20,"Pass","Fail")) | H20: =IF(G20=""," ",IF(G20<=Info!F20,"Pass","Fail")) | I20: P.I. = ( B/2 ) x A
F21: =IF(E21=""," ",IF(E21<=Info!D21,"Pass","Fail")) | H21: =IF(G21=""," ",IF(G21<=Info!F21,"Pass","Fail"))
F22: =IF(E22=""," ",IF(E22<=Info!D22,"Pass","Fail")) | H22: =IF(G22=""," ",IF(G22<=Info!F22,"Pass","Fail"))
F23: =IF(E23=""," ",IF(E23<=Info!D23,"Pass","Fail")) | H23: =IF(G23=""," ",IF(G23<=Info!F23,"Pass","Fail")) | I23: These Lanes
F24: =IF(E24=""," ",IF(E24<=Info!D24,"Pass","Fail")) | H24: =IF(G24=""," ",IF(G24<=Info!F24,"Pass","Fail")) | I24: =IF(A18=""," ",IF(F56=0,"Do Meet","Do Not Meet"))
F25: =IF(E25=""," ",IF(E25<=Info!D25,"Pass","Fail")) | H25: =IF(G25=""," ",IF(G25<=Info!F25,"Pass","Fail"))
F26: =IF(E26=""," ",IF(E26<=Info!D26,"Pass","Fail")) | H26: =IF(G26=""," ",IF(G26<=Info!F26,"Pass","Fail")) | I26: The Surface Roughness Requirements
F27: =IF(E27=""," ",IF(E27<=Info!D27,"Pass","Fail")) | H27: =IF(G27=""," ",IF(G27<=Info!F27,"Pass","Fail")) | I27: For Specification 501.17
F28: =IF(E28=""," ",IF(E28<=Info!D28,"Pass","Fail")) | H28: =IF(G28=""," ",IF(G28<=Info!F28,"Pass","Fail"))
F29: =IF(E29=""," ",IF(E29<=Info!D29,"Pass","Fail")) | H29: =IF(G29=""," ",IF(G29<=Info!F29,"Pass","Fail")) | I29: Remarks
F30: =IF(E30=""," ",IF(E30<=Info!D30,"Pass","Fail")) | H30: =IF(G30=""," ",IF(G30<=Info!F30,"Pass","Fail"))
F31: =IF(E31=""," ",IF(E31<=Info!D31,"Pass","Fail")) | H31: =IF(G31=""," ",IF(G31<=Info!F31,"Pass","Fail"))
F32: =IF(E32=""," ",IF(E32<=Info!D32,"Pass","Fail")) | H32: =IF(G32=""," ",IF(G32<=Info!F32,"Pass","Fail"))
F33: =IF(E33=""," ",IF(E33<=Info!D33,"Pass","Fail")) | H33: =IF(G33=""," ",IF(G33<=Info!F33,"Pass","Fail"))
F34: =IF(E34=""," ",IF(E34<=Info!D34,"Pass","Fail")) | H34: =IF(G34=""," ",IF(G34<=Info!F34,"Pass","Fail"))
F35: =IF(E35=""," ",IF(E35<=Info!D35,"Pass","Fail")) | H35: =IF(G35=""," ",IF(G35<=Info!F35,"Pass","Fail"))
F36: =IF(E36=""," ",IF(E36<=Info!D36,"Pass","Fail")) | H36: =IF(G36=""," ",IF(G36<=Info!F36,"Pass","Fail"))
F37: =IF(E37=""," ",IF(E37<=Info!D37,"Pass","Fail")) | H37: =IF(G37=""," ",IF(G37<=Info!F37,"Pass","Fail"))
F38: =IF(E38=""," ",IF(E38<=Info!D38,"Pass","Fail")) | H38: =IF(G38=""," ",IF(G38<=Info!F38,"Pass","Fail"))
F39: =IF(E39=""," ",IF(E39<=Info!D39,"Pass","Fail")) | H39: =IF(G39=""," ",IF(G39<=Info!F39,"Pass","Fail"))
F40: =IF(E40=""," ",IF(E40<=Info!D40,"Pass","Fail")) | H40: =IF(G40=""," ",IF(G40<=Info!F40,"Pass","Fail"))
F41: =IF(E41=""," ",IF(E41<=Info!D41,"Pass","Fail")) | H41: =IF(G41=""," ",IF(G41<=Info!F41,"Pass","Fail"))
... F54: =IF(E54=""," ",IF(E54<=Info!D54,"Pass","Fail")) | H54: =IF(G54=""," ",IF(G54<=Info!F54,"Pass","Fail"))
...

Sheet Page4
A1: State of Tennessee
D2: Department of Transportation
A3: Report Number | C3: =IF(Info!D4=""," ",Info!D4) | D3: Division of Materials and Tests | J3: Date | K3: =IF(Info!D5=""," ",Info!D5)
A4: Page Number | C4: 4 | D4: Ramp Concrete Pavemant Surface | K4: F53
D5: Roughness Evaluation
A7: Project Ref. No. | C7: =IF(Info!D6=""," ",Info!D6) | G7: Contract No. | I7: =IF(Info!D8=""," ",Info!D8)
A8: Project No. | C8: =IF(Info!D7=""," ",Info!D7) | G8: Region | I8: =IF(Info!D11=""," ",Info!D11)
A9: Contractor | C9: =IF(Info!D10=""," ",Info!D10) | G9: County | I9: =IF(Info!D12=""," ",Info!D12)
A10: Weather / Temp. | C10: =IF(Info!D15=""," ",Info!D15) | G10: Route | I10: =IF(Info!D13=""," ",Info!D13)
A11: Equip. Calib. Date | C11: =IF(Info!D19=""," ",Info!D19) | G11: Test Date | I11: =IF(Info!D14=""," ",Info!D14)
A12: Spec. Requirements | C12: =IF(Info!D18=""," ",Info!D18) | D12: Inches per Mile | G12: Test No. | I12: =IF(Info!D16=""," ",Info!D16)
A14: Test Performed by TDOT Road Profiler
A15: Test Limits | C15: Direction and Measured Roughness ( Inches per Mile )
A16: Feet | C16: N S E W | D16: Ramp | E16: Track 1 | F16: Pass / | G16: Track 2 | H16: Pass / | I16: Profile Index (P.I.)
A17: From | B17: To | C17: & Lane # | D17: # | E17: P.I. | F17: Fail | G17: P.I. | H17: Fail | I17: Calculation:
F18: =IF(E18=""," ",IF(E18<=Info!D18,"Pass","Fail")) | H18: =IF(G18=""," ",IF(G18<=Info!F18,"Pass","Fail")) | I18: A=5280 Divided by Total Ft. In Tests Limits
F19: =IF(E19=""," ",IF(E19<=Info!D19,"Pass","Fail")) | H19: =IF(G19=""," ",IF(G19<=Info!F19,"Pass","Fail")) | I19: B=Total Roughness of Wheel Paths
F20: =IF(E20=""," ",IF(E20<=Info!D20,"Pass","Fail")) | H20: =IF(G20=""," ",IF(G20<=Info!F20,"Pass","Fail")) | I20: P.I. = ( B/2 ) x A
F21: =IF(E21=""," ",IF(E21<=Info!D21,"Pass","Fail")) | H21: =IF(G21=""," ",IF(G21<=Info!F21,"Pass","Fail"))
F22: =IF(E22=""," ",IF(E22<=Info!D22,"Pass","Fail")) | H22: =IF(G22=""," ",IF(G22<=Info!F22,"Pass","Fail"))
F23: =IF(E23=""," ",IF(E23<=Info!D23,"Pass","Fail")) | H23: =IF(G23=""," ",IF(G23<=Info!F23,"Pass","Fail")) | I23: These Lanes
F24: =IF(E24=""," ",IF(E24<=Info!D24,"Pass","Fail")) | H24: =IF(G24=""," ",IF(G24<=Info!F24,"Pass","Fail")) | I24: =IF(A18=""," ",IF(F56=0,"Do Meet","Do Not Meet"))
F25: =IF(E25=""," ",IF(E25<=Info!D25,"Pass","Fail")) | H25: =IF(G25=""," ",IF(G25<=Info!F25,"Pass","Fail"))
F26: =IF(E26=""," ",IF(E26<=Info!D26,"Pass","Fail")) | H26: =IF(G26=""," ",IF(G26<=Info!F26,"Pass","Fail")) | I26: The Surface Roughness Requirements
F27: =IF(E27=""," ",IF(E27<=Info!D27,"Pass","Fail")) | H27: =IF(G27=""," ",IF(G27<=Info!F27,"Pass","Fail")) | I27: For Specification 501.17
F28: =IF(E28=""," ",IF(E28<=Info!D28,"Pass","Fail")) | H28: =IF(G28=""," ",IF(G28<=Info!F28,"Pass","Fail"))
F29: =IF(E29=""," ",IF(E29<=Info!D29,"Pass","Fail")) | H29: =IF(G29=""," ",IF(G29<=Info!F29,"Pass","Fail")) | I29: Remarks
F30: =IF(E30=""," ",IF(E30<=Info!D30,"Pass","Fail")) | H30: =IF(G30=""," ",IF(G30<=Info!F30,"Pass","Fail"))
F31: =IF(E31=""," ",IF(E31<=Info!D31,"Pass","Fail")) | H31: =IF(G31=""," ",IF(G31<=Info!F31,"Pass","Fail"))
F32: =IF(E32=""," ",IF(E32<=Info!D32,"Pass","Fail")) | H32: =IF(G32=""," ",IF(G32<=Info!F32,"Pass","Fail"))
F33: =IF(E33=""," ",IF(E33<=Info!D33,"Pass","Fail")) | H33: =IF(G33=""," ",IF(G33<=Info!F33,"Pass","Fail"))
F34: =IF(E34=""," ",IF(E34<=Info!D34,"Pass","Fail")) | H34: =IF(G34=""," ",IF(G34<=Info!F34,"Pass","Fail"))
F35: =IF(E35=""," ",IF(E35<=Info!D35,"Pass","Fail")) | H35: =IF(G35=""," ",IF(G35<=Info!F35,"Pass","Fail"))
F36: =IF(E36=""," ",IF(E36<=Info!D36,"Pass","Fail")) | H36: =IF(G36=""," ",IF(G36<=Info!F36,"Pass","Fail"))
F37: =IF(E37=""," ",IF(E37<=Info!D37,"Pass","Fail")) | H37: =IF(G37=""," ",IF(G37<=Info!F37,"Pass","Fail"))
F38: =IF(E38=""," ",IF(E38<=Info!D38,"Pass","Fail")) | H38: =IF(G38=""," ",IF(G38<=Info!F38,"Pass","Fail"))
F39: =IF(E39=""," ",IF(E39<=Info!D39,"Pass","Fail")) | H39: =IF(G39=""," ",IF(G39<=Info!F39,"Pass","Fail"))
F40: =IF(E40=""," ",IF(E40<=Info!D40,"Pass","Fail")) | H40: =IF(G40=""," ",IF(G40<=Info!F40,"Pass","Fail"))
F41: =IF(E41=""," ",IF(E41<=Info!D41,"Pass","Fail")) | H41: =IF(G41=""," ",IF(G41<=Info!F41,"Pass","Fail"))
... F54: =IF(E54=""," ",IF(E54<=Info!D54,"Pass","Fail")) | H54: =IF(G54=""," ",IF(G54<=Info!F54,"Pass","Fail"))
...

Sheet Page5
A1: State of Tennessee
D2: Department of Transportation
A3: Report Number | C3: =IF(Info!D4=""," ",Info!D4) | D3: Division of Materials and Tests | J3: Date | K3: =IF(Info!D5=""," ",Info!D5)
A4: Page Number | C4: 5 | D4: Ramp Concrete Pavemant Surface | K4: F53
D5: Roughness Evaluation
A7: Project Ref. No. | C7: =IF(Info!D6=""," ",Info!D6) | G7: Contract No. | I7: =IF(Info!D8=""," ",Info!D8)
A8: Project No. | C8: =IF(Info!D7=""," ",Info!D7) | G8: Region | I8: =IF(Info!D11=""," ",Info!D11)
A9: Contractor | C9: =IF(Info!D10=""," ",Info!D10) | G9: County | I9: =IF(Info!D12=""," ",Info!D12)
A10: Weather / Temp. | C10: =IF(Info!D15=""," ",Info!D15) | G10: Route | I10: =IF(Info!D13=""," ",Info!D13)
A11: Equip. Calib. Date | C11: =IF(Info!D19=""," ",Info!D19) | G11: Test Date | I11: =IF(Info!D14=""," ",Info!D14)
A12: Spec. Requirements | C12: =IF(Info!D18=""," ",Info!D18) | D12: Inches per Mile | G12: Test No. | I12: =IF(Info!D16=""," ",Info!D16)
A14: Test Performed by TDOT Road Profiler
A15: Test Limits | C15: Direction and Measured Roughness ( Inches per Mile )
A16: Feet | C16: N S E W | D16: Ramp | E16: Track 1 | F16: Pass / | G16: Track 2 | H16: Pass / | I16: Profile Index (P.I.)
A17: From | B17: To | C17: & Lane # | D17: # | E17: P.I. | F17: Fail | G17: P.I. | H17: Fail | I17: Calculation:
F18: =IF(E18=""," ",IF(E18<=Info!D18,"Pass","Fail")) | H18: =IF(G18=""," ",IF(G18<=Info!F18,"Pass","Fail")) | I18: A=5280 Divided by Total Ft. In Tests Limits
F19: =IF(E19=""," ",IF(E19<=Info!D19,"Pass","Fail")) | H19: =IF(G19=""," ",IF(G19<=Info!F19,"Pass","Fail")) | I19: B=Total Roughness of Wheel Paths
F20: =IF(E20=""," ",IF(E20<=Info!D20,"Pass","Fail")) | H20: =IF(G20=""," ",IF(G20<=Info!F20,"Pass","Fail")) | I20: P.I. = ( B/2 ) x A
F21: =IF(E21=""," ",IF(E21<=Info!D21,"Pass","Fail")) | H21: =IF(G21=""," ",IF(G21<=Info!F21,"Pass","Fail"))
F22: =IF(E22=""," ",IF(E22<=Info!D22,"Pass","Fail")) | H22: =IF(G22=""," ",IF(G22<=Info!F22,"Pass","Fail"))
F23: =IF(E23=""," ",IF(E23<=Info!D23,"Pass","Fail")) | H23: =IF(G23=""," ",IF(G23<=Info!F23,"Pass","Fail")) | I23: These Lanes
F24: =IF(E24=""," ",IF(E24<=Info!D24,"Pass","Fail")) | H24: =IF(G24=""," ",IF(G24<=Info!F24,"Pass","Fail")) | I24: =IF(A18=""," ",IF(F56=0,"Do Meet","Do Not Meet"))
F25: =IF(E25=""," ",IF(E25<=Info!D25,"Pass","Fail")) | H25: =IF(G25=""," ",IF(G25<=Info!F25,"Pass","Fail"))
F26: =IF(E26=""," ",IF(E26<=Info!D26,"Pass","Fail")) | H26: =IF(G26=""," ",IF(G26<=Info!F26,"Pass","Fail")) | I26: The Surface Roughness Requirements
F27: =IF(E27=""," ",IF(E27<=Info!D27,"Pass","Fail")) | H27: =IF(G27=""," ",IF(G27<=Info!F27,"Pass","Fail")) | I27: For Specification 501.17
F28: =IF(E28=""," ",IF(E28<=Info!D28,"Pass","Fail")) | H28: =IF(G28=""," ",IF(G28<=Info!F28,"Pass","Fail"))
F29: =IF(E29=""," ",IF(E29<=Info!D29,"Pass","Fail")) | H29: =IF(G29=""," ",IF(G29<=Info!F29,"Pass","Fail")) | I29: Remarks
F30: =IF(E30=""," ",IF(E30<=Info!D30,"Pass","Fail")) | H30: =IF(G30=""," ",IF(G30<=Info!F30,"Pass","Fail"))
F31: =IF(E31=""," ",IF(E31<=Info!D31,"Pass","Fail")) | H31: =IF(G31=""," ",IF(G31<=Info!F31,"Pass","Fail"))
F32: =IF(E32=""," ",IF(E32<=Info!D32,"Pass","Fail")) | H32: =IF(G32=""," ",IF(G32<=Info!F32,"Pass","Fail"))
F33: =IF(E33=""," ",IF(E33<=Info!D33,"Pass","Fail")) | H33: =IF(G33=""," ",IF(G33<=Info!F33,"Pass","Fail"))
F34: =IF(E34=""," ",IF(E34<=Info!D34,"Pass","Fail")) | H34: =IF(G34=""," ",IF(G34<=Info!F34,"Pass","Fail"))
F35: =IF(E35=""," ",IF(E35<=Info!D35,"Pass","Fail")) | H35: =IF(G35=""," ",IF(G35<=Info!F35,"Pass","Fail"))
F36: =IF(E36=""," ",IF(E36<=Info!D36,"Pass","Fail")) | H36: =IF(G36=""," ",IF(G36<=Info!F36,"Pass","Fail"))
F37: =IF(E37=""," ",IF(E37<=Info!D37,"Pass","Fail")) | H37: =IF(G37=""," ",IF(G37<=Info!F37,"Pass","Fail"))
F38: =IF(E38=""," ",IF(E38<=Info!D38,"Pass","Fail")) | H38: =IF(G38=""," ",IF(G38<=Info!F38,"Pass","Fail"))
F39: =IF(E39=""," ",IF(E39<=Info!D39,"Pass","Fail")) | H39: =IF(G39=""," ",IF(G39<=Info!F39,"Pass","Fail"))
F40: =IF(E40=""," ",IF(E40<=Info!D40,"Pass","Fail")) | H40: =IF(G40=""," ",IF(G40<=Info!F40,"Pass","Fail"))
F41: =IF(E41=""," ",IF(E41<=Info!D41,"Pass","Fail")) | H41: =IF(G41=""," ",IF(G41<=Info!F41,"Pass","Fail"))
... F54: =IF(E54=""," ",IF(E54<=Info!D54,"Pass","Fail")) | H54: =IF(G54=""," ",IF(G54<=Info!F54,"Pass","Fail"))
...

Sheet Page6
A1: State of Tennessee
D2: Department of Transportation
A3: Report Number | C3: =IF(Info!D4=""," ",Info!D4) | D3: Division of Materials and Tests | J3: Date | K3: =IF(Info!D5=""," ",Info!D5)
A4: Page Number | C4: 6 | D4: Ramp Concrete Pavemant Surface | K4: F53
D5: Roughness Evaluation
A7: Project Ref. No. | C7: =IF(Info!D6=""," ",Info!D6) | G7: Contract No. | I7: =IF(Info!D8=""," ",Info!D8)
A8: Project No. | C8: =IF(Info!D7=""," ",Info!D7) | G8: Region | I8: =IF(Info!D11=""," ",Info!D11)
A9: Contractor | C9: =IF(Info!D10=""," ",Info!D10) | G9: County | I9: =IF(Info!D12=""," ",Info!D12)
A10: Weather / Temp. | C10: =IF(Info!D15=""," ",Info!D15) | G10: Route | I10: =IF(Info!D13=""," ",Info!D13)
A11: Equip. Calib. Date | C11: =IF(Info!D19=""," ",Info!D19) | G11: Test Date | I11: =IF(Info!D14=""," ",Info!D14)
A12: Spec. Requirements | C12: =IF(Info!D18=""," ",Info!D18) | D12: Inches per Mile | G12: Test No. | I12: =IF(Info!D16=""," ",Info!D16)
A14: Test Performed by TDOT Road Profiler
A15: Test Limits | C15: Direction and Measured Roughness ( Inches per Mile )
A16: Feet | C16: N S E W | D16: Ramp | E16: Track 1 | F16: Pass / | G16: Track 2 | H16: Pass / | I16: Profile Index (P.I.)
A17: From | B17: To | C17: & Lane # | D17: # | E17: P.I. | F17: Fail | G17: P.I. | H17: Fail | I17: Calculation:
F18: =IF(E18=""," ",IF(E18<=Info!D18,"Pass","Fail")) | H18: =IF(G18=""," ",IF(G18<=Info!F18,"Pass","Fail")) | I18: A=5280 Divided by Total Ft. In Tests Limits
F19: =IF(E19=""," ",IF(E19<=Info!D19,"Pass","Fail")) | H19: =IF(G19=""," ",IF(G19<=Info!F19,"Pass","Fail")) | I19: B=Total Roughness of Wheel Paths
F20: =IF(E20=""," ",IF(E20<=Info!D20,"Pass","Fail")) | H20: =IF(G20=""," ",IF(G20<=Info!F20,"Pass","Fail")) | I20: P.I. = ( B/2 ) x A
F21: =IF(E21=""," ",IF(E21<=Info!D21,"Pass","Fail")) | H21: =IF(G21=""," ",IF(G21<=Info!F21,"Pass","Fail"))
F22: =IF(E22=""," ",IF(E22<=Info!D22,"Pass","Fail")) | H22: =IF(G22=""," ",IF(G22<=Info!F22,"Pass","Fail"))
F23: =IF(E23=""," ",IF(E23<=Info!D23,"Pass","Fail")) | H23: =IF(G23=""," ",IF(G23<=Info!F23,"Pass","Fail")) | I23: These Lanes
F24: =IF(E24=""," ",IF(E24<=Info!D24,"Pass","Fail")) | H24: =IF(G24=""," ",IF(G24<=Info!F24,"Pass","Fail")) | I24: =IF(A18=""," ",IF(F56=0,"Do Meet","Do Not Meet"))
F25: =IF(E25=""," ",IF(E25<=Info!D25,"Pass","Fail")) | H25: =IF(G25=""," ",IF(G25<=Info!F25,"Pass","Fail"))
F26: =IF(E26=""," ",IF(E26<=Info!D26,"Pass","Fail")) | H26: =IF(G26=""," ",IF(G26<=Info!F26,"Pass","Fail")) | I26: The Surface Roughness Requirements
F27: =IF(E27=""," ",IF(E27<=Info!D27,"Pass","Fail")) | H27: =IF(G27=""," ",IF(G27<=Info!F27,"Pass","Fail")) | I27: For Specification 501.17
F28: =IF(E28=""," ",IF(E28<=Info!D28,"Pass","Fail")) | H28: =IF(G28=""," ",IF(G28<=Info!F28,"Pass","Fail"))
F29: =IF(E29=""," ",IF(E29<=Info!D29,"Pass","Fail")) | H29: =IF(G29=""," ",IF(G29<=Info!F29,"Pass","Fail")) | I29: Remarks
F30: =IF(E30=""," ",IF(E30<=Info!D30,"Pass","Fail")) | H30: =IF(G30=""," ",IF(G30<=Info!F30,"Pass","Fail"))
F31: =IF(E31=""," ",IF(E31<=Info!D31,"Pass","Fail")) | H31: =IF(G31=""," ",IF(G31<=Info!F31,"Pass","Fail"))
F32: =IF(E32=""," ",IF(E32<=Info!D32,"Pass","Fail")) | H32: =IF(G32=""," ",IF(G32<=Info!F32,"Pass","Fail"))
F33: =IF(E33=""," ",IF(E33<=Info!D33,"Pass","Fail")) | H33: =IF(G33=""," ",IF(G33<=Info!F33,"Pass","Fail"))
F34: =IF(E34=""," ",IF(E34<=Info!D34,"Pass","Fail")) | H34: =IF(G34=""," ",IF(G34<=Info!F34,"Pass","Fail"))
F35: =IF(E35=""," ",IF(E35<=Info!D35,"Pass","Fail")) | H35: =IF(G35=""," ",IF(G35<=Info!F35,"Pass","Fail"))
F36: =IF(E36=""," ",IF(E36<=Info!D36,"Pass","Fail")) | H36: =IF(G36=""," ",IF(G36<=Info!F36,"Pass","Fail"))
F37: =IF(E37=""," ",IF(E37<=Info!D37,"Pass","Fail")) | H37: =IF(G37=""," ",IF(G37<=Info!F37,"Pass","Fail"))
F38: =IF(E38=""," ",IF(E38<=Info!D38,"Pass","Fail")) | H38: =IF(G38=""," ",IF(G38<=Info!F38,"Pass","Fail"))
F39: =IF(E39=""," ",IF(E39<=Info!D39,"Pass","Fail")) | H39: =IF(G39=""," ",IF(G39<=Info!F39,"Pass","Fail"))
F40: =IF(E40=""," ",IF(E40<=Info!D40,"Pass","Fail")) | H40: =IF(G40=""," ",IF(G40<=Info!F40,"Pass","Fail"))
F41: =IF(E41=""," ",IF(E41<=Info!D41,"Pass","Fail")) | H41: =IF(G41=""," ",IF(G41<=Info!F41,"Pass","Fail"))
... F54: =IF(E54=""," ",IF(E54<=Info!D54,"Pass","Fail")) | H54: =IF(G54=""," ",IF(G54<=Info!F54,"Pass","Fail"))
...

Sheet Page7
A1: State of Tennessee
D2: Department of Transportation
A3: Report Number | C3: =IF(Info!D4=""," ",Info!D4) | D3: Division of Materials and Tests | J3: Date | K3: =IF(Info!D5=""," ",Info!D5)
A4: Page Number | C4: 7 | D4: Ramp Concrete Pavemant Surface | K4: F53
D5: Roughness Evaluation
A7: Project Ref. No. | C7: =IF(Info!D6=""," ",Info!D6) | G7: Contract No. | I7: =IF(Info!D8=""," ",Info!D8)
A8: Project No. | C8: =IF(Info!D7=""," ",Info!D7) | G8: Region | I8: =IF(Info!D11=""," ",Info!D11)
A9: Contractor | C9: =IF(Info!D10=""," ",Info!D10) | G9: County | I9: =IF(Info!D12=""," ",Info!D12)
A10: Weather / Temp. | C10: =IF(Info!D15=""," ",Info!D15) | G10: Route | I10: =IF(Info!D13=""," ",Info!D13)
A11: Equip. Calib. Date | C11: =IF(Info!D19=""," ",Info!D19) | G11: Test Date | I11: =IF(Info!D14=""," ",Info!D14)
A12: Spec. Requirements | C12: =IF(Info!D18=""," ",Info!D18) | D12: Inches per Mile | G12: Test No. | I12: =IF(Info!D16=""," ",Info!D16)
A14: Test Performed by TDOT Road Profiler
A15: Test Limits | C15: Direction and Measured Roughness ( Inches per Mile )
A16: Feet | C16: N S E W | D16: Ramp | E16: Track 1 | F16: Pass / | G16: Track 2 | H16: Pass / | I16: Profile Index (P.I.)
A17: From | B17: To | C17: & Lane # | D17: # | E17: P.I. | F17: Fail | G17: P.I. | H17: Fail | I17: Calculation:
F18: =IF(E18=""," ",IF(E18<=Info!D18,"Pass","Fail")) | H18: =IF(G18=""," ",IF(G18<=Info!F18,"Pass","Fail")) | I18: A=5280 Divided by Total Ft. In Tests Limits
F19: =IF(E19=""," ",IF(E19<=Info!D19,"Pass","Fail")) | H19: =IF(G19=""," ",IF(G19<=Info!F19,"Pass","Fail")) | I19: B=Total Roughness of Wheel Paths
F20: =IF(E20=""," ",IF(E20<=Info!D20,"Pass","Fail")) | H20: =IF(G20=""," ",IF(G20<=Info!F20,"Pass","Fail")) | I20: P.I. = ( B/2 ) x A
F21: =IF(E21=""," ",IF(E21<=Info!D21,"Pass","Fail")) | H21: =IF(G21=""," ",IF(G21<=Info!F21,"Pass","Fail"))
F22: =IF(E22=""," ",IF(E22<=Info!D22,"Pass","Fail")) | H22: =IF(G22=""," ",IF(G22<=Info!F22,"Pass","Fail"))
F23: =IF(E23=""," ",IF(E23<=Info!D23,"Pass","Fail")) | H23: =IF(G23=""," ",IF(G23<=Info!F23,"Pass","Fail")) | I23: These Lanes
F24: =IF(E24=""," ",IF(E24<=Info!D24,"Pass","Fail")) | H24: =IF(G24=""," ",IF(G24<=Info!F24,"Pass","Fail")) | I24: =IF(A18=""," ",IF(F56=0,"Do Meet","Do Not Meet"))
F25: =IF(E25=""," ",IF(E25<=Info!D25,"Pass","Fail")) | H25: =IF(G25=""," ",IF(G25<=Info!F25,"Pass","Fail"))
F26: =IF(E26=""," ",IF(E26<=Info!D26,"Pass","Fail")) | H26: =IF(G26=""," ",IF(G26<=Info!F26,"Pass","Fail")) | I26: The Surface Roughness Requirements
F27: =IF(E27=""," ",IF(E27<=Info!D27,"Pass","Fail")) | H27: =IF(G27=""," ",IF(G27<=Info!F27,"Pass","Fail")) | I27: For Specification 501.17
F28: =IF(E28=""," ",IF(E28<=Info!D28,"Pass","Fail")) | H28: =IF(G28=""," ",IF(G28<=Info!F28,"Pass","Fail"))
F29: =IF(E29=""," ",IF(E29<=Info!D29,"Pass","Fail")) | H29: =IF(G29=""," ",IF(G29<=Info!F29,"Pass","Fail")) | I29: Remarks
F30: =IF(E30=""," ",IF(E30<=Info!D30,"Pass","Fail")) | H30: =IF(G30=""," ",IF(G30<=Info!F30,"Pass","Fail"))
F31: =IF(E31=""," ",IF(E31<=Info!D31,"Pass","Fail")) | H31: =IF(G31=""," ",IF(G31<=Info!F31,"Pass","Fail"))
F32: =IF(E32=""," ",IF(E32<=Info!D32,"Pass","Fail")) | H32: =IF(G32=""," ",IF(G32<=Info!F32,"Pass","Fail"))
F33: =IF(E33=""," ",IF(E33<=Info!D33,"Pass","Fail")) | H33: =IF(G33=""," ",IF(G33<=Info!F33,"Pass","Fail"))
F34: =IF(E34=""," ",IF(E34<=Info!D34,"Pass","Fail")) | H34: =IF(G34=""," ",IF(G34<=Info!F34,"Pass","Fail"))
F35: =IF(E35=""," ",IF(E35<=Info!D35,"Pass","Fail")) | H35: =IF(G35=""," ",IF(G35<=Info!F35,"Pass","Fail"))
F36: =IF(E36=""," ",IF(E36<=Info!D36,"Pass","Fail")) | H36: =IF(G36=""," ",IF(G36<=Info!F36,"Pass","Fail"))
F37: =IF(E37=""," ",IF(E37<=Info!D37,"Pass","Fail")) | H37: =IF(G37=""," ",IF(G37<=Info!F37,"Pass","Fail"))
F38: =IF(E38=""," ",IF(E38<=Info!D38,"Pass","Fail")) | H38: =IF(G38=""," ",IF(G38<=Info!F38,"Pass","Fail"))
F39: =IF(E39=""," ",IF(E39<=Info!D39,"Pass","Fail")) | H39: =IF(G39=""," ",IF(G39<=Info!F39,"Pass","Fail"))
F40: =IF(E40=""," ",IF(E40<=Info!D40,"Pass","Fail")) | H40: =IF(G40=""," ",IF(G40<=Info!F40,"Pass","Fail"))
F41: =IF(E41=""," ",IF(E41<=Info!D41,"Pass","Fail")) | H41: =IF(G41=""," ",IF(G41<=Info!F41,"Pass","Fail"))
... F54: =IF(E54=""," ",IF(E54<=Info!D54,"Pass","Fail")) | H54: =IF(G54=""," ",IF(G54<=Info!F54,"Pass","Fail"))
...

Sheet Page8
A1: State of Tennessee
D2: Department of Transportation
A3: Report Number | C3: =IF(Info!D4=""," ",Info!D4) | D3: Division of Materials and Tests | J3: Date | K3: =IF(Info!D5=""," ",Info!D5)
A4: Page Number | C4: 8 | D4: Ramp Concrete Pavemant Surface | K4: F53
D5: Roughness Evaluation
A7: Project Ref. No. | C7: =IF(Info!D6=""," ",Info!D6) | G7: Contract No. | I7: =IF(Info!D8=""," ",Info!D8)
A8: Project No. | C8: =IF(Info!D7=""," ",Info!D7) | G8: Region | I8: =IF(Info!D11=""," ",Info!D11)
A9: Contractor | C9: =IF(Info!D10=""," ",Info!D10) | G9: County | I9: =IF(Info!D12=""," ",Info!D12)
A10: Weather / Temp. | C10: =IF(Info!D15=""," ",Info!D15) | G10: Route | I10: =IF(Info!D13=""," ",Info!D13)
A11: Equip. Calib. Date | C11: =IF(Info!D19=""," ",Info!D19) | G11: Test Date | I11: =IF(Info!D14=""," ",Info!D14)
A12: Spec. Requirements | C12: =IF(Info!D18=""," ",Info!D18) | D12: Inches per Mile | G12: Test No. | I12: =IF(Info!D16=""," ",Info!D16)
A14: Test Performed by TDOT Road Profiler
A15: Test Limits | C15: Direction and Measured Roughness ( Inches per Mile )
A16: Feet | C16: N S E W | D16: Ramp | E16: Track 1 | F16: Pass / | G16: Track 2 | H16: Pass / | I16: Profile Index (P.I.)
A17: From | B17: To | C17: & Lane # | D17: # | E17: P.I. | F17: Fail | G17: P.I. | H17: Fail | I17: Calculation:
F18: =IF(E18=""," ",IF(E18<=Info!D18,"Pass","Fail")) | H18: =IF(G18=""," ",IF(G18<=Info!F18,"Pass","Fail")) | I18: A=5280 Divided by Total Ft. In Tests Limits
F19: =IF(E19=""," ",IF(E19<=Info!D19,"Pass","Fail")) | H19: =IF(G19=""," ",IF(G19<=Info!F19,"Pass","Fail")) | I19: B=Total Roughness of Wheel Paths
F20: =IF(E20=""," ",IF(E20<=Info!D20,"Pass","Fail")) | H20: =IF(G20=""," ",IF(G20<=Info!F20,"Pass","Fail")) | I20: P.I. = ( B/2 ) x A
F21: =IF(E21=""," ",IF(E21<=Info!D21,"Pass","Fail")) | H21: =IF(G21=""," ",IF(G21<=Info!F21,"Pass","Fail"))
F22: =IF(E22=""," ",IF(E22<=Info!D22,"Pass","Fail")) | H22: =IF(G22=""," ",IF(G22<=Info!F22,"Pass","Fail"))
F23: =IF(E23=""," ",IF(E23<=Info!D23,"Pass","Fail")) | H23: =IF(G23=""," ",IF(G23<=Info!F23,"Pass","Fail")) | I23: These Lanes
F24: =IF(E24=""," ",IF(E24<=Info!D24,"Pass","Fail")) | H24: =IF(G24=""," ",IF(G24<=Info!F24,"Pass","Fail")) | I24: =IF(A18=""," ",IF(F56=0,"Do Meet","Do Not Meet"))
F25: =IF(E25=""," ",IF(E25<=Info!D25,"Pass","Fail")) | H25: =IF(G25=""," ",IF(G25<=Info!F25,"Pass","Fail"))
F26: =IF(E26=""," ",IF(E26<=Info!D26,"Pass","Fail")) | H26: =IF(G26=""," ",IF(G26<=Info!F26,"Pass","Fail")) | I26: The Surface Roughness Requirements
F27: =IF(E27=""," ",IF(E27<=Info!D27,"Pass","Fail")) | H27: =IF(G27=""," ",IF(G27<=Info!F27,"Pass","Fail")) | I27: For Specification 501.17
F28: =IF(E28=""," ",IF(E28<=Info!D28,"Pass","Fail")) | H28: =IF(G28=""," ",IF(G28<=Info!F28,"Pass","Fail"))
F29: =IF(E29=""," ",IF(E29<=Info!D29,"Pass","Fail")) | H29: =IF(G29=""," ",IF(G29<=Info!F29,"Pass","Fail")) | I29: Remarks
F30: =IF(E30=""," ",IF(E30<=Info!D30,"Pass","Fail")) | H30: =IF(G30=""," ",IF(G30<=Info!F30,"Pass","Fail"))
F31: =IF(E31=""," ",IF(E31<=Info!D31,"Pass","Fail")) | H31: =IF(G31=""," ",IF(G31<=Info!F31,"Pass","Fail"))
F32: =IF(E32=""," ",IF(E32<=Info!D32,"Pass","Fail")) | H32: =IF(G32=""," ",IF(G32<=Info!F32,"Pass","Fail"))
F33: =IF(E33=""," ",IF(E33<=Info!D33,"Pass","Fail")) | H33: =IF(G33=""," ",IF(G33<=Info!F33,"Pass","Fail"))
F34: =IF(E34=""," ",IF(E34<=Info!D34,"Pass","Fail")) | H34: =IF(G34=""," ",IF(G34<=Info!F34,"Pass","Fail"))
F35: =IF(E35=""," ",IF(E35<=Info!D35,"Pass","Fail")) | H35: =IF(G35=""," ",IF(G35<=Info!F35,"Pass","Fail"))
F36: =IF(E36=""," ",IF(E36<=Info!D36,"Pass","Fail")) | H36: =IF(G36=""," ",IF(G36<=Info!F36,"Pass","Fail"))
F37: =IF(E37=""," ",IF(E37<=Info!D37,"Pass","Fail")) | H37: =IF(G37=""," ",IF(G37<=Info!F37,"Pass","Fail"))
F38: =IF(E38=""," ",IF(E38<=Info!D38,"Pass","Fail")) | H38: =IF(G38=""," ",IF(G38<=Info!F38,"Pass","Fail"))
F39: =IF(E39=""," ",IF(E39<=Info!D39,"Pass","Fail")) | H39: =IF(G39=""," ",IF(G39<=Info!F39,"Pass","Fail"))
F40: =IF(E40=""," ",IF(E40<=Info!D40,"Pass","Fail")) | H40: =IF(G40=""," ",IF(G40<=Info!F40,"Pass","Fail"))
F41: =IF(E41=""," ",IF(E41<=Info!D41,"Pass","Fail")) | H41: =IF(G41=""," ",IF(G41<=Info!F41,"Pass","Fail"))
... F54: =IF(E54=""," ",IF(E54<=Info!D54,"Pass","Fail")) | H54: =IF(G54=""," ",IF(G54<=Info!F54,"Pass","Fail"))
...

Sheet Page9
A1: State of Tennessee
D2: Department of Transportation
A3: Report Number | C3: =IF(Info!D4=""," ",Info!D4) | D3: Division of Materials and Tests | J3: Date | K3: =IF(Info!D5=""," ",Info!D5)
A4: Page Number | C4: 9 | D4: Ramp Concrete Pavemant Surface | K4: F53
D5: Roughness Evaluation
A7: Project Ref. No. | C7: =IF(Info!D6=""," ",Info!D6) | G7: Contract No. | I7: =IF(Info!D8=""," ",Info!D8)
A8: Project No. | C8: =IF(Info!D7=""," ",Info!D7) | G8: Region | I8: =IF(Info!D11=""," ",Info!D11)
A9: Contractor | C9: =IF(Info!D10=""," ",Info!D10) | G9: County | I9: =IF(Info!D12=""," ",Info!D12)
A10: Weather / Temp. | C10: =IF(Info!D15=""," ",Info!D15) | G10: Route | I10: =IF(Info!D13=""," ",Info!D13)
A11: Equip. Calib. Date | C11: =IF(Info!D19=""," ",Info!D19) | G11: Test Date | I11: =IF(Info!D14=""," ",Info!D14)
A12: Spec. Requirements | C12: =IF(Info!D18=""," ",Info!D18) | D12: Inches per Mile | G12: Test No. | I12: =IF(Info!D16=""," ",Info!D16)
A14: Test Performed by TDOT Road Profiler
A15: Test Limits | C15: Direction and Measured Roughness ( Inches per Mile )
A16: Feet | C16: N S E W | D16: Ramp | E16: Track 1 | F16: Pass / | G16: Track 2 | H16: Pass / | I16: Profile Index (P.I.)
A17: From | B17: To | C17: & Lane # | D17: # | E17: P.I. | F17: Fail | G17: P.I. | H17: Fail | I17: Calculation:
F18: =IF(E18=""," ",IF(E18<=Info!D18,"Pass","Fail")) | H18: =IF(G18=""," ",IF(G18<=Info!F18,"Pass","Fail")) | I18: A=5280 Divided by Total Ft. In Tests Limits
F19: =IF(E19=""," ",IF(E19<=Info!D19,"Pass","Fail")) | H19: =IF(G19=""," ",IF(G19<=Info!F19,"Pass","Fail")) | I19: B=Total Roughness of Wheel Paths
F20: =IF(E20=""," ",IF(E20<=Info!D20,"Pass","Fail")) | H20: =IF(G20=""," ",IF(G20<=Info!F20,"Pass","Fail")) | I20: P.I. = ( B/2 ) x A
F21: =IF(E21=""," ",IF(E21<=Info!D21,"Pass","Fail")) | H21: =IF(G21=""," ",IF(G21<=Info!F21,"Pass","Fail"))
F22: =IF(E22=""," ",IF(E22<=Info!D22,"Pass","Fail")) | H22: =IF(G22=""," ",IF(G22<=Info!F22,"Pass","Fail"))
F23: =IF(E23=""," ",IF(E23<=Info!D23,"Pass","Fail")) | H23: =IF(G23=""," ",IF(G23<=Info!F23,"Pass","Fail")) | I23: These Lanes
F24: =IF(E24=""," ",IF(E24<=Info!D24,"Pass","Fail")) | H24: =IF(G24=""," ",IF(G24<=Info!F24,"Pass","Fail")) | I24: =IF(A18=""," ",IF(F56=0,"Do Meet","Do Not Meet"))
F25: =IF(E25=""," ",IF(E25<=Info!D25,"Pass","Fail")) | H25: =IF(G25=""," ",IF(G25<=Info!F25,"Pass","Fail"))
F26: =IF(E26=""," ",IF(E26<=Info!D26,"Pass","Fail")) | H26: =IF(G26=""," ",IF(G26<=Info!F26,"Pass","Fail")) | I26: The Surface Roughness Requirements
F27: =IF(E27=""," ",IF(E27<=Info!D27,"Pass","Fail")) | H27: =IF(G27=""," ",IF(G27<=Info!F27,"Pass","Fail")) | I27: For Specification 501.17
F28: =IF(E28=""," ",IF(E28<=Info!D28,"Pass","Fail")) | H28: =IF(G28=""," ",IF(G28<=Info!F28,"Pass","Fail"))
F29: =IF(E29=""," ",IF(E29<=Info!D29,"Pass","Fail")) | H29: =IF(G29=""," ",IF(G29<=Info!F29,"Pass","Fail")) | I29: Remarks
F30: =IF(E30=""," ",IF(E30<=Info!D30,"Pass","Fail")) | H30: =IF(G30=""," ",IF(G30<=Info!F30,"Pass","Fail"))
F31: =IF(E31=""," ",IF(E31<=Info!D31,"Pass","Fail")) | H31: =IF(G31=""," ",IF(G31<=Info!F31,"Pass","Fail"))
F32: =IF(E32=""," ",IF(E32<=Info!D32,"Pass","Fail")) | H32: =IF(G32=""," ",IF(G32<=Info!F32,"Pass","Fail"))
F33: =IF(E33=""," ",IF(E33<=Info!D33,"Pass","Fail")) | H33: =IF(G33=""," ",IF(G33<=Info!F33,"Pass","Fail"))
F34: =IF(E34=""," ",IF(E34<=Info!D34,"Pass","Fail")) | H34: =IF(G34=""," ",IF(G34<=Info!F34,"Pass","Fail"))
F35: =IF(E35=""," ",IF(E35<=Info!D35,"Pass","Fail")) | H35: =IF(G35=""," ",IF(G35<=Info!F35,"Pass","Fail"))
F36: =IF(E36=""," ",IF(E36<=Info!D36,"Pass","Fail")) | H36: =IF(G36=""," ",IF(G36<=Info!F36,"Pass","Fail"))
F37: =IF(E37=""," ",IF(E37<=Info!D37,"Pass","Fail")) | H37: =IF(G37=""," ",IF(G37<=Info!F37,"Pass","Fail"))
F38: =IF(E38=""," ",IF(E38<=Info!D38,"Pass","Fail")) | H38: =IF(G38=""," ",IF(G38<=Info!F38,"Pass","Fail"))
F39: =IF(E39=""," ",IF(E39<=Info!D39,"Pass","Fail")) | H39: =IF(G39=""," ",IF(G39<=Info!F39,"Pass","Fail"))
F40: =IF(E40=""," ",IF(E40<=Info!D40,"Pass","Fail")) | H40: =IF(G40=""," ",IF(G40<=Info!F40,"Pass","Fail"))
F41: =IF(E41=""," ",IF(E41<=Info!D41,"Pass","Fail")) | H41: =IF(G41=""," ",IF(G41<=Info!F41,"Pass","Fail"))
... F54: =IF(E54=""," ",IF(E54<=Info!D54,"Pass","Fail")) | H54: =IF(G54=""," ",IF(G54<=Info!F54,"Pass","Fail"))
...

Sheet Page10
A1: State of Tennessee
D2: Department of Transportation
A3: Report Number | C3: =IF(Info!D4=""," ",Info!D4) | D3: Division of Materials and Tests | J3: Date | K3: =IF(Info!D5=""," ",Info!D5)
A4: Page Number | C4: 10 | D4: Ramp Concrete Pavemant Surface | K4: F53
D5: Roughness Evaluation
A7: Project Ref. No. | C7: =IF(Info!D6=""," ",Info!D6) | G7: Contract No. | I7: =IF(Info!D8=""," ",Info!D8)
A8: Project No. | C8: =IF(Info!D7=""," ",Info!D7) | G8: Region | I8: =IF(Info!D11=""," ",Info!D11)
A9: Contractor | C9: =IF(Info!D10=""," ",Info!D10) | G9: County | I9: =IF(Info!D12=""," ",Info!D12)
A10: Weather / Temp. | C10: =IF(Info!D15=""," ",Info!D15) | G10: Route | I10: =IF(Info!D13=""," ",Info!D13)
A11: Equip. Calib. Date | C11: =IF(Info!D19=""," ",Info!D19) | G11: Test Date | I11: =IF(Info!D14=""," ",Info!D14)
A12: Spec. Requirements | C12: =IF(Info!D18=""," ",Info!D18) | D12: Inches per Mile | G12: Test No. | I12: =IF(Info!D16=""," ",Info!D16)
A14: Test Performed by TDOT Road Profiler
A15: Test Limits | C15: Direction and Measured Roughness ( Inches per Mile )
A16: Feet | C16: N S E W | D16: Ramp | E16: Track 1 | F16: Pass / | G16: Track 2 | H16: Pass / | I16: Profile Index (P.I.)
A17: From | B17: To | C17: & Lane # | D17: # | E17: P.I. | F17: Fail | G17: P.I. | H17: Fail | I17: Calculation:
F18: =IF(E18=""," ",IF(E18<=Info!D18,"Pass","Fail")) | H18: =IF(G18=""," ",IF(G18<=Info!F18,"Pass","Fail")) | I18: A=5280 Divided by Total Ft. In Tests Limits
F19: =IF(E19=""," ",IF(E19<=Info!D19,"Pass","Fail")) | H19: =IF(G19=""," ",IF(G19<=Info!F19,"Pass","Fail")) | I19: B=Total Roughness of Wheel Paths
F20: =IF(E20=""," ",IF(E20<=Info!D20,"Pass","Fail")) | H20: =IF(G20=""," ",IF(G20<=Info!F20,"Pass","Fail")) | I20: P.I. = ( B/2 ) x A
F21: =IF(E21=""," ",IF(E21<=Info!D21,"Pass","Fail")) | H21: =IF(G21=""," ",IF(G21<=Info!F21,"Pass","Fail"))
F22: =IF(E22=""," ",IF(E22<=Info!D22,"Pass","Fail")) | H22: =IF(G22=""," ",IF(G22<=Info!F22,"Pass","Fail"))
F23: =IF(E23=""," ",IF(E23<=Info!D23,"Pass","Fail")) | H23: =IF(G23=""," ",IF(G23<=Info!F23,"Pass","Fail")) | I23: These Lanes
F24: =IF(E24=""," ",IF(E24<=Info!D24,"Pass","Fail")) | H24: =IF(G24=""," ",IF(G24<=Info!F24,"Pass","Fail")) | I24: =IF(A18=""," ",IF(F56=0,"Do Meet","Do Not Meet"))
F25: =IF(E25=""," ",IF(E25<=Info!D25,"Pass","Fail")) | H25: =IF(G25=""," ",IF(G25<=Info!F25,"Pass","Fail"))
F26: =IF(E26=""," ",IF(E26<=Info!D26,"Pass","Fail")) | H26: =IF(G26=""," ",IF(G26<=Info!F26,"Pass","Fail")) | I26: The Surface Roughness Requirements
F27: =IF(E27=""," ",IF(E27<=Info!D27,"Pass","Fail")) | H27: =IF(G27=""," ",IF(G27<=Info!F27,"Pass","Fail")) | I27: For Specification 501.17
F28: =IF(E28=""," ",IF(E28<=Info!D28,"Pass","Fail")) | H28: =IF(G28=""," ",IF(G28<=Info!F28,"Pass","Fail"))
F29: =IF(E29=""," ",IF(E29<=Info!D29,"Pass","Fail")) | H29: =IF(G29=""," ",IF(G29<=Info!F29,"Pass","Fail")) | I29: Remarks
F30: =IF(E30=""," ",IF(E30<=Info!D30,"Pass","Fail")) | H30: =IF(G30=""," ",IF(G30<=Info!F30,"Pass","Fail"))
F31: =IF(E31=""," ",IF(E31<=Info!D31,"Pass","Fail")) | H31: =IF(G31=""," ",IF(G31<=Info!F31,"Pass","Fail"))
F32: =IF(E32=""," ",IF(E32<=Info!D32,"Pass","Fail")) | H32: =IF(G32=""," ",IF(G32<=Info!F32,"Pass","Fail"))
F33: =IF(E33=""," ",IF(E33<=Info!D33,"Pass","Fail")) | H33: =IF(G33=""," ",IF(G33<=Info!F33,"Pass","Fail"))
F34: =IF(E34=""," ",IF(E34<=Info!D34,"Pass","Fail")) | H34: =IF(G34=""," ",IF(G34<=Info!F34,"Pass","Fail"))
F35: =IF(E35=""," ",IF(E35<=Info!D35,"Pass","Fail")) | H35: =IF(G35=""," ",IF(G35<=Info!F35,"Pass","Fail"))
F36: =IF(E36=""," ",IF(E36<=Info!D36,"Pass","Fail")) | H36: =IF(G36=""," ",IF(G36<=Info!F36,"Pass","Fail"))
F37: =IF(E37=""," ",IF(E37<=Info!D37,"Pass","Fail")) | H37: =IF(G37=""," ",IF(G37<=Info!F37,"Pass","Fail"))
F38: =IF(E38=""," ",IF(E38<=Info!D38,"Pass","Fail")) | H38: =IF(G38=""," ",IF(G38<=Info!F38,"Pass","Fail"))
F39: =IF(E39=""," ",IF(E39<=Info!D39,"Pass","Fail")) | H39: =IF(G39=""," ",IF(G39<=Info!F39,"Pass","Fail"))
F40: =IF(E40=""," ",IF(E40<=Info!D40,"Pass","Fail")) | H40: =IF(G40=""," ",IF(G40<=Info!F40,"Pass","Fail"))
F41: =IF(E41=""," ",IF(E41<=Info!D41,"Pass","Fail")) | H41: =IF(G41=""," ",IF(G41<=Info!F41,"Pass","Fail"))
... F54: =IF(E54=""," ",IF(E54<=Info!D54,"Pass","Fail")) | H54: =IF(G54=""," ",IF(G54<=Info!F54,"Pass","Fail"))
...
