Workbook
Name date: 'Short Form'!$N$2
Name expns: 'Short Form'!$A$61:$N$62

Sheet Coding Page
B1: Expense Report Coding Form
A2: AMOUNT | B2: GL Account Number | C2: GL Co | E2: Cost Center WBS Element | H2: Order Network | J2: Material | K2: Plant
A3: ='Short Form'!N27 -> 0 | B3: ='Short Form'!A29 -> 0 | C3: ='Short Form'!B29 -> 0 | D3: ='Short Form'!C29 -> 0 | H3: ='Short Form'!G29 -> 0 | J3: ='Short Form'!I29 -> 0 | K3: ='Short Form'!J29 -> 0
D4: ='Short Form'!C30 -> 0 | H4: ='Short Form'!G30 -> 0
A5: ='Short Form'!N42 -> 0 | B5: ='Short Form'!A44 -> 0 | C5: ='Short Form'!B44 -> 0 | D5: ='Short Form'!C44 -> 0 | H5: ='Short Form'!G44 -> 0 | J5: ='Short Form'!I44 -> 0 | K5: ='Short Form'!J44 -> 0
D6: ='Short Form'!C45 -> 0 | H6: ='Short Form'!G45 -> 0
A7: ='Travel Form'!O49 -> 1709.53 | B7: ='Travel Form'!B49 -> 52004500 | C7: ='Travel Form'!C49 -> 0060 | D7: ='Travel Form'!D49:G49 -> 111102 | H7: ='Travel Form'!H49:I49 -> 0 | J7: ='Travel Form'!J49 -> 0 | K7: ='Travel Form'!K49 -> 0
D8: ='Travel Form'!D50:G50 -> 0 | H8: ='Travel Form'!H50:I50 -> 0
A9: ='Travel Form'!O51 -> 0 | B9: ='Travel Form'!B51 -> 0 | C9: ='Travel Form'!C51 -> 0 | D9: ='Travel Form'!D51:G51 -> 0 | H9: ='Travel Form'!H51:I51 -> 0 | J9: ='Travel Form'!J51 -> 0 | K9: ='Travel Form'!K51 -> 0
D10: ='Travel Form'!D52:G52 -> 0 | H10: ='Travel Form'!H52:I52 -> 0
A11: ='Travel Form'!O53 -> 0 | B11: ='Travel Form'!B53 -> 0 | C11: ='Travel Form'!C53 -> 0 | D11: ='Travel Form'!D53:G53 -> 0 | H11: ='Travel Form'!H53:I53 -> 0 | J11: ='Travel Form'!J53 -> 0 | K11: ='Travel Form'!K53 -> 0
D12: ='Travel Form'!D54:G54 -> 0 | H12: ='Travel Form'!H54:I54 -> 0
A13: ='Meals and Ent Sup'!N49 -> 484.96 | B13: ='Meals and Ent Sup'!B49 -> 52003000 | C13: ='Meals and Ent Sup'!C49 -> 0060 | D13: ='Meals and Ent Sup'!D49 -> 111102 | H13: ='Meals and Ent Sup'!H49 -> 0 | J13: ='Meals and Ent Sup'!J49 -> 9000060 | K13: ='Meals and Ent Sup'!K49 -> 0
D14: ='Meals and Ent Sup'!D50 -> 0 | H14: ='Meals and Ent Sup'!H50 -> 0
A15: ='Meals and Ent Sup'!N51 -> 0 | B15: ='Meals and Ent Sup'!B51 -> 0 | C15: ='Meals and Ent Sup'!C51 -> 0 | D15: ='Meals and Ent Sup'!D51 -> 0 | H15: ='Meals and Ent Sup'!H51 -> 0 | J15: ='Meals and Ent Sup'!J51 -> 0 | K15: ='Meals and Ent Sup'!K51 -> 0
D16: ='Meals and Ent Sup'!D52 -> 0 | H16: ='Meals and Ent Sup'!H52 -> 0
A17: ='Meals and Ent Sup'!N53 -> 0 | B17: ='Meals and Ent Sup'!B53 -> 0 | C17: ='Meals and Ent Sup'!C53 -> 0 | D17: ='Meals and Ent Sup'!D53 -> 0 | H17: ='Meals and Ent Sup'!H53 -> 0 | J17: ='Meals and Ent Sup'!J53 -> 0 | K17: ='Meals and Ent Sup'!K53 -> 0
D18: ='Meals and Ent Sup'!D54 -> 0 | H18: ='Meals and Ent Sup'!H54 -> 0
A19: ='Misc. Exp. Sup'!O49 -> 11.88 | B19: ='Misc. Exp. Sup'!B49 -> 0 | C19: ='Misc. Exp. Sup'!C49 -> 0 | D19: ='Misc. Exp. Sup'!D49 -> 0 | H19: ='Misc. Exp. Sup'!H49 -> 0 | I19: ='Misc. Exp. Sup'!I49 -> 0 | J19: ='Misc. Exp. Sup'!J49 -> 0 | K19: ='Misc. Exp. Sup'!K49 -> 0
D20: ='Misc. Exp. Sup'!D50 -> 0 | H20: ='Misc. Exp. Sup'!H50 -> 0 | I20: ='Misc. Exp. Sup'!I50 -> 0
A21: ='Misc. Exp. Sup'!O51 -> 0 | B21: ='Misc. Exp. Sup'!B51 -> 0 | C21: ='Misc. Exp. Sup'!C51 -> 0 | D21: ='Misc. Exp. Sup'!D51 -> 0 | H21: ='Misc. Exp. Sup'!H51 -> 0 | I21: ='Misc. Exp. Sup'!I51 -> 0 | J21: ='Misc. Exp. Sup'!J51 -> 0 | K21: ='Misc. Exp. Sup'!K51 -> 0
D22: ='Misc. Exp. Sup'!D52 -> 0 | H22: ='Misc. Exp. Sup'!H52 -> 0 | I22: ='Misc. Exp. Sup'!I52 -> 0
A23: ='Misc. Exp. Sup'!O53 -> 0 | B23: ='Misc. Exp. Sup'!B53 -> 0 | C23: ='Misc. Exp. Sup'!C53 -> 0 | D23: ='Misc. Exp. Sup'!D53 -> 0 | H23: ='Misc. Exp. Sup'!H53 -> 0 | I23: ='Misc. Exp. Sup'!I53 -> 0 | J23: ='Misc. Exp. Sup'!J53 -> 0 | K23: ='Misc. Exp. Sup'!K53 -> 0
D24: ='Misc. Exp. Sup'!D54 -> 0 | H24: ='Misc. Exp. Sup'!H54 -> 0 | I24: ='Misc. Exp. Sup'!I54 -> 0
A25: ='Travel Sup (2)'!O49 -> 0 | B25: ='Travel Sup (2)'!B49 -> 0 | C25: ='Travel Sup (2)'!C49 -> 0 | D25: ='Travel Sup (2)'!D49 -> 0 | H25: ='Travel Sup (2)'!H49 -> 0 | J25: ='Travel Sup (2)'!J49 -> 0 | K25: ='Travel Sup (2)'!K49 -> 0
D26: ='Travel Sup (2)'!D50 -> 0 | H26: ='Travel Sup (2)'!H50 -> 0
A27: ='Travel Sup (2)'!O51 -> 0 | B27: ='Travel Sup (2)'!B51 -> 0 | C27: ='Travel Sup (2)'!C51 -> 0 | D27: ='Travel Sup (2)'!D51 -> 0 | H27: ='Travel Sup (2)'!H51 -> 0 | J27: ='Travel Sup (2)'!J51 -> 0 | K27: ='Travel Sup (2)'!K51 -> 0
D28: ='Travel Sup (2)'!D52 -> 0 | H28: ='Travel Sup (2)'!H52 -> 0
A29: ='Travel Sup (2)'!O53 -> 0 | B29: ='Travel Sup (2)'!B53 -> 0 | C29: ='Travel Sup (2)'!C53 -> 0 | D29: ='Travel Sup (2)'!D53 -> 0 | H29: ='Travel Sup (2)'!H53 -> 0 | J29: ='Travel Sup (2)'!J53 -> 0 | K29: ='Travel Sup (2)'!K53 -> 0
D30: ='Travel Sup (2)'!D54 -> 0 | H30: ='Travel Sup (2)'!H54 -> 0
A31: ='Meals and Ent Sup (2)'!N49 -> 0 | B31: ='Meals and Ent Sup (2)'!B49 -> 0 | C31: ='Meals and Ent Sup (2)'!C49 -> 0 | D31: ='Meals and Ent Sup (2)'!D49 -> 0 | E31: ='Meals and Ent Sup (2)'!E49 -> 0 | F31: ='Meals and Ent Sup (2)'!F49 -> 0 | G31: ='Meals and Ent Sup (2)'!G49 -> 0 | H31: ='Meals and Ent Sup (2)'!H49 -> 0 | I31: ='Meals and Ent Sup (2)'!I49 -> 0 | ... K31: ='Meals and Ent Sup (2)'!K49 -> 0
D32: ='Meals and Ent Sup (2)'!D50 -> 0 | E32: ='Meals and Ent Sup (2)'!E50 -> 0 | F32: ='Meals and Ent Sup (2)'!F50 -> 0 | G32: ='Meals and Ent Sup (2)'!G50 -> 0 | H32: ='Meals and Ent Sup (2)'!H50 -> 0 | I32: ='Meals and Ent Sup (2)'!I50 -> 0
A33: ='Meals and Ent Sup (2)'!N51 -> 0 | B33: ='Meals and Ent Sup (2)'!B51 -> 0 | C33: ='Meals and Ent Sup (2)'!C51 -> 0 | D33: ='Meals and Ent Sup (2)'!D51 -> 0 | E33: ='Meals and Ent Sup (2)'!E51 -> 0 | F33: ='Meals and Ent Sup (2)'!F51 -> 0 | G33: ='Meals and Ent Sup (2)'!G51 -> 0 | H33: ='Meals and Ent Sup (2)'!H51 -> 0 | I33: ='Meals and Ent Sup (2)'!I51 -> 0 | ... K33: ='Meals and Ent Sup (2)'!K51 -> 0
D34: ='Meals and Ent Sup (2)'!D52 -> 0 | E34: ='Meals and Ent Sup (2)'!E52 -> 0 | F34: ='Meals and Ent Sup (2)'!F52 -> 0 | G34: ='Meals and Ent Sup (2)'!G52 -> 0 | H34: ='Meals and Ent Sup (2)'!H52 -> 0 | I34: ='Meals and Ent Sup (2)'!I52 -> 0
A35: ='Meals and Ent Sup (2)'!N53 -> 0 | B35: ='Meals and Ent Sup (2)'!B53 -> 0 | C35: ='Meals and Ent Sup (2)'!C53 -> 0 | D35: ='Meals and Ent Sup (2)'!D53 -> 0 | E35: ='Meals and Ent Sup (2)'!E53 -> 0 | F35: ='Meals and Ent Sup (2)'!F53 -> 0 | G35: ='Meals and Ent Sup (2)'!G53 -> 0 | H35: ='Meals and Ent Sup (2)'!H53 -> 0 | I35: ='Meals and Ent Sup (2)'!I53 -> 0 | ... K35: ='Meals and Ent Sup (2)'!K53 -> 0
D36: ='Meals and Ent Sup (2)'!D54 -> 0 | E36: ='Meals and Ent Sup (2)'!E54 -> 0 | F36: ='Meals and Ent Sup (2)'!F54 -> 0 | G36: ='Meals and Ent Sup (2)'!G54 -> 0 | H36: ='Meals and Ent Sup (2)'!H54 -> 0 | I36: ='Meals and Ent Sup (2)'!I54 -> 0
A37: ='Misc. Exp. Sup (2)'!O49 -> 0 | B37: ='Misc. Exp. Sup (2)'!B49 -> 0 | C37: ='Misc. Exp. Sup (2)'!C49 -> 0 | D37: ='Misc. Exp. Sup (2)'!D49 -> 0 | H37: ='Misc. Exp. Sup (2)'!H49 -> 0 | I37: ='Misc. Exp. Sup (2)'!J49 -> 0 | J37: ='Misc. Exp. Sup (2)'!J49 -> 0 | K37: ='Misc. Exp. Sup (2)'!K49 -> 0
D38: ='Misc. Exp. Sup (2)'!D50 -> 0 | E38: ='Misc. Exp. Sup (2)'!F50 -> 0 | F38: ='Misc. Exp. Sup (2)'!G50 -> 0 | G38: ='Misc. Exp. Sup (2)'!H50 -> 0 | H38: ='Misc. Exp. Sup (2)'!H50 -> 0 | I38: ='Misc. Exp. Sup (2)'!J50 -> 0
A39: ='Misc. Exp. Sup (2)'!O51 -> 0 | B39: ='Misc. Exp. Sup (2)'!B51 -> 0 | C39: ='Misc. Exp. Sup (2)'!C51 -> 0 | D39: ='Misc. Exp. Sup (2)'!D51 -> 0 | H39: ='Misc. Exp. Sup (2)'!H51 -> 0 | I39: ='Misc. Exp. Sup (2)'!J51 -> 0 | J39: ='Misc. Exp. Sup (2)'!J51 -> 0 | K39: ='Misc. Exp. Sup (2)'!K51 -> 0
D40: ='Misc. Exp. Sup (2)'!D52 -> 0 | E40: ='Misc. Exp. Sup (2)'!F52 -> 0 | F40: ='Misc. Exp. Sup (2)'!G52 -> 0 | G40: ='Misc. Exp. Sup (2)'!H52 -> 0 | H40: ='Misc. Exp. Sup (2)'!H52 -> 0 | I40: ='Misc. Exp. Sup (2)'!J52 -> 0
...

Sheet Short Form
D1: Enron Corp
D2: Employee Expense Report | M2: EXP | P2: =TODAY() -> 46107
D3: Short Form | K3: Page | L3: 1 | M3: of | N3: =1+VALUE(H62)+VALUE(I62)+VALUE(J62)+VALUE(K62)+VALUE(L62)+VALUE(M62) -> 4
A5: LAST NAME | E5: FIRST NAME, INITIAL | H5: TITLE | K5: EMPLOYEE NUMBER
A7: COMPANY NUMBER | E7: OFFICE NUMBER/FIELD LOCATION | K7: PHONE NUMBER FOR QUESTIONS
A10: MEALS AND ENTERTAINMENT - Enter the cost of all meals (including food charges from hotel receipts) and entertainment. Attach guest list for entertainment expense.
A11: Meal: B = Breakfast, L = Lunch, D = Dinner, R = Refreshments, T = Travel Status. See the Accounts Payable information page at http://hrweb.enron.com/accts/index.asp for detailed instructions.
A13: Date | B13: Meal | D13: Location and Business Purpose | H13: Guests | L13: Cost/Quantity | M13: Rate | N13: $ Amount
N14: =IF(M14=" ",L14*1,L14*M14) -> 0
N15: =IF(M15=" ",L15*1,L15*M15) -> 0
N16: =IF(M16=" ",L16*1,L16*M16) -> 0
N17: =IF(M17=" ",L17*1,L17*M17) -> 0
N18: =IF(M18=" ",L18*1,L18*M18) -> 0
N19: =IF(M19=" ",L19*1,L19*M19) -> 0
N20: =IF(M20=" ",L20*1,L20*M20) -> 0
N21: =IF(M21=" ",L21*1,L21*M21) -> 0
N22: =IF(M22=" ",L22*1,L22*M22) -> 0
N23: =IF(M23=" ",L23*1,L23*M23) -> 0
N24: =IF(M24=" ",L24*1,L24*M24) -> 0
N25: =IF(M25=" ",L25*1,L25*M25) -> 0
N26: =IF(M26=" ",L26*1,L26*M26) -> 0
A27: ACCOUNT CODING - For multiple lines of coding, use supplemental page. | L27: MEALS THIS PAGE | N27: =SUM(N14:N26) -> 0
A28: GL Acct Asset | B28: GL Co Tr Ptr | D28: Cost Center WBS Element | G28: Order Network | I28: Material Activity | J28: Plant Func Area | L28: MEALS, SUPP PAGES | N28: ='Meals and Ent Sup'!N55+'Meals and Ent Sup (2)'!N55 -> 484.96
L29: TOTAL MEALS | N29: =SUM(N27:N28) -> 484.96
A31: MISCELLANEOUS EXPENSE - Enter all other expenses (memberships, fees, supplies, mileage, etc.) not associated with business transportation or lodging.
A33: Date | F33: Description | L33: Cost/Quantity | M33: Rate | N33: $ Amount
N34: =IF(M34=" ",L34*1,L34*M34) -> 0
N35: =IF(M35=" ",L35*1,L35*M35) -> 0
N36: =IF(M36=" ",L36*1,L36*M36) -> 0
N37: =IF(M37=" ",L37*1,L37*M37) -> 0
N38: =IF(M38=" ",L38*1,L38*M38) -> 0
N39: =IF(M39=" ",L39*1,L39*M39) -> 0
N40: =IF(M40=" ",L40*1,L40*M40) -> 0
N41: =IF(M41=" ",L41*1,L41*M41) -> 0
A42: ACCOUNT CODING - For multiple lines of coding, use supplemental page. | L42: MISC THIS PAGE | N42: =SUM(N34:N41) -> 0
A43: GL Acct Asset | B43: GL Co Tr Ptr | D43: Cost Center WBS Element | G43: Order Network | I43: Material Activity | J43: Plant Func Area | L43: MISC., SUPP PAGES | N43: ='Misc. Exp. Sup'!O55+'Misc. Exp. Sup (2)'!O55 -> 11.88
L44: TOTAL MISC | N44: =SUM(N42:N43) -> 11.88
A48: This section used in conjunction with all expense reports. | J48: Total Travel (attach Summary) | N48: ='Travel Form'!O55+'Travel Sup (2)'!O55 -> 1709.53
A49: ADVANCES TO BE CLEARED | J49: Total Expenses (travel, entertainment, misc.) | N49: =N48+N44+N29 -> 2206.37
A50: DATE | C50: CO. | E50: AMOUNT | J50: Less: Total Advances | N50: =F53 -> 0
...

Sheet Travel Form
A1: Employee Expense Report
A2: Travel Expense Summary | M2: Page | N2: =IF(VALUE('Short Form'!H62)<>0,2,"") -> 2 | O2: =IF(N2=0,"",'Short Form'!N3) -> 4
A4: LAST NAME | E4: FIRST NAME, INITIAL | H4: TITLE | K4: EMPLOYEE NUMBER
A5: ='Short Form'!A6 -> 0 | E5: ='Short Form'!E6 -> 0 | H5: ='Short Form'!H6 -> 0 | K5: ='Short Form'!K6 -> 0
A7: TRAVEL EXPENSE - Enter all transportation and lodging expenses by receipt total (airline tickets, rental car receipts, taxis, hotel, tips, personal mileage, etc.). Exclude meals and entertainment.
A8: Designate type of transportation used: B = Bus, C = Cab, P = Plane, PC = Personal Car, CC = Company Car, RC = Rental Car, T = Train.
A9: Assign a reference symbol for each accounting classification to be used. Charges to be allocated do not require a reference symbol.
A11: REF | B11: Date | E11: Location and Business Purpose | L11: Type | M11: Cost/Miles | N11: Rate | O11: $ Amount
A12: 01 | B12: 8/14-8/18 | C12: Roswell to Albuq. To Roswell DES and Interim Review Mtg | L12: P | M12: 309 | N12: 1 | O12: =IF(N12=" ",M12*1,M12*N12) -> 309
A13: 01 | B13: 8/14-8/18 | C13: DES Interim Review | M13: 410.61 | N13: 1 | O13: =IF(N13=" ",M13*1,M13*N13) -> 410.61
A14: 01 | B14: 8/14-8/18 | C14: DES Interim Review Rental Car | L14: RC | M14: 180.72 | N14: 1 | O14: =IF(N14=" ",M14*1,M14*N14) -> 180.72
A15: 01 | B15: 8/14-8/18 | C15: DES Interim Review Rental Car Gasoline | L15: RC | M15: 7.35 | N15: 1 | O15: =IF(N15=" ",M15*1,M15*N15) -> 7.35
A16: 01 | B16: 36758 | C16: Title V Mtg Texas Teams | M16: 62.1 | N16: 1 | O16: =IF(N16=" ",M16*1,M16*N16) -> 62.1
A17: 01 | B17: 36760 | C17: EOTT Pipeline Due Diligence | M17: 90.85 | N17: 1 | O17: =IF(N17=" ",M17*1,M17*N17) -> 90.85
A18: 01 | B18: 8/232/00 | C18: Roswell to Farmington NM EOTT Pipeline Due Diligence | L18: P | M18: 446 | N18: 1 | O18: =IF(N18=" ",M18*1,M18*N18) -> 446
A19: 01 | B19: 36761 | C19: EOTT Pipeline Due Diligence | M19: 107.87 | N19: 1 | O19: =IF(N19=" ",M19*1,M19*N19) -> 107.87
A20: 01 | B20: 36762 | C20: EOTT Pipeline Due Diligence Rental Car | L20: RC | M20: 72.78 | N20: 1 | O20: =IF(N20=" ",M20*1,M20*N20) -> 72.78
A21: 01 | B21: 36762 | C21: EOTT Pipeline Dur Diligence Rental Car Gasoline | L21: RC | M21: 22.25 | N21: 1 | O21: =IF(N21=" ",M21*1,M21*N21) -> 22.25
O22: =IF(N22=" ",M22*1,M22*N22) -> 0
O23: =IF(N23=" ",M23*1,M23*N23) -> 0
O24: =IF(N24=" ",M24*1,M24*N24) -> 0
O25: =IF(N25=" ",M25*1,M25*N25) -> 0
O26: =IF(N26=" ",M26*1,M26*N26) -> 0
O27: =IF(N27=" ",M27*1,M27*N27) -> 0
O28: =IF(N28=" ",M28*1,M28*N28) -> 0
O29: =IF(N29=" ",M29*1,M29*N29) -> 0
O30: =IF(N30=" ",M30*1,M30*N30) -> 0
O31: =IF(N31=" ",M31*1,M31*N31) -> 0
O32: =IF(N32=" ",M32*1,M32*N32) -> 0
O33: =IF(N33=" ",M33*1,M33*N33) -> 0
... O40: =IF(N40=" ",M40*1,M40*N40) -> 0
F41: Expense allocation | J41: Allocated amount: | K41: =IF(SUM(L49:L54)=0,0,$O$41-(SUMIF($A$12:$A$40,IF($L$49=" ",$A$49," "),$O$12:$O$40))-(SUMIF($A$12:$A$40,IF($L$50=" ",$A$50," "),$O$12:$O$40))-(SUMIF($A$12:$A$40,IF( $L$51=" ",$A$51," "),$O$12:$O$40))-(SUMIF($A$12:$A$40,IF($L$52=" ",$A$52," "),$O$12:$O$40))-(SUMIF($A$12:$A$40,IF($L$53=" ",$A$53," "),$O$12:$O$40))-(SUMIF($A$12:$A$40,IF($L$54=" ",$A$54," "),$O$12:$O$40))) -> 0 | M41: TOTAL | O41: =SUM(O12:O40) -> 1709.53
F42: Enter an allocation factor next to each account receiving allocated | K42: Total travel expense must be shown on Page 1,
F43: charges. Lines not assigned an allocation factor will not | K43: Employee Expense Report Short Form.
F44: receive an allocation; lines without a REF code will be allocated.
F45: The total of all allocation factors must equal 1.
A46: ACCOUNT DISTRIBUTION | L46: =IF($O$41=$O$55," ","Totals are not equal")
A47: Show the total amount for each accounting classification referenced above.
A48: REF | B48: GL Acct Asset | C48: GL Co Trd Ptr | E48: Cost Center WBS Element | H48: Order Network | J48: Material Activity | K48: Plant Func Area | L48: ALLOC FACTOR | O48: Amount
A49: 01 | B49: 52004500 | C49: 0060 | D49: 111102 | O49: =IF($L$49=" ",SUMIF($A$12:$A$40,A49,$O$12:$O$40),$K$41*$L$49) -> 1709.53
...

Sheet Meals and Ent Sup
A1: Employee Expense Report
A2: Meals and Entertainment Supplement | L2: Page | M2: =IF((VALUE('Short Form'!I62)<>0),1+VALUE('Short Form'!H62)+VALUE('Short Form'!I62),"") -> 3 | N2: =IF((M2=0),"",'Short Form'!N3) -> 4
A4: LAST NAME | E4: FIRST NAME, INITIAL | H4: TITLE | L4: EMPLOYEE NUMBER
A5: ='Short Form'!A6 -> 0 | E5: ='Short Form'!E6 -> 0 | H5: ='Short Form'!H6 -> 0 | L5: ='Short Form'!K6 -> 0
A6: MEALS AND ENTERTAINMENT - Enter the cost of all meals (including food charges from hotel receipts) and entertainment. Attach guest list for entertainment expense. Meal: B = Breakfast,
A7: L = Lunch, D = Dinner, R = Refreshments, T = Travel Status. Assign a reference symbol for each accounting classification to be used. Charges to be allocated do not require a reference symbol.
A9: REF | B9: Date | C9: Meal | E9: Location and Business Purpose | I9: Guests | L9: Cost/Qty | M9: Rate | N9: $ Amount
A10: 05 | B10: 36741 | C10: B,D | D10: Laguna Tribal Mtg. Remediatioin | L10: 7.94 | M10: 1 | N10: =IF(M10=" ",L10*1,L10*M10) -> 7.94
A11: 05 | B11: 8/3/00 | C11: L | D11: Laguna Tribal Mtg. Remediatioin | I11: 7 members Laguna Team 3 members Tribe | L11: 98.84 | M11: 1 | N11: =IF(M11=" ",L11*1,L11*M11) -> 98.84
A12: 05 | B12: 36745 | C12: B,L,D | D12: Title V Mtg, Eunice Team | L12: 13.7 | M12: 1 | N12: =IF(M12=" ",L12*1,L12*M12) -> 13.7
A13: 05 | B13: 36746 | C13: B | D13: Title V Mtg, C/S No. 5, Thoreau | L13: 3.78 | M13: 1 | N13: =IF(M13=" ",L13*1,L13*M13) -> 3.78
A14: 05 | B14: 36752 | C14: B,L | D14: Env. Team, Interim Review | L14: 10.65 | M14: 1 | N14: =IF(M14=" ",L14*1,L14*M14) -> 10.65
A15: 05 | B15: 36754 | C15: B | D15: Env. Team, Interim Review | L15: 24.33 | M15: 1 | N15: =IF(M15=" ",L15*1,L15*M15) -> 24.33
A16: 05 | B16: 36754 | C16: D | D16: Env. Team, Interim Review | I16: Env. Team | L16: 124.86 | M16: 1 | N16: =IF(M16=" ",L16*1,L16*M16) -> 124.86
A17: 05 | B17: 36756 | C17: B,L,D | D17: Env. Team, Interim Review | L17: 2.87 | M17: 1 | N17: =IF(M17=" ",L17*1,L17*M17) -> 2.87
A18: 05 | B18: 36758 | C18: D | D18: Title V Mtg Texas Teams | L18: 6.19 | M18: 1 | N18: =IF(M18=" ",L18*1,L18*M18) -> 6.19
A19: 05 | B19: 36759 | C19: L | D19: Title V Mtg Texas Teams | I19: 11 Team Members | L19: 93.58 | M19: 1 | N19: =IF(M19=" ",L19*1,L19*M19) -> 93.58
A20: 05 | B20: 36759 | C20: B | D20: Title V Mtg Texas Teams | L20: 2.34 | M20: 1 | N20: =IF(M20=" ",L20*1,L20*M20) -> 2.34
A21: 05 | B21: 36759 | C21: D | D21: EOTT Pipeline Due Diligence | I21: R.Loveless | L21: 64.92 | M21: 1 | N21: =IF(M21=" ",L21*1,L21*M21) -> 64.92
A22: 05 | B22: 36760 | C22: B | D22: EOTT Pipeline Due Diligence | L22: 5.01 | M22: 1 | N22: =IF(M22=" ",L22*1,L22*M22) -> 5.01
A23: 05 | B23: 36761 | C23: L,D | D23: EOTT Pipeline Due Diligence | L23: 18.98 | M23: 1 | N23: =IF(M23=" ",L23*1,L23*M23) -> 18.98
A24: 05 | B24: 36762 | C24: L,D | D24: EOTT Pipeline Due Diligence | L24: 6.97 | M24: 1 | N24: =IF(M24=" ",L24*1,L24*M24) -> 6.97
N25: =IF(M25=" ",L25*1,L25*M25) -> 0
N26: =IF(M26=" ",L26*1,L26*M26) -> 0
N27: =IF(M27=" ",L27*1,L27*M27) -> 0
N28: =IF(M28=" ",L28*1,L28*M28) -> 0
N29: =IF(M29=" ",L29*1,L29*M29) -> 0
N30: =IF(M30=" ",L30*1,L30*M30) -> 0
N31: =IF(M31=" ",L31*1,L31*M31) -> 0
N32: =IF(M32=" ",L32*1,L32*M32) -> 0
N33: =IF(M33=" ",L33*1,L33*M33) -> 0
N34: =IF(M34=" ",L34*1,L34*M34) -> 0
N35: =IF(M35=" ",L35*1,L35*M35) -> 0
N36: =IF(M36=" ",L36*1,L36*M36) -> 0
... N40: =IF(M40=" ",L40*1,L40*M40) -> 0
F41: Expense allocation | J41: Allocated amount: | K41: =IF(SUM(L49:L54)=0,0,$N$41-(SUMIF($A$10:$A$40,IF($L$49=" ",$A$49," "),$N$10:$N$40))-(SUMIF($A$10:$A$40,IF($L$50=" ",$A$50," "),$N$10:$N$40))-(SUMIF($A$10:$A$40,IF( $L$51=" ",$A$51," "),$N$10:$N$40))-(SUMIF($A$10:$A$40,IF($L$52=" ",$A$52," "),$N$10:$N$40))-(SUMIF($A$10:$A$40,IF($L$53=" ",$A$53," "),$N$10:$N$40))-(SUMIF($A$10:$A$40,IF($L$54=" ",$A$54," "),$N$10:$N$40))) -> 0 | L41: TOTAL | N41: =SUM(N10:N40) -> 484.96
F42: Enter an allocation factor next to each account receiving allocated | K42: Total travel expense must be shown on Page 1,
F43: charges. Lines not assigned an allocation factor will not | K43: Employee Expense Report Short Form.
F44: receive an allocation; lines without a REF code will be allocated.
F45: The total of all allocation factors must equal 1.
...

Sheet Misc. Exp. Sup
A1: Employee Expense Report
A2: Miscellaneous Expense Supplement | M2: Page | N2: =IF((VALUE('Short Form'!J62)<>0),1+VALUE('Short Form'!I62)+VALUE('Short Form'!J62)+VALUE('Short Form'!H62),"") -> 4 | O2: =IF((N2=0),"",'Short Form'!$N3) -> 4
A4: LAST NAME | E4: FIRST NAME, INITIAL | H4: TITLE | K4: EMPLOYEE NUMBER
A5: ='Short Form'!A6 -> 0 | E5: ='Short Form'!E6 -> 0 | H5: ='Short Form'!H6 -> 0 | K5: ='Short Form'!K6 -> 0
A7: MISCELLANEOUS EXPENSE - Enter all other expenses (memberships, fees, supplies, mileage, etc.) not associated with business transportation or lodging.
A8: Assign a reference symbol for each accounting classification to be used. Charges to be allocated do not require a reference symbol.
A9: REF | B9: Date | E9: Location and Business Purpose | M9: Cost/Miles | N9: Rate | O9: $ Amount
A10: 01 | B10: 36759 | C10: EOTT Pipeline Due Diligence-Supplies | M10: 11.88 | N10: 1 | O10: =IF(N10=" ",M10*1,M10*N10) -> 11.88
O11: =IF(N11=" ",M11*1,M11*N11) -> 0
O12: =IF(N12=" ",M12*1,M12*N12) -> 0
O13: =IF(N13=" ",M13*1,M13*N13) -> 0
O14: =IF(N14=" ",M14*1,M14*N14) -> 0
O15: =IF(N15=" ",M15*1,M15*N15) -> 0
O16: =IF(N16=" ",M16*1,M16*N16) -> 0
O17: =IF(N17=" ",M17*1,M17*N17) -> 0
O18: =IF(N18=" ",M18*1,M18*N18) -> 0
O19: =IF(N19=" ",M19*1,M19*N19) -> 0
O20: =IF(N20=" ",M20*1,M20*N20) -> 0
O21: =IF(N21=" ",M21*1,M21*N21) -> 0
O22: =IF(N22=" ",M22*1,M22*N22) -> 0
... O40: =IF(N40=" ",M40*1,M40*N40) -> 0
F41: Expense allocation | J41: Allocated amount: | K41: =IF(SUM(L49:L54)=0,0,$O$41-(SUMIF($A$10:$A$40,IF($L$49=" ",$A$49," "),$O$10:$O$40))-(SUMIF($A$10:$A$40,IF($L$50=" ",$A$50," "),$O$10:$O$40))-(SUMIF($A$10:$A$40,IF($L$51=" ",$A$51," "),$O$10:$O$40))-(SUMIF($A$10:$A$40,IF($L$52=" ",$A$52," "),$O$10:$O$40))-(SUMIF($A$10:$A$40,IF($L$53=" ",$A$53," "),$O$10:$O$40))-(SUMIF($A$10:$A$40,IF($L$54=" ",$A$54," "),$O$10:$O$40))) -> 0 | M41: TOTAL | O41: =SUM(O10:O40) -> 11.88
F42: Enter an allocation factor next to each account receiving allocated | L42: Total travel expense must be shown on Page 1,
F43: charges. Lines not assigned an allocation factor will not | L43: Employee Expense Report Short Form.
F44: receive an allocation; lines without a REF code will be allocated.
F45: The total of all allocation factors must equal 1.
A46: ACCOUNT DISTRIBUTION | L46: =IF($O$41=$O$55," ","Totals are not equal")
A47: Show the total amount for each accounting classification referenced above.
A48: REF | B48: GL Acct Asset | C48: GL Co Tr Ptr | E48: Cost Center WBS Element | H48: Order Network | J48: Material Activity | K48: Plant Func Area | L48: ALLOC FACTOR | O48: Amount
A49: 01 | O49: =IF($L$49=" ",SUMIF($A$10:$A$40,A49,$O$10:$O$40),$K$41*$L$49) -> 11.88
O50: =IF($L$50=" ",SUMIF($A$10:$A$40,A50,$O$10:$O$40),$K$41*$L$50) -> 0
O51: =IF($L$51=" ",SUMIF($A$10:$A$40,A51,$O$10:$O$40),$K$41*$L$51) -> 0
O52: =IF($L$52=" ",SUMIF($A$10:$A$40,A52,$O$10:$O$40),$K$41*$L$52) -> 0
O53: =IF($L$53=" ",SUMIF($A$10:$A$40,A53,$O$10:$O$40),$K$41*$L$53) -> 0
O54: =IF($L$54=" ",SUMIF($A$12:$A$40,A54,$O$12:$O$40),$K$41*$L$54) -> 0
L55: =SUM(L49:L54) -> 0 | M55: TOTAL | O55: =SUM(O49:O54) -> 11.88

Sheet Travel Sup (2)
A1: Employee Expense Report
A2: Travel Expense Summary (2) | M2: Page | N2: =IF((VALUE('Short Form'!K62)<>0),1+VALUE('Short Form'!I62)+VALUE('Short Form'!J62)+VALUE('Short Form'!H62)+VALUE('Short Form'!K62),"") | O2: =IF(N2=0,"",'Short Form'!N3)
A4: LAST NAME | E4: FIRST NAME, INITIAL | H4: TITLE | K4: EMPLOYEE NUMBER
A5: ='Short Form'!A6 -> 0 | E5: ='Short Form'!E6 -> 0 | H5: ='Short Form'!H6 -> 0 | K5: ='Short Form'!K6 -> 0
A7: TRAVEL EXPENSE - Enter all transportation and lodging expenses by receipt total (airline tickets, rental car receipts, taxis, hotel, tips, personal mileage, etc.). Exclude meals and entertainment.
A8: Designate type of transportation used: B = Bus, C = Cab, P = Plane, PC = Personal Car, CC = Company Car, RC = Rental Car, T = Train.
A9: Assign a reference symbol for each accounting classification to be used. Charges to be allocated do not require a reference symbol.
A11: REF | B11: Date | E11: Location and Business Purpose | L11: Type | M11: Cost/Miles | N11: Rate | O11: $ Amount
O12: =IF(N12=" ",M12*1,M12*N12) -> 0
O13: =IF(N13=" ",M13*1,M13*N13) -> 0
O14: =IF(N14=" ",M14*1,M14*N14) -> 0
O15: =IF(N15=" ",M15*1,M15*N15) -> 0
O16: =IF(N16=" ",M16*1,M16*N16) -> 0
O17: =IF(N17=" ",M17*1,M17*N17) -> 0
O18: =IF(N18=" ",M18*1,M18*N18) -> 0
O19: =IF(N19=" ",M19*1,M19*N19) -> 0
O20: =IF(N20=" ",M20*1,M20*N20) -> 0
O21: =IF(N21=" ",M21*1,M21*N21) -> 0
O22: =IF(N22=" ",M22*1,M22*N22) -> 0
O23: =IF(N23=" ",M23*1,M23*N23) -> 0
... O40: =IF(N40=" ",M40*1,M40*N40) -> 0
F41: Expense allocation | J41: Allocated amount: | K41: =IF(SUM(L49:L54)=0,0,$O$41-(SUMIF($A$12:$A$40,IF($L$49=" ",$A$49," "),$O$12:$O$40))-(SUMIF($A$12:$A$40,IF($L$50=" ",$A$50," "),$O$12:$O$40))-(SUMIF($A$12:$A$40,IF( $L$51=" ",$A$51," "),$O$12:$O$40))-(SUMIF($A$12:$A$40,IF($L$52=" ",$A$52," "),$O$12:$O$40))-(SUMIF($A$12:$A$40,IF($L$53=" ",$A$53," "),$O$12:$O$40))-(SUMIF($A$12:$A$40,IF($L$54=" ",$A$54," "),$O$12:$O$40))) -> 0 | M41: TOTAL | O41: =SUM(O12:O40) -> 0
F42: Enter an allocation factor next to each account receiving allocated | K42: Total travel expense must be shown on Page 1,
F43: charges. Lines not assigned an allocation factor will not | K43: Employee Expense Report Short Form.
F44: receive an allocation; lines without a REF code will be allocated.
F45: The total of all allocation factors must equal 1.
A46: ACCOUNT DISTRIBUTION | L46: =IF($O$41=$O$55," ","Totals are not equal")
A47: Show the total amount for each accounting classification referenced above.
A48: REF | B48: GL Acct Asset | C48: GL Co Tr Ptr | E48: Cost Center WBS Element | H48: Order Network | J48: Material Activity | K48: Plant Func Area | L48: ALLOC FACTOR | O48: Amount
O49: =IF($L$49=" ",SUMIF($A$12:$A$40,A49,$O$12:$O$40),$K$41*$L$49) -> 0
O50: =IF($L$50=" ",SUMIF($A$12:$A$40,A50,$O$12:$O$40),$K$41*$L$50) -> 0
O51: =IF($L$51=" ",SUMIF($A$12:$A$40,A51,$O$12:$O$40),$K$41*$L$51) -> 0
O52: =IF($L$52=" ",SUMIF($A$12:$A$40,A52,$O$12:$O$40),$K$41*$L$52) -> 0
O53: =IF($L$53=" ",SUMIF($A$12:$A$40,A53,$O$12:$O$40),$K$41*$L$53) -> 0
O54: =IF($L$54=" ",SUMIF($A$12:$A$40,A54,$O$12:$O$40),$K$41*$L$54) -> 0
L55: =L49+L50+L51+L52+L53+L54 -> 0 | M55: TOTAL | O55: =SUM(O49:O54) -> 0

Sheet Meals and Ent Sup (2)
A1: Employee Expense Report
A2: Meals and Entertainment Supplement (2) | L2: Page | M2: =IF((VALUE('Short Form'!L62)<>0),1+VALUE('Short Form'!H62)+VALUE('Short Form'!I62)+VALUE('Short Form'!J62)+VALUE('Short Form'!K62)+VALUE('Short Form'!L62),"") | N2: =IF((M2=0),"",'Short Form'!N3)
A4: LAST NAME | E4: FIRST NAME, INITIAL | H4: TITLE | L4: EMPLOYEE NUMBER
A5: ='Short Form'!A6 -> 0 | E5: ='Short Form'!E6 -> 0 | H5: ='Short Form'!H6 -> 0 | L5: ='Short Form'!K6 -> 0
A6: MEALS AND ENTERTAINMENT - Enter the cost of all meals (including food charges from hotel receipts) and entertainment. Attach guest list for entertainment expense. Meal: B = Breakfast,
A7: L = Lunch, D = Dinner, R = Refreshments, T = Travel Status. Assign a reference symbol for each accounting classification to be used. Charges to be allocated do not require a reference symbol.
A9: REF | B9: Date | C9: Meal | E9: Location and Business Purpose | I9: Guests | L9: Cost/Qty | M9: Rate | N9: $ Amount
N10: =IF(M10=" ",L10*1,L10*M10) -> 0
N11: =IF(M11=" ",L11*1,L11*M11) -> 0
N12: =IF(M12=" ",L12*1,L12*M12) -> 0
N13: =IF(M13=" ",L13*1,L13*M13) -> 0
N14: =IF(M14=" ",L14*1,L14*M14) -> 0
N15: =IF(M15=" ",L15*1,L15*M15) -> 0
N16: =IF(M16=" ",L16*1,L16*M16) -> 0
N17: =IF(M17=" ",L17*1,L17*M17) -> 0
N18: =IF(M18=" ",L18*1,L18*M18) -> 0
N19: =IF(M19=" ",L19*1,L19*M19) -> 0
N20: =IF(M20=" ",L20*1,L20*M20) -> 0
N21: =IF(M21=" ",L21*1,L21*M21) -> 0
... N40: =IF(M40=" ",L40*1,L40*M40) -> 0
F41: Expense allocation | J41: Allocated amount: | K41: =IF(SUM(L49:L54)=0,0,$N$41-(SUMIF($A$10:$A$40,IF($L$49=" ",$A$49," "),$N$10:$N$40))-(SUMIF($A$10:$A$40,IF($L$50=" ",$A$50," "),$N$10:$N$40))-(SUMIF($A$10:$A$40,IF( $L$51=" ",$A$51," "),$N$10:$N$40))-(SUMIF($A$10:$A$40,IF($L$52=" ",$A$52," "),$N$10:$N$40))-(SUMIF($A$10:$A$40,IF($L$53=" ",$A$53," "),$N$10:$N$40))-(SUMIF($A$10:$A$40,IF($L$54=" ",$A$54," "),$N$10:$N$40))) -> 0 | L41: TOTAL | N41: =SUM(N10:N40) -> 0
F42: Enter an allocation factor next to each account receiving allocated | K42: Total travel expense must be shown on Page 1,
F43: charges. Lines not assigned an allocation factor will not | K43: Employee Expense Report Short Form.
F44: receive an allocation; lines without a REF code will be allocated.
F45: The total of all allocation factors must equal 1.
A46: ACCOUNT DISTRIBUTION | L46: =IF($N$41=$N$55," ","Totals are not equal")
A47: Show the total amount for each accounting classification referenced above.
A48: REF | B48: GL Acct Asset | C48: GL Co Tr Ptr | E48: Cost Center WBS Element | H48: Order Network | J48: Material Activity | K48: Plant Func Area | L48: ALLOC FACTOR | N48: Amount
N49: =IF($L$49=" ",SUMIF($A$10:$A$40,A49,$N$10:$N$40),$K$41*$L$49) -> 0
N50: =IF($L$50=" ",SUMIF($A$10:$A$40,A50,$N$10:$N$40),$K$41*$L$50) -> 0
N51: =IF($L$51=" ",SUMIF($A$10:$A$40,A51,$N$10:$N$40),$K$41*$L$51) -> 0
N52: =IF($L$52=" ",SUMIF($A$10:$A$40,A52,$N$10:$N$40),$K$41*$L$52) -> 0
N53: =IF($L$53=" ",SUMIF($A$10:$A$40,A53,$N$10:$N$40),$K$41*$L$53) -> 0
N54: =IF($L$54=" ",SUMIF($A$10:$A$40,A54,$N$10:$N$40),$K$41*$L$54) -> 0
L55: =SUM(L49:L54) -> 0 | M55: TOTAL | N55: =SUM(N49:N54) -> 0

Sheet Misc. Exp. Sup (2)
A1: Employee Expense Report
A2: Miscellaneous Expense Supplement (2) | M2: Page | N2: =IF((VALUE('Short Form'!M62)<>0),1+VALUE('Short Form'!H62)+VALUE('Short Form'!I62)+VALUE('Short Form'!J62)+VALUE('Short Form'!K62)+VALUE('Short Form'!L62)+VALUE('Short Form'!M62),"") | O2: =IF((N2=0),"",'Short Form'!$N3)
A4: LAST NAME | E4: FIRST NAME, INITIAL | H4: TITLE | K4: EMPLOYEE NUMBER
A5: ='Short Form'!A6 -> 0 | E5: ='Short Form'!E6 -> 0 | H5: ='Short Form'!H6 -> 0 | K5: ='Short Form'!K6 -> 0
A7: MISCELLANEOUS EXPENSE - Enter all other expenses (memberships, fees, supplies, mileage, etc.) not associated with business transportation or lodging.
A8: Assign a reference symbol for each accounting classification to be used. Charges to be allocated do not require a reference symbol.
A9: REF | B9: Date | E9: Location and Business Purpose | M9: Cost/Miles | N9: Rate | O9: $ Amount
O10: =IF(N10=" ",M10*1,M10*N10) -> 0
O11: =IF(N11=" ",M11*1,M11*N11) -> 0
O12: =IF(N12=" ",M12*1,M12*N12) -> 0
O13: =IF(N13=" ",M13*1,M13*N13) -> 0
O14: =IF(N14=" ",M14*1,M14*N14) -> 0
O15: =IF(N15=" ",M15*1,M15*N15) -> 0
O16: =IF(N16=" ",M16*1,M16*N16) -> 0
O17: =IF(N17=" ",M17*1,M17*N17) -> 0
O18: =IF(N18=" ",M18*1,M18*N18) -> 0
O19: =IF(N19=" ",M19*1,M19*N19) -> 0
O20: =IF(N20=" ",M20*1,M20*N20) -> 0
O21: =IF(N21=" ",M21*1,M21*N21) -> 0
... O40: =IF(N40=" ",M40*1,M40*N40) -> 0
F41: Expense allocation | J41: Allocated amount: | K41: =IF(SUM(L49:L54)=0,0,$O$41-(SUMIF($A$10:$A$40,IF($L$49=" ",$A$49," "),$O$10:$O$40))-(SUMIF($A$10:$A$40,IF($L$50=" ",$A$50," "),$O$10:$O$40))-(SUMIF($A$10:$A$40,IF($L$51=" ",$A$51," "),$O$10:$O$40))-(SUMIF($A$10:$A$40,IF($L$52=" ",$A$52," "),$O$10:$O$40))-(SUMIF($A$10:$A$40,IF($L$53=" ",$A$53," "),$O$10:$O$40))-(SUMIF($A$10:$A$40,IF($L$54=" ",$A$54," "),$O$10:$O$40))) -> 0 | M41: TOTAL | O41: =SUM(O10:O40) -> 0
F42: Enter an allocation factor next to each account receiving allocated | L42: Total travel expense must be shown on Page 1,
F43: charges. Lines not assigned an allocation factor will not | L43: Employee Expense Report Short Form.
F44: receive an allocation; lines without a REF code will be allocated.
F45: The total of all allocation factors must equal 1.
A46: ACCOUNT DISTRIBUTION | L46: =IF($O$41=$O$55," ","Totals are not equal")
A47: Show the total amount for each accounting classification referenced above.
A48: REF | B48: GL Acct Asset | C48: GL Co Tr Ptr | E48: Cost Center WBS Element | H48: Order Network | J48: Material Activity | K48: Plant Func Area | L48: ALLOC FACTOR | O48: Amount
O49: =IF($L$49=" ",SUMIF($A$10:$A$40,A49,$O$10:$O$40),$K$41*$L$49) -> 0
O50: =IF($L$50=" ",SUMIF($A$10:$A$40,A50,$O$10:$O$40),$K$41*$L$50) -> 0
O51: =IF($L$51=" ",SUMIF($A$10:$A$40,A51,$O$10:$O$40),$K$41*$L$51) -> 0
O52: =IF($L$52=" ",SUMIF($A$10:$A$40,A52,$O$10:$O$40),$K$41*$L$52) -> 0
O53: =IF($L$53=" ",SUMIF($A$10:$A$40,A53,$O$10:$O$40),$K$41*$L$53) -> 0
O54: =IF($L$54=" ",SUMIF($A$12:$A$40,A54,$O$12:$O$40),$K$41*$L$54) -> 0
L55: =SUM(L49:L54) -> 0 | M55: TOTAL | O55: =SUM(O49:O54) -> 0
