Workbook
Name AprAward: 'Monthly OPP Awards'!$A$60:$I$69
Name AprOffer: 'Monthly OPP Awards'!$A$6:$D$13
Name AprOffer: 'Strip Award'!#REF!
Name AprOffer: 'Apr OPP'!$A$17:$R$24
Name AugAward: 'Monthly OPP Awards'!$A$38:$I$69
Name AugOffer: 'Feb OPP'!$A$17:$R$24
Name cell1: 'Monthly OPP Awards'!#REF!
Name cell2: 'Monthly OPP Awards'!#REF!
Name cell3: 'Monthly OPP Awards'!#REF!
Name DecAward: 'Monthly OPP Awards'!$A$16:$I$69
Name DecOffer: 'Dec OPP'!$A$17:$R$24
Name FebAward: 'Monthly OPP Awards'!$A$38:$I$69
Name FebOffer: 'Feb OPP'!$A$17:$R$24
Name JanAward: 'Monthly OPP Awards'!$A$27:$I$69
Name JanOffer: 'Jan OPP'!$A$17:$R$24
Name JulAward: 'Monthly OPP Awards'!$A$27:$I$69
Name JulOffer: 'Jan OPP'!$A$17:$R$24
Name JunAward: 'Monthly OPP Awards'!$A$16:$I$69
Name JunOffer: 'Dec OPP'!$A$17:$R$24
Name MarAward: 'Monthly OPP Awards'!$A$49:$I$69
Name MarOffer: 'Mar OPP'!$A$17:$R$24
Name MayAward: 'Monthly OPP Awards'!$A$5:$I$69
Name MayOffer: 'Nov OPP'!$A$17:$R$24
Name NovAward: 'Monthly OPP Awards'!$A$5:$I$69
Name NovOffer: 'Nov OPP'!$A$17:$R$24
Name OctAward: 'Monthly OPP Awards'!$A$60:$I$69
Name OctOffer: 'Monthly OPP Awards'!$A$6:$D$13
Name OctOffer: 'Strip Award'!#REF!
Name OctOffer: 'Apr OPP'!$A$17:$R$24
Name opp1insrow: 'Monthly OPP Awards'!#REF!
Name opp2insrow: 'Monthly OPP Awards'!#REF!
Name opp3insrow: 'Monthly OPP Awards'!#REF!
Name opp4insrow: 'Monthly OPP Awards'!#REF!
Name opp5insrow: 'Monthly OPP Awards'!#REF!
Name opp6insrow: 'Monthly OPP Awards'!#REF!
Name oppdiff1: 'Monthly OPP Awards'!$A$115
Name oppdiff2: 'Monthly OPP Awards'!#REF!
Name oppdiff3: 'Monthly OPP Awards'!$B$115
Name oppdiff4: 'Monthly OPP Awards'!#REF!
Name oppdiff5: 'Monthly OPP Awards'!$C$115
Name oppdiff6: 'Monthly OPP Awards'!$D$115
Name SepAward: 'Monthly OPP Awards'!$A$49:$I$69
Name SepOffer: 'Mar OPP'!$A$17:$R$24
Name StripAward: 'Strip Award'!$A$16:$I$25
Name StripOffer: 'Offers-Strip'!$A$17:$R$24
Name sumdiff: 'Monthly OPP Awards'!$F$115
Name temp: 'Monthly OPP Awards'!$A$5:$H$17
Name temp: 'Strip Award'!$A$11:$H$15
Name temp: #REF!
Name Templete: 'Nov OPP'!$A$3:$AB$40

Sheet Instruction Page
A3: This workbook has been redesigned to increase the accuracy of information being transferred to the auction model and to facilitate the rapid transfer of award
A4: notices to sellers.
A6: In order to meet the above goals each spreadsheet page requires that information be entered in a consistent format and that changes to the workbook be made
A7: in a manner that does not destroy links and formulas. The following steps must adhered to:
A9: Special Notes:
B10: 1. Pages prior to the periods being offered must be deleted.
B11: 2. Do not delete pages between the current obligation month and the last month of the Obligation Procurement Period (OPP).
B12: 3. Do not make any changes to awards pages. Award pages are for the use of NYISO Employees only.
B13: 4. Do not enter any information in the red colored cells
B14: 5. Do not delete rows highlighted in yellow.
A16: Strip auctions:
B17: 1. Do Not submit detached pages. Transmit entire workbook.
B18: 2. Do not use this page for monthly offers.
B19: 3. Enter the obligation procurement period in cell "E8."
B20: 4. Enter the date offer is submitted in "L8."
B21: 5. Enter your "Registrant Name:" in cell "E11." This information will appear in the "Seller's Name" area when PTID #'s are entered.
B22: 6. If you resubmit an offer during an auction day, then increase the submittal number by one.
B23: 7. Enter the time, in military standard units, when this workbook is transmitted to the ISO. (example 15:00 equals 3:00 PM)
B24: 8. In rows 17 through 24 enter your offer information. | G24: All locations have been prefilled with zeros, do not forget to enter the number 1 for the chosen location.
C25: a. If more rows are needed, push "Insert Rows" button
C26: b. If less rows are needed, push "Delete Rows" button. Do not delete row with yellow bar.
C27: c. Do not enter in formation in the red cells
C28: d. If you do not have a "PTID #," because you are reselling from an auction, then enter "NYISO Auction."
B29: 9. Enter your name in cell "C30."
B30: 10. Enter your telephone number in cell "L30."
B31: 11. Enter the company name for in cell "C34."
B32: 12. Enter required information in cells "C35" to "C40."
A34: Monthly auctions (OPP):
B35: 1. Do Not submit detached pages. Transmit entire workbook.
B36: 2. Do not use these pages for the strip auction.
B37: 3. Enter the obligation procurement month in cells "E8" on each page.
B38: 4. Enter the date offer is submitted in "L8."
B39: 5. Enter your "Registrant Name:" in cell "E11." This information will appear in the "Seller's Name" area when PTID #'s are entered.
B40: 6. If you resubmit an offer during an auction day, then increase the submittal number by one.
B41: 7. Enter the time, in military standard units, when this workbook is transmitted to the ISO. (example 15:00 equals 3:00 PM)
B42: 8. In rows 17 through 24 enter your offer information. | G42: All locations have been prefilled with zeros, do not forget to enter a number 1 for the chosen location.
C43: a. If more rows are needed, push "Insert Rows" button
C44: b. If less rows are needed, push "Delete Rows" button. Do not delete row with yellow bar.
C45: c. Do not enter in formation in the red cells
C46: d. If you do not have a "PTID #," because you are reselling from an auction, then enter "NYISO Auction."
...

Sheet Offers-Strip
D3: SUBMIT TO: | I3: New York Independent System Operator
D4: sellicap@nyiso.com | I4: Installed Capacity (UCAP) Strip Auction
I6: Offers to Sell
D8: Auction Period: | K8: Date submitted:
G9: Submittal Number | K9: Time submitted:
D11: Registrant Name:
A12: Not To Be Used For Single Monthly Auction
B14: Seller's | F14: Minimum Price | G14: Amount (MW) | H14: Location ( indicate a (1) for chosen area and (0) for other areas)
A15: Offer# | B15: Name | C15: NYC | D15: PTID# | E15: Resource Name | F15: [($/kW- 6 month) | G15: [express to | H15: NYC | I15: LI | J15: ROS* | K15: PJM | L15: ISO-NE | M15: HQ | N15: O-IMO
C16: Mitigated | F16: express to nearest $.01] | G16: nearest 0.1 MW]
A17: 1 | B17: =IF(D17=0," ",+$E$11) | C17: N | E17: =IF(ISERROR(VLOOKUP(D17,$C$80:$D$700,2)),"",VLOOKUP(D17,$C$80:$D$700,2)) | H17: 0 | I17: 0 | J17: 0 | K17: 0 | L17: 0 | M17: 0 | N17: 0 | O17: =+$E$8 -> 0 | P17: =+$G$8 -> 0 | Q17: =+$M$8 -> 0 | R17: =+$M$9 -> 0 | S17: =IF(AND(OR(H17=0,H17=1),OR(I17=0,I17=1),OR(J17=0,J17=1),OR(K17=0,K17=1),OR(L17=0,L17=1),OR(N17=0,N17=1),OR(M17=0,M17=1)),0,1) -> 0 | T17: =IF(L17+N17>0,1,0) -> 0 | U17: =IF(SUM(H17:N17)>1,1,0) -> 0 | V17: =IF(AND(G17>0,SUM(H17:N17)=0),1,0) -> 0 | W17: =IF(H17>0,1,0) -> 0
A18: =COUNT($A$17:A17)+1 -> 2 | B18: =IF(D18=0," ",+$E$11) | C18: N | E18: =IF(ISERROR(VLOOKUP(D18,$C$80:$D$700,2)),"",VLOOKUP(D18,$C$80:$D$700,2)) | H18: 0 | I18: 0 | J18: 0 | K18: 0 | L18: 0 | M18: 0 | N18: 0 | O18: =+$E$8 -> 0 | P18: =+$G$8 -> 0 | Q18: =+$M$8 -> 0 | R18: =+$M$9 -> 0 | S18: =IF(AND(OR(H18=0,H18=1),OR(I18=0,I18=1),OR(J18=0,J18=1),OR(K18=0,K18=1),OR(L18=0,L18=1),OR(N18=0,N18=1),OR(M18=0,M18=1)),0,1) -> 0 | T18: =IF(L18+N18>0,1,0) -> 0 | U18: =IF(SUM(H18:N18)>1,1,0) -> 0 | V18: =IF(AND(G18>0,SUM(H18:N18)=0),1,0) -> 0 | W18: =IF(H18>0,1,0) -> 0
A19: =COUNT($A$17:A18)+1 -> 3 | B19: =IF(D19=0," ",+$E$11) | C19: N | E19: =IF(ISERROR(VLOOKUP(D19,$C$80:$D$700,2)),"",VLOOKUP(D19,$C$80:$D$700,2)) | H19: 0 | I19: 0 | J19: 0 | K19: 0 | L19: 0 | M19: 0 | N19: 0 | O19: =+$E$8 -> 0 | P19: =+$G$8 -> 0 | Q19: =+$M$8 -> 0 | R19: =+$M$9 -> 0 | S19: =IF(AND(OR(H19=0,H19=1),OR(I19=0,I19=1),OR(J19=0,J19=1),OR(K19=0,K19=1),OR(L19=0,L19=1),OR(N19=0,N19=1),OR(M19=0,M19=1)),0,1) -> 0 | T19: =IF(L19+N19>0,1,0) -> 0 | U19: =IF(SUM(H19:N19)>1,1,0) -> 0 | V19: =IF(AND(G19>0,SUM(H19:N19)=0),1,0) -> 0 | W19: =IF(H19>0,1,0) -> 0
A20: =COUNT($A$17:A19)+1 -> 4 | B20: =IF(D20=0," ",+$E$11) | C20: N | E20: =IF(ISERROR(VLOOKUP(D20,$C$80:$D$700,2)),"",VLOOKUP(D20,$C$80:$D$700,2)) | H20: 0 | I20: 0 | J20: 0 | K20: 0 | L20: 0 | M20: 0 | N20: 0 | O20: =+$E$8 -> 0 | P20: =+$G$8 -> 0 | Q20: =+$M$8 -> 0 | R20: =+$M$9 -> 0 | S20: =IF(AND(OR(H20=0,H20=1),OR(I20=0,I20=1),OR(J20=0,J20=1),OR(K20=0,K20=1),OR(L20=0,L20=1),OR(N20=0,N20=1),OR(M20=0,M20=1)),0,1) -> 0 | T20: =IF(L20+N20>0,1,0) -> 0 | U20: =IF(SUM(H20:N20)>1,1,0) -> 0 | V20: =IF(AND(G20>0,SUM(H20:N20)=0),1,0) -> 0 | W20: =IF(H20>0,1,0) -> 0
A21: =COUNT($A$17:A20)+1 -> 5 | B21: =IF(D21=0," ",+$E$11) | C21: N | E21: =IF(ISERROR(VLOOKUP(D21,$C$80:$D$700,2)),"",VLOOKUP(D21,$C$80:$D$700,2)) | H21: 0 | I21: 0 | J21: 0 | K21: 0 | L21: 0 | M21: 0 | N21: 0 | O21: =+$E$8 -> 0 | P21: =+$G$8 -> 0 | Q21: =+$M$8 -> 0 | R21: =+$M$9 -> 0 | S21: =IF(AND(OR(H21=0,H21=1),OR(I21=0,I21=1),OR(J21=0,J21=1),OR(K21=0,K21=1),OR(L21=0,L21=1),OR(N21=0,N21=1),OR(M21=0,M21=1)),0,1) -> 0 | T21: =IF(L21+N21>0,1,0) -> 0 | U21: =IF(SUM(H21:N21)>1,1,0) -> 0 | V21: =IF(AND(G21>0,SUM(H21:N21)=0),1,0) -> 0 | W21: =IF(H21>0,1,0) -> 0
A22: =COUNT($A$17:A21)+1 -> 6 | B22: =IF(D22=0," ",+$E$11) | C22: N | E22: =IF(ISERROR(VLOOKUP(D22,$C$80:$D$700,2)),"",VLOOKUP(D22,$C$80:$D$700,2)) | H22: 0 | I22: 0 | J22: 0 | K22: 0 | L22: 0 | M22: 0 | N22: 0 | O22: =+$E$8 -> 0 | P22: =+$G$8 -> 0 | Q22: =+$M$8 -> 0 | R22: =+$M$9 -> 0 | S22: =IF(AND(OR(H22=0,H22=1),OR(I22=0,I22=1),OR(J22=0,J22=1),OR(K22=0,K22=1),OR(L22=0,L22=1),OR(N22=0,N22=1),OR(M22=0,M22=1)),0,1) -> 0 | T22: =IF(L22+N22>0,1,0) -> 0 | U22: =IF(SUM(H22:N22)>1,1,0) -> 0 | V22: =IF(AND(G22>0,SUM(H22:N22)=0),1,0) -> 0 | W22: =IF(H22>0,1,0) -> 0
A23: =COUNT($A$17:A22)+1 -> 7 | B23: =IF(D23=0," ",+$E$11) | C23: N | E23: =IF(ISERROR(VLOOKUP(D23,$C$80:$D$700,2)),"",VLOOKUP(D23,$C$80:$D$700,2)) | H23: 0 | I23: 0 | J23: 0 | K23: 0 | L23: 0 | M23: 0 | N23: 0 | O23: =+$E$8 -> 0 | P23: =+$G$8 -> 0 | Q23: =+$M$8 -> 0 | R23: =+$M$9 -> 0 | S23: =IF(AND(OR(H23=0,H23=1),OR(I23=0,I23=1),OR(J23=0,J23=1),OR(K23=0,K23=1),OR(L23=0,L23=1),OR(N23=0,N23=1),OR(M23=0,M23=1)),0,1) -> 0 | T23: =IF(L23+N23>0,1,0) -> 0 | U23: =IF(SUM(H23:N23)>1,1,0) -> 0 | V23: =IF(AND(G23>0,SUM(H23:N23)=0),1,0) -> 0 | W23: =IF(H23>0,1,0) -> 0
A24: =COUNT($A$17:A23)+1 -> 8 | B24: =IF(D24=0," ",+$E$11) | C24: N | E24: =IF(ISERROR(VLOOKUP(D24,$C$80:$D$700,2)),"",VLOOKUP(D24,$C$80:$D$700,2)) | H24: 0 | I24: 0 | J24: 0 | K24: 0 | L24: 0 | M24: 0 | N24: 0 | O24: =+$E$8 -> 0 | P24: =+$G$8 -> 0 | Q24: =+$M$8 -> 0 | R24: =+$M$9 -> 0 | S24: =IF(AND(OR(H24=0,H24=1),OR(I24=0,I24=1),OR(J24=0,J24=1),OR(K24=0,K24=1),OR(L24=0,L24=1),OR(N24=0,N24=1),OR(M24=0,M24=1)),0,1) -> 0 | T24: =IF(L24+N24>0,1,0) -> 0 | U24: =IF(SUM(H24:N24)>1,1,0) -> 0 | V24: =IF(AND(G24>0,SUM(H24:N24)=0),1,0) -> 0 | W24: =IF(H24>0,1,0) -> 0
I25: =IF(T25+S25+U25+V25>0,"WARNING:","") | J25: =IF(S25>0,"Values above must be 1's or 0's",IF(T25>0,"NE and Ontario are not participating. These must be 0's",IF(U25>0,"Choose one location only",IF(V25>0,"You must select a location","")))) | S25: =SUM(S17:S24) -> 0 | T25: =SUM(T17:T24) -> 0 | U25: =SUM(U17:U24) -> 0 | V25: =SUM(V17:V24) -> 0 | W25: =SUM(W17:W24) -> 0
A26: Instructions:
A27: * Rest of State - New York Control Area outside of New York City & Long Island
B28: Do Not Delete Yellow Row
B29: Do Not Enter Information
B31: Your Name | J31: Contact Phone#:
F32: Comments:
B33: Company Name:
B34: Company Address:
B39: Contact E-Mail:
A79: Short Name | B79: Logical | C79: PTID | D79: Resource Name
A80: 1stRoch | B80: Y | C80: 1 | D80: ISOStrpS
A81: 3mP&P | B81: N | C81: 2 | D81: ISOMoMAY
A82: AdvantEn | C82: 3 | D82: ISODfMAY
A83: AEPSysOp | C83: 4 | D83: ISOSuMay
A84: AESCreRe | C84: 5 | D84: ISOMoJUN
A85: AESEastE | C85: 6 | D85: ISODfJUN
A86: AESNuEn | C86: 7 | D86: ISOSuJun
A87: AgwayES | C87: 8 | D87: ISOMoJUL
A88: AllegEnS | C88: 9 | D88: ISODfJUL
A89: AllegPwr | C89: 10 | D89: ISOSuJul
A90: AmerHess | C90: 11 | D90: ISOMoAUG
...

Sheet Nov OPP
D3: SUBMIT TO: | I3: New York Independent System Operator
D4: sellicap@nyiso.com | I4: Installed Capacity (UCAP) Strip Auction
I6: Offers to Sell
H7: Not To Be Used For The Strip Auction
D8: Auction Month: | E8: November | G8: 1 | K8: Date submitted: | M8: 36526
G9: Submittal Number | K9: Time submitted: | M9: 0.625
D11: Registrant Name:
B14: Seller's | F14: Minimum Price | G14: Amount (MW) | H14: Location ( indicate a (1) for chosen area and (0) for other areas)
A15: Offer# | B15: Name | C15: NYC | D15: PTID# | E15: Resource Name | F15: [($/kW- per month) | G15: [express to | H15: NYC | I15: LI | J15: ROS* | K15: PJM | L15: ISO-NE | M15: HQ | N15: O-IMO
C16: Mitigated | F16: express to nearest $.01] | G16: nearest 0.1 MW]
A17: 1 | B17: =IF(D17=0," ",+$E$11) | C17: N | E17: =IF(ISERROR(VLOOKUP(D17,$C$80:$D$700,2)),"",VLOOKUP(D17,$C$80:$D$700,2)) | H17: 0 | I17: 0 | J17: 0 | K17: 0 | L17: 0 | M17: 0 | N17: 0 | O17: =+$E$8 -> November | P17: =+$G$8 -> 1 | Q17: =+$M$8 -> 36526 | R17: =+$M$9 -> 0.625 | S17: =IF(AND(OR(H17=0,H17=1),OR(I17=0,I17=1),OR(J17=0,J17=1),OR(K17=0,K17=1),OR(L17=0,L17=1),OR(N17=0,N17=1),OR(M17=0,M17=1)),0,1) -> 0 | T17: =IF(L17+N17>0,1,0) -> 0 | U17: =IF(SUM(H17:N17)>1,1,0) -> 0 | V17: =IF(AND(G17>0,SUM(H17:N17)=0),1,0) -> 0 | W17: =IF(H17>0,1,0) -> 0
A18: =COUNT($A$17:A17)+1 -> 2 | B18: =IF(D18=0," ",+$E$11) | C18: N | E18: =IF(ISERROR(VLOOKUP(D18,$C$80:$D$700,2)),"",VLOOKUP(D18,$C$80:$D$700,2)) | H18: 0 | I18: 0 | J18: 0 | K18: 0 | L18: 0 | M18: 0 | N18: 0 | O18: =+$E$8 -> November | P18: =+$G$8 -> 1 | Q18: =+$M$8 -> 36526 | R18: =+$M$9 -> 0.625 | S18: =IF(AND(OR(H18=0,H18=1),OR(I18=0,I18=1),OR(J18=0,J18=1),OR(K18=0,K18=1),OR(L18=0,L18=1),OR(N18=0,N18=1),OR(M18=0,M18=1)),0,1) -> 0 | T18: =IF(L18+N18>0,1,0) -> 0 | U18: =IF(SUM(H18:N18)>1,1,0) -> 0 | V18: =IF(AND(G18>0,SUM(H18:N18)=0),1,0) -> 0 | W18: =IF(H18>0,1,0) -> 0
A19: =COUNT($A$17:A18)+1 -> 3 | B19: =IF(D19=0," ",+$E$11) | C19: N | E19: =IF(ISERROR(VLOOKUP(D19,$C$80:$D$700,2)),"",VLOOKUP(D19,$C$80:$D$700,2)) | H19: 0 | I19: 0 | J19: 0 | K19: 0 | L19: 0 | M19: 0 | N19: 0 | O19: =+$E$8 -> November | P19: =+$G$8 -> 1 | Q19: =+$M$8 -> 36526 | R19: =+$M$9 -> 0.625 | S19: =IF(AND(OR(H19=0,H19=1),OR(I19=0,I19=1),OR(J19=0,J19=1),OR(K19=0,K19=1),OR(L19=0,L19=1),OR(N19=0,N19=1),OR(M19=0,M19=1)),0,1) -> 0 | T19: =IF(L19+N19>0,1,0) -> 0 | U19: =IF(SUM(H19:N19)>1,1,0) -> 0 | V19: =IF(AND(G19>0,SUM(H19:N19)=0),1,0) -> 0 | W19: =IF(H19>0,1,0) -> 0
A20: =COUNT($A$17:A19)+1 -> 4 | B20: =IF(D20=0," ",+$E$11) | C20: N | E20: =IF(ISERROR(VLOOKUP(D20,$C$80:$D$700,2)),"",VLOOKUP(D20,$C$80:$D$700,2)) | H20: 0 | I20: 0 | J20: 0 | K20: 0 | L20: 0 | M20: 0 | N20: 0 | O20: =+$E$8 -> November | P20: =+$G$8 -> 1 | Q20: =+$M$8 -> 36526 | R20: =+$M$9 -> 0.625 | S20: =IF(AND(OR(H20=0,H20=1),OR(I20=0,I20=1),OR(J20=0,J20=1),OR(K20=0,K20=1),OR(L20=0,L20=1),OR(N20=0,N20=1),OR(M20=0,M20=1)),0,1) -> 0 | T20: =IF(L20+N20>0,1,0) -> 0 | U20: =IF(SUM(H20:N20)>1,1,0) -> 0 | V20: =IF(AND(G20>0,SUM(H20:N20)=0),1,0) -> 0 | W20: =IF(H20>0,1,0) -> 0
A21: =COUNT($A$17:A20)+1 -> 5 | B21: =IF(D21=0," ",+$E$11) | C21: N | E21: =IF(ISERROR(VLOOKUP(D21,$C$80:$D$700,2)),"",VLOOKUP(D21,$C$80:$D$700,2)) | H21: 0 | I21: 0 | J21: 0 | K21: 0 | L21: 0 | M21: 0 | N21: 0 | O21: =+$E$8 -> November | P21: =+$G$8 -> 1 | Q21: =+$M$8 -> 36526 | R21: =+$M$9 -> 0.625 | S21: =IF(AND(OR(H21=0,H21=1),OR(I21=0,I21=1),OR(J21=0,J21=1),OR(K21=0,K21=1),OR(L21=0,L21=1),OR(N21=0,N21=1),OR(M21=0,M21=1)),0,1) -> 0 | T21: =IF(L21+N21>0,1,0) -> 0 | U21: =IF(SUM(H21:N21)>1,1,0) -> 0 | V21: =IF(AND(G21>0,SUM(H21:N21)=0),1,0) -> 0 | W21: =IF(H21>0,1,0) -> 0
A22: =COUNT($A$17:A21)+1 -> 6 | B22: =IF(D22=0," ",+$E$11) | C22: N | E22: =IF(ISERROR(VLOOKUP(D22,$C$80:$D$700,2)),"",VLOOKUP(D22,$C$80:$D$700,2)) | H22: 0 | I22: 0 | J22: 0 | K22: 0 | L22: 0 | M22: 0 | N22: 0 | O22: =+$E$8 -> November | P22: =+$G$8 -> 1 | Q22: =+$M$8 -> 36526 | R22: =+$M$9 -> 0.625 | S22: =IF(AND(OR(H22=0,H22=1),OR(I22=0,I22=1),OR(J22=0,J22=1),OR(K22=0,K22=1),OR(L22=0,L22=1),OR(N22=0,N22=1),OR(M22=0,M22=1)),0,1) -> 0 | T22: =IF(L22+N22>0,1,0) -> 0 | U22: =IF(SUM(H22:N22)>1,1,0) -> 0 | V22: =IF(AND(G22>0,SUM(H22:N22)=0),1,0) -> 0 | W22: =IF(H22>0,1,0) -> 0
A23: =COUNT($A$17:A22)+1 -> 7 | B23: =IF(D23=0," ",+$E$11) | C23: N | E23: =IF(ISERROR(VLOOKUP(D23,$C$80:$D$700,2)),"",VLOOKUP(D23,$C$80:$D$700,2)) | H23: 0 | I23: 0 | J23: 0 | K23: 0 | L23: 0 | M23: 0 | N23: 0 | O23: =+$E$8 -> November | P23: =+$G$8 -> 1 | Q23: =+$M$8 -> 36526 | R23: =+$M$9 -> 0.625 | S23: =IF(AND(OR(H23=0,H23=1),OR(I23=0,I23=1),OR(J23=0,J23=1),OR(K23=0,K23=1),OR(L23=0,L23=1),OR(N23=0,N23=1),OR(M23=0,M23=1)),0,1) -> 0 | T23: =IF(L23+N23>0,1,0) -> 0 | U23: =IF(SUM(H23:N23)>1,1,0) -> 0 | V23: =IF(AND(G23>0,SUM(H23:N23)=0),1,0) -> 0 | W23: =IF(H23>0,1,0) -> 0
A24: =COUNT($A$17:A23)+1 -> 8 | B24: =IF(D24=0," ",+$E$11) | C24: N | E24: =IF(ISERROR(VLOOKUP(D24,$C$80:$D$700,2)),"",VLOOKUP(D24,$C$80:$D$700,2)) | H24: 0 | I24: 0 | J24: 0 | K24: 0 | L24: 0 | M24: 0 | N24: 0 | O24: =+$E$8 -> November | P24: =+$G$8 -> 1 | Q24: =+$M$8 -> 36526 | R24: =+$M$9 -> 0.625 | S24: =IF(AND(OR(H24=0,H24=1),OR(I24=0,I24=1),OR(J24=0,J24=1),OR(K24=0,K24=1),OR(L24=0,L24=1),OR(N24=0,N24=1),OR(M24=0,M24=1)),0,1) -> 0 | T24: =IF(L24+N24>0,1,0) -> 0 | U24: =IF(SUM(H24:N24)>1,1,0) -> 0 | V24: =IF(AND(G24>0,SUM(H24:N24)=0),1,0) -> 0 | W24: =IF(H24>0,1,0) -> 0
I25: =IF(T25+S25+U25+V25>0,"WARNING:","") | J25: =IF(S25>0,"Values above must be 1's or 0's",IF(T25>0,"NE and Ontario are not participating. These must be 0's",IF(U25>0,"Choose one location only",IF(V25>0,"You must select a location","")))) | S25: =SUM(S17:S24) -> 0 | T25: =SUM(T17:T24) -> 0 | U25: =SUM(U17:U24) -> 0 | V25: =SUM(V17:V24) -> 0 | W25: =SUM(W17:W24) -> 0
A26: Instructions:
A27: * Rest of State - New York Control Area outside of New York City & Long Island
B28: Do Not Delete Yellow Row
B29: Do Not Enter Information
D30: Contact Name: | K30: Contact Phone#:
B32: Your Name | C32: Your Name Goes Here | J32: Contact Phone#: | L32: Your Phone # Here
F33: Comments:
B34: Company Name: | C34: Company
B35: Company Address: | C35: Address 1
C36: Address 2
C37: Address 3
C38: City, State Zip
B40: Contact E-Mail: | C40: your @ address here
A79: Short Name | B79: Logical | C79: PTID | D79: Resource Name
A80: 1stRoch | B80: Y | C80: 1 | D80: ISOStrpS
A81: 3mP&P | B81: N | C81: 2 | D81: ISOMoMAY
A82: AdvantEn | C82: 3 | D82: ISODfMAY
A83: AEPSysOp | C83: 4 | D83: ISOSuMay
A84: AESCreRe | C84: 5 | D84: ISOMoJUN
A85: AESEastE | C85: 6 | D85: ISODfJUN
A86: AESNuEn | C86: 7 | D86: ISOSuJun
...

Sheet Dec OPP
D3: SUBMIT TO: | I3: New York Independent System Operator
D4: sellicap@nyiso.com | I4: Installed Capacity (UCAP) Strip Auction
I6: Offers to Sell
H7: Not To Be Used For The Strip Auction
C8: Auction Month: | E8: December | G8: 1 | K8: Date submitted: | M8: =+'Nov OPP'!M8 -> 36526
G9: Submittal Number | K9: Time submitted: | M9: =+'Nov OPP'!M9 -> 0.625
C11: Registrant Name:
B14: Seller's | F14: Minimum Price | G14: Amount (MW) | H14: Location ( indicate a (1) for chosen area and (0) for other areas)
A15: Offer# | B15: Name | C15: NYC | D15: PTID# | E15: Resource Name | F15: [($/kW- per month) | G15: [express to | H15: NYC | I15: LI | J15: ROS* | K15: PJM | L15: ISO-NE | M15: HQ | N15: O-IMO
C16: Mitigated | F16: express to nearest $.01] | G16: nearest 0.1 MW]
A17: 1 | B17: =IF(D17=0," ",+$E$11) | C17: N | E17: =IF(ISERROR(VLOOKUP(D17,$C$80:$D$700,2)),"",VLOOKUP(D17,$C$80:$D$700,2)) | H17: 0 | I17: 0 | J17: 0 | K17: 0 | L17: 0 | M17: 0 | N17: 0 | O17: =+$E$8 -> December | P17: =+$G$8 -> 1 | Q17: =+$M$8 -> 36526 | R17: =+$M$9 -> 0.625 | S17: =IF(AND(OR(H17=0,H17=1),OR(I17=0,I17=1),OR(J17=0,J17=1),OR(K17=0,K17=1),OR(L17=0,L17=1),OR(N17=0,N17=1),OR(M17=0,M17=1)),0,1) -> 0 | T17: =IF(L17+N17>0,1,0) -> 0 | U17: =IF(SUM(H17:N17)>1,1,0) -> 0 | V17: =IF(AND(G17>0,SUM(H17:N17)=0),1,0) -> 0 | W17: =IF(H17>0,1,0) -> 0
A18: =COUNT($A$17:A17)+1 -> 2 | B18: =IF(D18=0," ",+$E$11) | C18: N | E18: =IF(ISERROR(VLOOKUP(D18,$C$80:$D$700,2)),"",VLOOKUP(D18,$C$80:$D$700,2)) | H18: 0 | I18: 0 | J18: 0 | K18: 0 | L18: 0 | M18: 0 | N18: 0 | O18: =+$E$8 -> December | P18: =+$G$8 -> 1 | Q18: =+$M$8 -> 36526 | R18: =+$M$9 -> 0.625 | S18: =IF(AND(OR(H18=0,H18=1),OR(I18=0,I18=1),OR(J18=0,J18=1),OR(K18=0,K18=1),OR(L18=0,L18=1),OR(N18=0,N18=1),OR(M18=0,M18=1)),0,1) -> 0 | T18: =IF(L18+N18>0,1,0) -> 0 | U18: =IF(SUM(H18:N18)>1,1,0) -> 0 | V18: =IF(AND(G18>0,SUM(H18:N18)=0),1,0) -> 0 | W18: =IF(H18>0,1,0) -> 0
A19: =COUNT($A$17:A18)+1 -> 3 | B19: =IF(D19=0," ",+$E$11) | C19: N | E19: =IF(ISERROR(VLOOKUP(D19,$C$80:$D$700,2)),"",VLOOKUP(D19,$C$80:$D$700,2)) | H19: 0 | I19: 0 | J19: 0 | K19: 0 | L19: 0 | M19: 0 | N19: 0 | O19: =+$E$8 -> December | P19: =+$G$8 -> 1 | Q19: =+$M$8 -> 36526 | R19: =+$M$9 -> 0.625 | S19: =IF(AND(OR(H19=0,H19=1),OR(I19=0,I19=1),OR(J19=0,J19=1),OR(K19=0,K19=1),OR(L19=0,L19=1),OR(N19=0,N19=1),OR(M19=0,M19=1)),0,1) -> 0 | T19: =IF(L19+N19>0,1,0) -> 0 | U19: =IF(SUM(H19:N19)>1,1,0) -> 0 | V19: =IF(AND(G19>0,SUM(H19:N19)=0),1,0) -> 0 | W19: =IF(H19>0,1,0) -> 0
A20: =COUNT($A$17:A19)+1 -> 4 | B20: =IF(D20=0," ",+$E$11) | C20: N | E20: =IF(ISERROR(VLOOKUP(D20,$C$80:$D$700,2)),"",VLOOKUP(D20,$C$80:$D$700,2)) | H20: 0 | I20: 0 | J20: 0 | K20: 0 | L20: 0 | M20: 0 | N20: 0 | O20: =+$E$8 -> December | P20: =+$G$8 -> 1 | Q20: =+$M$8 -> 36526 | R20: =+$M$9 -> 0.625 | S20: =IF(AND(OR(H20=0,H20=1),OR(I20=0,I20=1),OR(J20=0,J20=1),OR(K20=0,K20=1),OR(L20=0,L20=1),OR(N20=0,N20=1),OR(M20=0,M20=1)),0,1) -> 0 | T20: =IF(L20+N20>0,1,0) -> 0 | U20: =IF(SUM(H20:N20)>1,1,0) -> 0 | V20: =IF(AND(G20>0,SUM(H20:N20)=0),1,0) -> 0 | W20: =IF(H20>0,1,0) -> 0
A21: =COUNT($A$17:A20)+1 -> 5 | B21: =IF(D21=0," ",+$E$11) | C21: N | E21: =IF(ISERROR(VLOOKUP(D21,$C$80:$D$700,2)),"",VLOOKUP(D21,$C$80:$D$700,2)) | H21: 0 | I21: 0 | J21: 0 | K21: 0 | L21: 0 | M21: 0 | N21: 0 | O21: =+$E$8 -> December | P21: =+$G$8 -> 1 | Q21: =+$M$8 -> 36526 | R21: =+$M$9 -> 0.625 | S21: =IF(AND(OR(H21=0,H21=1),OR(I21=0,I21=1),OR(J21=0,J21=1),OR(K21=0,K21=1),OR(L21=0,L21=1),OR(N21=0,N21=1),OR(M21=0,M21=1)),0,1) -> 0 | T21: =IF(L21+N21>0,1,0) -> 0 | U21: =IF(SUM(H21:N21)>1,1,0) -> 0 | V21: =IF(AND(G21>0,SUM(H21:N21)=0),1,0) -> 0 | W21: =IF(H21>0,1,0) -> 0
A22: =COUNT($A$17:A21)+1 -> 6 | B22: =IF(D22=0," ",+$E$11) | C22: N | E22: =IF(ISERROR(VLOOKUP(D22,$C$80:$D$700,2)),"",VLOOKUP(D22,$C$80:$D$700,2)) | H22: 0 | I22: 0 | J22: 0 | K22: 0 | L22: 0 | M22: 0 | N22: 0 | O22: =+$E$8 -> December | P22: =+$G$8 -> 1 | Q22: =+$M$8 -> 36526 | R22: =+$M$9 -> 0.625 | S22: =IF(AND(OR(H22=0,H22=1),OR(I22=0,I22=1),OR(J22=0,J22=1),OR(K22=0,K22=1),OR(L22=0,L22=1),OR(N22=0,N22=1),OR(M22=0,M22=1)),0,1) -> 0 | T22: =IF(L22+N22>0,1,0) -> 0 | U22: =IF(SUM(H22:N22)>1,1,0) -> 0 | V22: =IF(AND(G22>0,SUM(H22:N22)=0),1,0) -> 0 | W22: =IF(H22>0,1,0) -> 0
A23: =COUNT($A$17:A22)+1 -> 7 | B23: =IF(D23=0," ",+$E$11) | C23: N | E23: =IF(ISERROR(VLOOKUP(D23,$C$80:$D$700,2)),"",VLOOKUP(D23,$C$80:$D$700,2)) | H23: 0 | I23: 0 | J23: 0 | K23: 0 | L23: 0 | M23: 0 | N23: 0 | O23: =+$E$8 -> December | P23: =+$G$8 -> 1 | Q23: =+$M$8 -> 36526 | R23: =+$M$9 -> 0.625 | S23: =IF(AND(OR(H23=0,H23=1),OR(I23=0,I23=1),OR(J23=0,J23=1),OR(K23=0,K23=1),OR(L23=0,L23=1),OR(N23=0,N23=1),OR(M23=0,M23=1)),0,1) -> 0 | T23: =IF(L23+N23>0,1,0) -> 0 | U23: =IF(SUM(H23:N23)>1,1,0) -> 0 | V23: =IF(AND(G23>0,SUM(H23:N23)=0),1,0) -> 0 | W23: =IF(H23>0,1,0) -> 0
A24: =COUNT($A$17:A23)+1 -> 8 | B24: =IF(D24=0," ",+$E$11) | C24: N | E24: =IF(ISERROR(VLOOKUP(D24,$C$80:$D$700,2)),"",VLOOKUP(D24,$C$80:$D$700,2)) | H24: 0 | I24: 0 | J24: 0 | K24: 0 | L24: 0 | M24: 0 | N24: 0 | O24: =+$E$8 -> December | P24: =+$G$8 -> 1 | Q24: =+$M$8 -> 36526 | R24: =+$M$9 -> 0.625 | S24: =IF(AND(OR(H24=0,H24=1),OR(I24=0,I24=1),OR(J24=0,J24=1),OR(K24=0,K24=1),OR(L24=0,L24=1),OR(N24=0,N24=1),OR(M24=0,M24=1)),0,1) -> 0 | T24: =IF(L24+N24>0,1,0) -> 0 | U24: =IF(SUM(H24:N24)>1,1,0) -> 0 | V24: =IF(AND(G24>0,SUM(H24:N24)=0),1,0) -> 0 | W24: =IF(H24>0,1,0) -> 0
I25: =IF(T25+S25+U25+V25>0,"WARNING:","") | J25: =IF(S25>0,"Values above must be 1's or 0's",IF(T25>0,"NE and Ontario are not participating. These must be 0's",IF(U25>0,"Choose one location only",IF(V25>0,"You must select a location","")))) | S25: =SUM(S17:S24) -> 0 | T25: =SUM(T17:T24) -> 0 | U25: =SUM(U17:U24) -> 0 | V25: =SUM(V17:V24) -> 0 | W25: =SUM(W17:W24) -> 0
A26: Instructions:
A27: * Rest of State - New York Control Area outside of New York City & Long Island
B28: Do Not Delete Yellow Row
B29: Do Not Enter Information
D30: Contact Name: | K30: Contact Phone#:
B32: Your Name | C32: =+'Nov OPP'!C32 -> Your Name Goes Here | J32: Contact Phone#: | L32: =+'Nov OPP'!L32 -> Your Phone # Here
F33: Comments:
B34: Company Name: | C34: =+'Nov OPP'!C34 -> Company
B35: Company Address: | C35: =+'Nov OPP'!C35 -> Address 1
C36: =+'Nov OPP'!C36 -> Address 2
C37: =+'Nov OPP'!C37 -> Address 3
C38: =+'Nov OPP'!C38 -> City, State Zip
B40: Contact E-Mail: | C40: =+'Nov OPP'!C40 -> your @ address here
A79: Short Name | B79: Logical | C79: PTID | D79: Resource Name
A80: 1stRoch | B80: Y | C80: 1 | D80: ISOStrpS
A81: 3mP&P | B81: N | C81: 2 | D81: ISOMoMAY
A82: AdvantEn | C82: 3 | D82: ISODfMAY
A83: AEPSysOp | C83: 4 | D83: ISOSuMay
A84: AESCreRe | C84: 5 | D84: ISOMoJUN
A85: AESEastE | C85: 6 | D85: ISODfJUN
A86: AESNuEn | C86: 7 | D86: ISOSuJun
...

Sheet Jan OPP
D3: SUBMIT TO: | I3: New York Independent System Operator
D4: sellicap@nyiso.com | I4: Installed Capacity (UCAP) Strip Auction
I6: Offers to Sell
H7: Not To Be Used For The Strip Auction
D8: Auction Month: | E8: January | G8: 1 | K8: Date submitted: | M8: =+'Dec OPP'!M8 -> 36526
G9: Submittal Number | K9: Time submitted: | M9: =+'Dec OPP'!M9 -> 0.625
D11: Registrant Name:
B14: Seller's | F14: Minimum Price | G14: Amount (MW) | H14: Location ( indicate a (1) for chosen area and (0) for other areas)
A15: Offer# | B15: Name | C15: NYC | D15: PTID# | E15: Resource Name | F15: [($/kW- per month) | G15: [express to | H15: NYC | I15: LI | J15: ROS* | K15: PJM | L15: ISO-NE | M15: HQ | N15: O-IMO
C16: Mitigated | F16: express to nearest $.01] | G16: nearest 0.1 MW]
A17: 1 | B17: =IF(D17=0," ",+$E$11) | C17: N | E17: =IF(ISERROR(VLOOKUP(D17,$C$80:$D$700,2)),"",VLOOKUP(D17,$C$80:$D$700,2)) | H17: 0 | I17: 0 | J17: 0 | K17: 0 | L17: 0 | M17: 0 | N17: 0 | O17: =+$E$8 -> January | P17: =+$G$8 -> 1 | Q17: =+$M$8 -> 36526 | R17: =+$M$9 -> 0.625 | S17: =IF(AND(OR(H17=0,H17=1),OR(I17=0,I17=1),OR(J17=0,J17=1),OR(K17=0,K17=1),OR(L17=0,L17=1),OR(N17=0,N17=1),OR(M17=0,M17=1)),0,1) -> 0 | T17: =IF(L17+N17>0,1,0) -> 0 | U17: =IF(SUM(H17:N17)>1,1,0) -> 0 | V17: =IF(AND(G17>0,SUM(H17:N17)=0),1,0) -> 0 | W17: =IF(H17>0,1,0) -> 0
A18: =COUNT($A$17:A17)+1 -> 2 | B18: =IF(D18=0," ",+$E$11) | C18: N | E18: =IF(ISERROR(VLOOKUP(D18,$C$80:$D$700,2)),"",VLOOKUP(D18,$C$80:$D$700,2)) | H18: 0 | I18: 0 | J18: 0 | K18: 0 | L18: 0 | M18: 0 | N18: 0 | O18: =+$E$8 -> January | P18: =+$G$8 -> 1 | Q18: =+$M$8 -> 36526 | R18: =+$M$9 -> 0.625 | S18: =IF(AND(OR(H18=0,H18=1),OR(I18=0,I18=1),OR(J18=0,J18=1),OR(K18=0,K18=1),OR(L18=0,L18=1),OR(N18=0,N18=1),OR(M18=0,M18=1)),0,1) -> 0 | T18: =IF(L18+N18>0,1,0) -> 0 | U18: =IF(SUM(H18:N18)>1,1,0) -> 0 | V18: =IF(AND(G18>0,SUM(H18:N18)=0),1,0) -> 0 | W18: =IF(H18>0,1,0) -> 0
A19: =COUNT($A$17:A18)+1 -> 3 | B19: =IF(D19=0," ",+$E$11) | C19: N | E19: =IF(ISERROR(VLOOKUP(D19,$C$80:$D$700,2)),"",VLOOKUP(D19,$C$80:$D$700,2)) | H19: 0 | I19: 0 | J19: 0 | K19: 0 | L19: 0 | M19: 0 | N19: 0 | O19: =+$E$8 -> January | P19: =+$G$8 -> 1 | Q19: =+$M$8 -> 36526 | R19: =+$M$9 -> 0.625 | S19: =IF(AND(OR(H19=0,H19=1),OR(I19=0,I19=1),OR(J19=0,J19=1),OR(K19=0,K19=1),OR(L19=0,L19=1),OR(N19=0,N19=1),OR(M19=0,M19=1)),0,1) -> 0 | T19: =IF(L19+N19>0,1,0) -> 0 | U19: =IF(SUM(H19:N19)>1,1,0) -> 0 | V19: =IF(AND(G19>0,SUM(H19:N19)=0),1,0) -> 0 | W19: =IF(H19>0,1,0) -> 0
A20: =COUNT($A$17:A19)+1 -> 4 | B20: =IF(D20=0," ",+$E$11) | C20: N | E20: =IF(ISERROR(VLOOKUP(D20,$C$80:$D$700,2)),"",VLOOKUP(D20,$C$80:$D$700,2)) | H20: 0 | I20: 0 | J20: 0 | K20: 0 | L20: 0 | M20: 0 | N20: 0 | O20: =+$E$8 -> January | P20: =+$G$8 -> 1 | Q20: =+$M$8 -> 36526 | R20: =+$M$9 -> 0.625 | S20: =IF(AND(OR(H20=0,H20=1),OR(I20=0,I20=1),OR(J20=0,J20=1),OR(K20=0,K20=1),OR(L20=0,L20=1),OR(N20=0,N20=1),OR(M20=0,M20=1)),0,1) -> 0 | T20: =IF(L20+N20>0,1,0) -> 0 | U20: =IF(SUM(H20:N20)>1,1,0) -> 0 | V20: =IF(AND(G20>0,SUM(H20:N20)=0),1,0) -> 0 | W20: =IF(H20>0,1,0) -> 0
A21: =COUNT($A$17:A20)+1 -> 5 | B21: =IF(D21=0," ",+$E$11) | C21: N | E21: =IF(ISERROR(VLOOKUP(D21,$C$80:$D$700,2)),"",VLOOKUP(D21,$C$80:$D$700,2)) | H21: 0 | I21: 0 | J21: 0 | K21: 0 | L21: 0 | M21: 0 | N21: 0 | O21: =+$E$8 -> January | P21: =+$G$8 -> 1 | Q21: =+$M$8 -> 36526 | R21: =+$M$9 -> 0.625 | S21: =IF(AND(OR(H21=0,H21=1),OR(I21=0,I21=1),OR(J21=0,J21=1),OR(K21=0,K21=1),OR(L21=0,L21=1),OR(N21=0,N21=1),OR(M21=0,M21=1)),0,1) -> 0 | T21: =IF(L21+N21>0,1,0) -> 0 | U21: =IF(SUM(H21:N21)>1,1,0) -> 0 | V21: =IF(AND(G21>0,SUM(H21:N21)=0),1,0) -> 0 | W21: =IF(H21>0,1,0) -> 0
A22: =COUNT($A$17:A21)+1 -> 6 | B22: =IF(D22=0," ",+$E$11) | C22: N | E22: =IF(ISERROR(VLOOKUP(D22,$C$80:$D$700,2)),"",VLOOKUP(D22,$C$80:$D$700,2)) | H22: 0 | I22: 0 | J22: 0 | K22: 0 | L22: 0 | M22: 0 | N22: 0 | O22: =+$E$8 -> January | P22: =+$G$8 -> 1 | Q22: =+$M$8 -> 36526 | R22: =+$M$9 -> 0.625 | S22: =IF(AND(OR(H22=0,H22=1),OR(I22=0,I22=1),OR(J22=0,J22=1),OR(K22=0,K22=1),OR(L22=0,L22=1),OR(N22=0,N22=1),OR(M22=0,M22=1)),0,1) -> 0 | T22: =IF(L22+N22>0,1,0) -> 0 | U22: =IF(SUM(H22:N22)>1,1,0) -> 0 | V22: =IF(AND(G22>0,SUM(H22:N22)=0),1,0) -> 0 | W22: =IF(H22>0,1,0) -> 0
A23: =COUNT($A$17:A22)+1 -> 7 | B23: =IF(D23=0," ",+$E$11) | C23: N | E23: =IF(ISERROR(VLOOKUP(D23,$C$80:$D$700,2)),"",VLOOKUP(D23,$C$80:$D$700,2)) | H23: 0 | I23: 0 | J23: 0 | K23: 0 | L23: 0 | M23: 0 | N23: 0 | O23: =+$E$8 -> January | P23: =+$G$8 -> 1 | Q23: =+$M$8 -> 36526 | R23: =+$M$9 -> 0.625 | S23: =IF(AND(OR(H23=0,H23=1),OR(I23=0,I23=1),OR(J23=0,J23=1),OR(K23=0,K23=1),OR(L23=0,L23=1),OR(N23=0,N23=1),OR(M23=0,M23=1)),0,1) -> 0 | T23: =IF(L23+N23>0,1,0) -> 0 | U23: =IF(SUM(H23:N23)>1,1,0) -> 0 | V23: =IF(AND(G23>0,SUM(H23:N23)=0),1,0) -> 0 | W23: =IF(H23>0,1,0) -> 0
A24: =COUNT($A$17:A23)+1 -> 8 | B24: =IF(D24=0," ",+$E$11) | C24: N | E24: =IF(ISERROR(VLOOKUP(D24,$C$80:$D$700,2)),"",VLOOKUP(D24,$C$80:$D$700,2)) | H24: 0 | I24: 0 | J24: 0 | K24: 0 | L24: 0 | M24: 0 | N24: 0 | O24: =+$E$8 -> January | P24: =+$G$8 -> 1 | Q24: =+$M$8 -> 36526 | R24: =+$M$9 -> 0.625 | S24: =IF(AND(OR(H24=0,H24=1),OR(I24=0,I24=1),OR(J24=0,J24=1),OR(K24=0,K24=1),OR(L24=0,L24=1),OR(N24=0,N24=1),OR(M24=0,M24=1)),0,1) -> 0 | T24: =IF(L24+N24>0,1,0) -> 0 | U24: =IF(SUM(H24:N24)>1,1,0) -> 0 | V24: =IF(AND(G24>0,SUM(H24:N24)=0),1,0) -> 0 | W24: =IF(H24>0,1,0) -> 0
I25: =IF(T25+S25+U25+V25>0,"WARNING:","") | J25: =IF(S25>0,"Values above must be 1's or 0's",IF(T25>0,"NE and Ontario are not participating. These must be 0's",IF(U25>0,"Choose one location only",IF(V25>0,"You must select a location","")))) | S25: =SUM(S17:S24) -> 0 | T25: =SUM(T17:T24) -> 0 | U25: =SUM(U17:U24) -> 0 | V25: =SUM(V17:V24) -> 0 | W25: =SUM(W17:W24) -> 0
A26: Instructions:
A27: * Rest of State - New York Control Area outside of New York City & Long Island
B28: Do Not Delete Yellow Row
B29: Do Not Enter Information
D30: Contact Name: | K30: Contact Phone#:
B32: Your Name | C32: =+'Dec OPP'!C32 -> Your Name Goes Here | J32: Contact Phone#: | L32: =+'Dec OPP'!L32 -> Your Phone # Here
F33: Comments:
B34: Company Name: | C34: =+'Dec OPP'!C34 -> Company
B35: Company Address: | C35: =+'Dec OPP'!C35 -> Address 1
C36: =+'Dec OPP'!C36 -> Address 2
C37: =+'Dec OPP'!C37 -> Address 3
C38: =+'Dec OPP'!C38 -> City, State Zip
B40: Contact E-Mail: | C40: =+'Dec OPP'!C40 -> your @ address here
A79: Short Name | B79: Logical | C79: PTID | D79: Resource Name
A80: 1stRoch | B80: Y | C80: 1 | D80: ISOStrpS
A81: 3mP&P | B81: N | C81: 2 | D81: ISOMoMAY
A82: AdvantEn | C82: 3 | D82: ISODfMAY
A83: AEPSysOp | C83: 4 | D83: ISOSuMay
A84: AESCreRe | C84: 5 | D84: ISOMoJUN
A85: AESEastE | C85: 6 | D85: ISODfJUN
A86: AESNuEn | C86: 7 | D86: ISOSuJun
...

Sheet Feb OPP
D3: SUBMIT TO: | I3: New York Independent System Operator
D4: sellicap@nyiso.com | I4: Installed Capacity (UCAP) Strip Auction
I6: Offers to Sell
H7: Not To Be Used For The Strip Auction
D8: Auction Month: | E8: February | G8: 1 | K8: Date submitted: | M8: =+'Jan OPP'!M8 -> 36526
G9: Submittal Number | K9: Time submitted: | M9: =+'Jan OPP'!M9 -> 0.625
D11: Registrant Name:
B14: Seller's | F14: Minimum Price | G14: Amount (MW) | H14: Location ( indicate a (1) for chosen area and (0) for other areas)
A15: Offer# | B15: Name | C15: NYC | D15: PTID# | E15: Resource Name | F15: [($/kW- per month) | G15: [express to | H15: NYC | I15: LI | J15: ROS* | K15: PJM | L15: ISO-NE | M15: HQ | N15: O-IMO
C16: Mitigated | F16: express to nearest $.01] | G16: nearest 0.1 MW]
A17: 1 | B17: =IF(D17=0," ",+$E$11) | C17: N | E17: =IF(ISERROR(VLOOKUP(D17,$C$80:$D$700,2)),"",VLOOKUP(D17,$C$80:$D$700,2)) | H17: 0 | I17: 0 | J17: 0 | K17: 0 | L17: 0 | M17: 0 | N17: 0 | O17: =+$E$8 -> February | P17: =+$G$8 -> 1 | Q17: =+$M$8 -> 36526 | R17: =+$M$9 -> 0.625 | S17: =IF(AND(OR(H17=0,H17=1),OR(I17=0,I17=1),OR(J17=0,J17=1),OR(K17=0,K17=1),OR(L17=0,L17=1),OR(N17=0,N17=1),OR(M17=0,M17=1)),0,1) -> 0 | T17: =IF(L17+N17>0,1,0) -> 0 | U17: =IF(SUM(H17:N17)>1,1,0) -> 0 | V17: =IF(AND(G17>0,SUM(H17:N17)=0),1,0) -> 0 | W17: =IF(H17>0,1,0) -> 0
A18: =COUNT($A$17:A17)+1 -> 2 | B18: =IF(D18=0," ",+$E$11) | C18: N | E18: =IF(ISERROR(VLOOKUP(D18,$C$80:$D$700,2)),"",VLOOKUP(D18,$C$80:$D$700,2)) | H18: 0 | I18: 0 | J18: 0 | K18: 0 | L18: 0 | M18: 0 | N18: 0 | O18: =+$E$8 -> February | P18: =+$G$8 -> 1 | Q18: =+$M$8 -> 36526 | R18: =+$M$9 -> 0.625 | S18: =IF(AND(OR(H18=0,H18=1),OR(I18=0,I18=1),OR(J18=0,J18=1),OR(K18=0,K18=1),OR(L18=0,L18=1),OR(N18=0,N18=1),OR(M18=0,M18=1)),0,1) -> 0 | T18: =IF(L18+N18>0,1,0) -> 0 | U18: =IF(SUM(H18:N18)>1,1,0) -> 0 | V18: =IF(AND(G18>0,SUM(H18:N18)=0),1,0) -> 0 | W18: =IF(H18>0,1,0) -> 0
A19: =COUNT($A$17:A18)+1 -> 3 | B19: =IF(D19=0," ",+$E$11) | C19: N | E19: =IF(ISERROR(VLOOKUP(D19,$C$80:$D$700,2)),"",VLOOKUP(D19,$C$80:$D$700,2)) | H19: 0 | I19: 0 | J19: 0 | K19: 0 | L19: 0 | M19: 0 | N19: 0 | O19: =+$E$8 -> February | P19: =+$G$8 -> 1 | Q19: =+$M$8 -> 36526 | R19: =+$M$9 -> 0.625 | S19: =IF(AND(OR(H19=0,H19=1),OR(I19=0,I19=1),OR(J19=0,J19=1),OR(K19=0,K19=1),OR(L19=0,L19=1),OR(N19=0,N19=1),OR(M19=0,M19=1)),0,1) -> 0 | T19: =IF(L19+N19>0,1,0) -> 0 | U19: =IF(SUM(H19:N19)>1,1,0) -> 0 | V19: =IF(AND(G19>0,SUM(H19:N19)=0),1,0) -> 0 | W19: =IF(H19>0,1,0) -> 0
A20: =COUNT($A$17:A19)+1 -> 4 | B20: =IF(D20=0," ",+$E$11) | C20: N | E20: =IF(ISERROR(VLOOKUP(D20,$C$80:$D$700,2)),"",VLOOKUP(D20,$C$80:$D$700,2)) | H20: 0 | I20: 0 | J20: 0 | K20: 0 | L20: 0 | M20: 0 | N20: 0 | O20: =+$E$8 -> February | P20: =+$G$8 -> 1 | Q20: =+$M$8 -> 36526 | R20: =+$M$9 -> 0.625 | S20: =IF(AND(OR(H20=0,H20=1),OR(I20=0,I20=1),OR(J20=0,J20=1),OR(K20=0,K20=1),OR(L20=0,L20=1),OR(N20=0,N20=1),OR(M20=0,M20=1)),0,1) -> 0 | T20: =IF(L20+N20>0,1,0) -> 0 | U20: =IF(SUM(H20:N20)>1,1,0) -> 0 | V20: =IF(AND(G20>0,SUM(H20:N20)=0),1,0) -> 0 | W20: =IF(H20>0,1,0) -> 0
A21: =COUNT($A$17:A20)+1 -> 5 | B21: =IF(D21=0," ",+$E$11) | C21: N | E21: =IF(ISERROR(VLOOKUP(D21,$C$80:$D$700,2)),"",VLOOKUP(D21,$C$80:$D$700,2)) | H21: 0 | I21: 0 | J21: 0 | K21: 0 | L21: 0 | M21: 0 | N21: 0 | O21: =+$E$8 -> February | P21: =+$G$8 -> 1 | Q21: =+$M$8 -> 36526 | R21: =+$M$9 -> 0.625 | S21: =IF(AND(OR(H21=0,H21=1),OR(I21=0,I21=1),OR(J21=0,J21=1),OR(K21=0,K21=1),OR(L21=0,L21=1),OR(N21=0,N21=1),OR(M21=0,M21=1)),0,1) -> 0 | T21: =IF(L21+N21>0,1,0) -> 0 | U21: =IF(SUM(H21:N21)>1,1,0) -> 0 | V21: =IF(AND(G21>0,SUM(H21:N21)=0),1,0) -> 0 | W21: =IF(H21>0,1,0) -> 0
A22: =COUNT($A$17:A21)+1 -> 6 | B22: =IF(D22=0," ",+$E$11) | C22: N | E22: =IF(ISERROR(VLOOKUP(D22,$C$80:$D$700,2)),"",VLOOKUP(D22,$C$80:$D$700,2)) | H22: 0 | I22: 0 | J22: 0 | K22: 0 | L22: 0 | M22: 0 | N22: 0 | O22: =+$E$8 -> February | P22: =+$G$8 -> 1 | Q22: =+$M$8 -> 36526 | R22: =+$M$9 -> 0.625 | S22: =IF(AND(OR(H22=0,H22=1),OR(I22=0,I22=1),OR(J22=0,J22=1),OR(K22=0,K22=1),OR(L22=0,L22=1),OR(N22=0,N22=1),OR(M22=0,M22=1)),0,1) -> 0 | T22: =IF(L22+N22>0,1,0) -> 0 | U22: =IF(SUM(H22:N22)>1,1,0) -> 0 | V22: =IF(AND(G22>0,SUM(H22:N22)=0),1,0) -> 0 | W22: =IF(H22>0,1,0) -> 0
A23: =COUNT($A$17:A22)+1 -> 7 | B23: =IF(D23=0," ",+$E$11) | C23: N | E23: =IF(ISERROR(VLOOKUP(D23,$C$80:$D$700,2)),"",VLOOKUP(D23,$C$80:$D$700,2)) | H23: 0 | I23: 0 | J23: 0 | K23: 0 | L23: 0 | M23: 0 | N23: 0 | O23: =+$E$8 -> February | P23: =+$G$8 -> 1 | Q23: =+$M$8 -> 36526 | R23: =+$M$9 -> 0.625 | S23: =IF(AND(OR(H23=0,H23=1),OR(I23=0,I23=1),OR(J23=0,J23=1),OR(K23=0,K23=1),OR(L23=0,L23=1),OR(N23=0,N23=1),OR(M23=0,M23=1)),0,1) -> 0 | T23: =IF(L23+N23>0,1,0) -> 0 | U23: =IF(SUM(H23:N23)>1,1,0) -> 0 | V23: =IF(AND(G23>0,SUM(H23:N23)=0),1,0) -> 0 | W23: =IF(H23>0,1,0) -> 0
A24: =COUNT($A$17:A23)+1 -> 8 | B24: =IF(D24=0," ",+$E$11) | C24: N | E24: =IF(ISERROR(VLOOKUP(D24,$C$80:$D$700,2)),"",VLOOKUP(D24,$C$80:$D$700,2)) | H24: 0 | I24: 0 | J24: 0 | K24: 0 | L24: 0 | M24: 0 | N24: 0 | O24: =+$E$8 -> February | P24: =+$G$8 -> 1 | Q24: =+$M$8 -> 36526 | R24: =+$M$9 -> 0.625 | S24: =IF(AND(OR(H24=0,H24=1),OR(I24=0,I24=1),OR(J24=0,J24=1),OR(K24=0,K24=1),OR(L24=0,L24=1),OR(N24=0,N24=1),OR(M24=0,M24=1)),0,1) -> 0 | T24: =IF(L24+N24>0,1,0) -> 0 | U24: =IF(SUM(H24:N24)>1,1,0) -> 0 | V24: =IF(AND(G24>0,SUM(H24:N24)=0),1,0) -> 0 | W24: =IF(H24>0,1,0) -> 0
I25: =IF(T25+S25+U25+V25>0,"WARNING:","") | J25: =IF(S25>0,"Values above must be 1's or 0's",IF(T25>0,"NE and Ontario are not participating. These must be 0's",IF(U25>0,"Choose one location only",IF(V25>0,"You must select a location","")))) | S25: =SUM(S17:S24) -> 0 | T25: =SUM(T17:T24) -> 0 | U25: =SUM(U17:U24) -> 0 | V25: =SUM(V17:V24) -> 0 | W25: =SUM(W17:W24) -> 0
A26: Instructions:
A27: * Rest of State - New York Control Area outside of New York City & Long Island
B28: Do Not Delete Yellow Row
B29: Do Not Enter Information
D30: Contact Name: | K30: Contact Phone#:
B32: Your Name | C32: =+'Jan OPP'!C32 -> Your Name Goes Here | J32: Contact Phone#: | L32: =+'Jan OPP'!L32 -> Your Phone # Here
F33: Comments:
B34: Company Name: | C34: =+'Jan OPP'!C34 -> Company
B35: Company Address: | C35: =+'Jan OPP'!C35 -> Address 1
C36: =+'Jan OPP'!C36 -> Address 2
C37: =+'Jan OPP'!C37 -> Address 3
C38: =+'Jan OPP'!C38 -> City, State Zip
B40: Contact E-Mail: | C40: =+'Jan OPP'!C40 -> your @ address here
A79: Short Name | B79: Logical | C79: PTID | D79: Resource Name
A80: 1stRoch | B80: Y | C80: 1 | D80: ISOStrpS
A81: 3mP&P | B81: N | C81: 2 | D81: ISOMoMAY
A82: AdvantEn | C82: 3 | D82: ISODfMAY
A83: AEPSysOp | C83: 4 | D83: ISOSuMay
A84: AESCreRe | C84: 5 | D84: ISOMoJUN
A85: AESEastE | C85: 6 | D85: ISODfJUN
A86: AESNuEn | C86: 7 | D86: ISOSuJun
...

Sheet Mar OPP
D3: SUBMIT TO: | I3: New York Independent System Operator
D4: sellicap@nyiso.com | I4: Installed Capacity (UCAP) Strip Auction
I6: Offers to Sell
H7: Not To Be Used For The Strip Auction
D8: Auction Month: | E8: March | G8: 1 | K8: Date submitted: | M8: =+'Feb OPP'!M8 -> 36526
G9: Submittal Number | K9: Time submitted: | M9: =+'Feb OPP'!M9 -> 0.625
D11: Registrant Name:
B14: Seller's | F14: Minimum Price | G14: Amount (MW) | H14: Location ( indicate a (1) for chosen area and (0) for other areas)
A15: Offer# | B15: Name | C15: NYC | D15: PTID# | E15: Resource Name | F15: [($/kW- per month) | G15: [express to | H15: NYC | I15: LI | J15: ROS* | K15: PJM | L15: ISO-NE | M15: HQ | N15: O-IMO
C16: Mitigated | F16: express to nearest $.01] | G16: nearest 0.1 MW]
A17: 1 | B17: =IF(D17=0," ",+$E$11) | C17: N | E17: =IF(ISERROR(VLOOKUP(D17,$C$80:$D$700,2)),"",VLOOKUP(D17,$C$80:$D$700,2)) | H17: 0 | I17: 0 | J17: 0 | K17: 0 | L17: 0 | M17: 0 | N17: 0 | O17: =+$E$8 -> March | P17: =+$G$8 -> 1 | Q17: =+$M$8 -> 36526 | R17: =+$M$9 -> 0.625 | S17: =IF(AND(OR(H17=0,H17=1),OR(I17=0,I17=1),OR(J17=0,J17=1),OR(K17=0,K17=1),OR(L17=0,L17=1),OR(N17=0,N17=1),OR(M17=0,M17=1)),0,1) -> 0 | T17: =IF(L17+N17>0,1,0) -> 0 | U17: =IF(SUM(H17:N17)>1,1,0) -> 0 | V17: =IF(AND(G17>0,SUM(H17:N17)=0),1,0) -> 0 | W17: =IF(H17>0,1,0) -> 0
A18: =COUNT($A$17:A17)+1 -> 2 | B18: =IF(D18=0," ",+$E$11) | C18: N | E18: =IF(ISERROR(VLOOKUP(D18,$C$80:$D$700,2)),"",VLOOKUP(D18,$C$80:$D$700,2)) | H18: 0 | I18: 0 | J18: 0 | K18: 0 | L18: 0 | M18: 0 | N18: 0 | O18: =+$E$8 -> March | P18: =+$G$8 -> 1 | Q18: =+$M$8 -> 36526 | R18: =+$M$9 -> 0.625 | S18: =IF(AND(OR(H18=0,H18=1),OR(I18=0,I18=1),OR(J18=0,J18=1),OR(K18=0,K18=1),OR(L18=0,L18=1),OR(N18=0,N18=1),OR(M18=0,M18=1)),0,1) -> 0 | T18: =IF(L18+N18>0,1,0) -> 0 | U18: =IF(SUM(H18:N18)>1,1,0) -> 0 | V18: =IF(AND(G18>0,SUM(H18:N18)=0),1,0) -> 0 | W18: =IF(H18>0,1,0) -> 0
A19: =COUNT($A$17:A18)+1 -> 3 | B19: =IF(D19=0," ",+$E$11) | C19: N | E19: =IF(ISERROR(VLOOKUP(D19,$C$80:$D$700,2)),"",VLOOKUP(D19,$C$80:$D$700,2)) | H19: 0 | I19: 0 | J19: 0 | K19: 0 | L19: 0 | M19: 0 | N19: 0 | O19: =+$E$8 -> March | P19: =+$G$8 -> 1 | Q19: =+$M$8 -> 36526 | R19: =+$M$9 -> 0.625 | S19: =IF(AND(OR(H19=0,H19=1),OR(I19=0,I19=1),OR(J19=0,J19=1),OR(K19=0,K19=1),OR(L19=0,L19=1),OR(N19=0,N19=1),OR(M19=0,M19=1)),0,1) -> 0 | T19: =IF(L19+N19>0,1,0) -> 0 | U19: =IF(SUM(H19:N19)>1,1,0) -> 0 | V19: =IF(AND(G19>0,SUM(H19:N19)=0),1,0) -> 0 | W19: =IF(H19>0,1,0) -> 0
A20: =COUNT($A$17:A19)+1 -> 4 | B20: =IF(D20=0," ",+$E$11) | C20: N | E20: =IF(ISERROR(VLOOKUP(D20,$C$80:$D$700,2)),"",VLOOKUP(D20,$C$80:$D$700,2)) | H20: 0 | I20: 0 | J20: 0 | K20: 0 | L20: 0 | M20: 0 | N20: 0 | O20: =+$E$8 -> March | P20: =+$G$8 -> 1 | Q20: =+$M$8 -> 36526 | R20: =+$M$9 -> 0.625 | S20: =IF(AND(OR(H20=0,H20=1),OR(I20=0,I20=1),OR(J20=0,J20=1),OR(K20=0,K20=1),OR(L20=0,L20=1),OR(N20=0,N20=1),OR(M20=0,M20=1)),0,1) -> 0 | T20: =IF(L20+N20>0,1,0) -> 0 | U20: =IF(SUM(H20:N20)>1,1,0) -> 0 | V20: =IF(AND(G20>0,SUM(H20:N20)=0),1,0) -> 0 | W20: =IF(H20>0,1,0) -> 0
A21: =COUNT($A$17:A20)+1 -> 5 | B21: =IF(D21=0," ",+$E$11) | C21: N | E21: =IF(ISERROR(VLOOKUP(D21,$C$80:$D$700,2)),"",VLOOKUP(D21,$C$80:$D$700,2)) | H21: 0 | I21: 0 | J21: 0 | K21: 0 | L21: 0 | M21: 0 | N21: 0 | O21: =+$E$8 -> March | P21: =+$G$8 -> 1 | Q21: =+$M$8 -> 36526 | R21: =+$M$9 -> 0.625 | S21: =IF(AND(OR(H21=0,H21=1),OR(I21=0,I21=1),OR(J21=0,J21=1),OR(K21=0,K21=1),OR(L21=0,L21=1),OR(N21=0,N21=1),OR(M21=0,M21=1)),0,1) -> 0 | T21: =IF(L21+N21>0,1,0) -> 0 | U21: =IF(SUM(H21:N21)>1,1,0) -> 0 | V21: =IF(AND(G21>0,SUM(H21:N21)=0),1,0) -> 0 | W21: =IF(H21>0,1,0) -> 0
A22: =COUNT($A$17:A21)+1 -> 6 | B22: =IF(D22=0," ",+$E$11) | C22: N | E22: =IF(ISERROR(VLOOKUP(D22,$C$80:$D$700,2)),"",VLOOKUP(D22,$C$80:$D$700,2)) | H22: 0 | I22: 0 | J22: 0 | K22: 0 | L22: 0 | M22: 0 | N22: 0 | O22: =+$E$8 -> March | P22: =+$G$8 -> 1 | Q22: =+$M$8 -> 36526 | R22: =+$M$9 -> 0.625 | S22: =IF(AND(OR(H22=0,H22=1),OR(I22=0,I22=1),OR(J22=0,J22=1),OR(K22=0,K22=1),OR(L22=0,L22=1),OR(N22=0,N22=1),OR(M22=0,M22=1)),0,1) -> 0 | T22: =IF(L22+N22>0,1,0) -> 0 | U22: =IF(SUM(H22:N22)>1,1,0) -> 0 | V22: =IF(AND(G22>0,SUM(H22:N22)=0),1,0) -> 0 | W22: =IF(H22>0,1,0) -> 0
A23: =COUNT($A$17:A22)+1 -> 7 | B23: =IF(D23=0," ",+$E$11) | C23: N | E23: =IF(ISERROR(VLOOKUP(D23,$C$80:$D$700,2)),"",VLOOKUP(D23,$C$80:$D$700,2)) | H23: 0 | I23: 0 | J23: 0 | K23: 0 | L23: 0 | M23: 0 | N23: 0 | O23: =+$E$8 -> March | P23: =+$G$8 -> 1 | Q23: =+$M$8 -> 36526 | R23: =+$M$9 -> 0.625 | S23: =IF(AND(OR(H23=0,H23=1),OR(I23=0,I23=1),OR(J23=0,J23=1),OR(K23=0,K23=1),OR(L23=0,L23=1),OR(N23=0,N23=1),OR(M23=0,M23=1)),0,1) -> 0 | T23: =IF(L23+N23>0,1,0) -> 0 | U23: =IF(SUM(H23:N23)>1,1,0) -> 0 | V23: =IF(AND(G23>0,SUM(H23:N23)=0),1,0) -> 0 | W23: =IF(H23>0,1,0) -> 0
A24: =COUNT($A$17:A23)+1 -> 8 | B24: =IF(D24=0," ",+$E$11) | C24: N | E24: =IF(ISERROR(VLOOKUP(D24,$C$80:$D$700,2)),"",VLOOKUP(D24,$C$80:$D$700,2)) | H24: 0 | I24: 0 | J24: 0 | K24: 0 | L24: 0 | M24: 0 | N24: 0 | O24: =+$E$8 -> March | P24: =+$G$8 -> 1 | Q24: =+$M$8 -> 36526 | R24: =+$M$9 -> 0.625 | S24: =IF(AND(OR(H24=0,H24=1),OR(I24=0,I24=1),OR(J24=0,J24=1),OR(K24=0,K24=1),OR(L24=0,L24=1),OR(N24=0,N24=1),OR(M24=0,M24=1)),0,1) -> 0 | T24: =IF(L24+N24>0,1,0) -> 0 | U24: =IF(SUM(H24:N24)>1,1,0) -> 0 | V24: =IF(AND(G24>0,SUM(H24:N24)=0),1,0) -> 0 | W24: =IF(H24>0,1,0) -> 0
I25: =IF(T25+S25+U25+V25>0,"WARNING:","") | J25: =IF(S25>0,"Values above must be 1's or 0's",IF(T25>0,"NE and Ontario are not participating. These must be 0's",IF(U25>0,"Choose one location only",IF(V25>0,"You must select a location","")))) | S25: =SUM(S17:S24) -> 0 | T25: =SUM(T17:T24) -> 0 | U25: =SUM(U17:U24) -> 0 | V25: =SUM(V17:V24) -> 0 | W25: =SUM(W17:W24) -> 0
A26: Instructions:
A27: * Rest of State - New York Control Area outside of New York City & Long Island
B28: Do Not Delete Yellow Row
B29: Do Not Enter Information
D30: Contact Name: | K30: Contact Phone#:
B32: Your Name | C32: =+'Feb OPP'!C32 -> Your Name Goes Here | J32: Contact Phone#: | L32: =+'Feb OPP'!L32 -> Your Phone # Here
F33: Comments:
B34: Company Name: | C34: =+'Feb OPP'!C34 -> Company
B35: Company Address: | C35: =+'Feb OPP'!C35 -> Address 1
C36: =+'Feb OPP'!C36 -> Address 2
C37: =+'Feb OPP'!C37 -> Address 3
C38: =+'Feb OPP'!C38 -> City, State Zip
B40: Contact E-Mail: | C40: =+'Feb OPP'!C40 -> your @ address here
A79: Short Name | B79: Logical | C79: PTID | D79: Resource Name
A80: 1stRoch | B80: Y | C80: 1 | D80: ISOStrpS
A81: 3mP&P | B81: N | C81: 2 | D81: ISOMoMAY
A82: AdvantEn | C82: 3 | D82: ISODfMAY
A83: AEPSysOp | C83: 4 | D83: ISOSuMay
A84: AESCreRe | C84: 5 | D84: ISOMoJUN
A85: AESEastE | C85: 6 | D85: ISODfJUN
A86: AESNuEn | C86: 7 | D86: ISOSuJun
...

Sheet Apr OPP
D3: SUBMIT TO: | I3: New York Independent System Operator
D4: sellicap@nyiso.com | I4: Installed Capacity (UCAP) Strip Auction
I6: Offers to Sell
H7: Not To Be Used For The Strip Auction
D8: Auction Month: | E8: April | G8: 1 | K8: Date submitted: | M8: =+'Mar OPP'!M8 -> 36526
G9: Submittal Number | K9: Time submitted: | M9: =+'Mar OPP'!M9 -> 0.625
D11: Registrant Name:
B14: Seller's | F14: Minimum Price | G14: Amount (MW) | H14: Location ( indicate a (1) for chosen area and (0) for other areas)
A15: Offer# | B15: Name | C15: NYC | D15: PTID# | E15: Resource Name | F15: [($/kW- per month) | G15: [express to | H15: NYC | I15: LI | J15: ROS* | K15: PJM | L15: ISO-NE | M15: HQ | N15: O-IMO
C16: Mitigated | F16: express to nearest $.01] | G16: nearest 0.1 MW]
A17: 1 | B17: =IF(D17=0," ",+$E$11) | C17: N | E17: =IF(ISERROR(VLOOKUP(D17,$C$80:$D$700,2)),"",VLOOKUP(D17,$C$80:$D$700,2)) | H17: 0 | I17: 0 | J17: 0 | K17: 0 | L17: 0 | M17: 0 | N17: 0 | O17: =+$E$8 -> April | P17: =+$G$8 -> 1 | Q17: =+$M$8 -> 36526 | R17: =+$M$9 -> 0.625 | S17: =IF(AND(OR(H17=0,H17=1),OR(I17=0,I17=1),OR(J17=0,J17=1),OR(K17=0,K17=1),OR(L17=0,L17=1),OR(N17=0,N17=1),OR(M17=0,M17=1)),0,1) -> 0 | T17: =IF(L17+N17>0,1,0) -> 0 | U17: =IF(SUM(H17:N17)>1,1,0) -> 0 | V17: =IF(AND(G17>0,SUM(H17:N17)=0),1,0) -> 0 | W17: =IF(H17>0,1,0) -> 0
A18: =COUNT($A$17:A17)+1 -> 2 | B18: =IF(D18=0," ",+$E$11) | C18: N | E18: =IF(ISERROR(VLOOKUP(D18,$C$80:$D$700,2)),"",VLOOKUP(D18,$C$80:$D$700,2)) | H18: 0 | I18: 0 | J18: 0 | K18: 0 | L18: 0 | M18: 0 | N18: 0 | O18: =+$E$8 -> April | P18: =+$G$8 -> 1 | Q18: =+$M$8 -> 36526 | R18: =+$M$9 -> 0.625 | S18: =IF(AND(OR(H18=0,H18=1),OR(I18=0,I18=1),OR(J18=0,J18=1),OR(K18=0,K18=1),OR(L18=0,L18=1),OR(N18=0,N18=1),OR(M18=0,M18=1)),0,1) -> 0 | T18: =IF(L18+N18>0,1,0) -> 0 | U18: =IF(SUM(H18:N18)>1,1,0) -> 0 | V18: =IF(AND(G18>0,SUM(H18:N18)=0),1,0) -> 0 | W18: =IF(H18>0,1,0) -> 0
A19: =COUNT($A$17:A18)+1 -> 3 | B19: =IF(D19=0," ",+$E$11) | C19: N | E19: =IF(ISERROR(VLOOKUP(D19,$C$80:$D$700,2)),"",VLOOKUP(D19,$C$80:$D$700,2)) | H19: 0 | I19: 0 | J19: 0 | K19: 0 | L19: 0 | M19: 0 | N19: 0 | O19: =+$E$8 -> April | P19: =+$G$8 -> 1 | Q19: =+$M$8 -> 36526 | R19: =+$M$9 -> 0.625 | S19: =IF(AND(OR(H19=0,H19=1),OR(I19=0,I19=1),OR(J19=0,J19=1),OR(K19=0,K19=1),OR(L19=0,L19=1),OR(N19=0,N19=1),OR(M19=0,M19=1)),0,1) -> 0 | T19: =IF(L19+N19>0,1,0) -> 0 | U19: =IF(SUM(H19:N19)>1,1,0) -> 0 | V19: =IF(AND(G19>0,SUM(H19:N19)=0),1,0) -> 0 | W19: =IF(H19>0,1,0) -> 0
A20: =COUNT($A$17:A19)+1 -> 4 | B20: =IF(D20=0," ",+$E$11) | C20: N | E20: =IF(ISERROR(VLOOKUP(D20,$C$80:$D$700,2)),"",VLOOKUP(D20,$C$80:$D$700,2)) | H20: 0 | I20: 0 | J20: 0 | K20: 0 | L20: 0 | M20: 0 | N20: 0 | O20: =+$E$8 -> April | P20: =+$G$8 -> 1 | Q20: =+$M$8 -> 36526 | R20: =+$M$9 -> 0.625 | S20: =IF(AND(OR(H20=0,H20=1),OR(I20=0,I20=1),OR(J20=0,J20=1),OR(K20=0,K20=1),OR(L20=0,L20=1),OR(N20=0,N20=1),OR(M20=0,M20=1)),0,1) -> 0 | T20: =IF(L20+N20>0,1,0) -> 0 | U20: =IF(SUM(H20:N20)>1,1,0) -> 0 | V20: =IF(AND(G20>0,SUM(H20:N20)=0),1,0) -> 0 | W20: =IF(H20>0,1,0) -> 0
A21: =COUNT($A$17:A20)+1 -> 5 | B21: =IF(D21=0," ",+$E$11) | C21: N | E21: =IF(ISERROR(VLOOKUP(D21,$C$80:$D$700,2)),"",VLOOKUP(D21,$C$80:$D$700,2)) | H21: 0 | I21: 0 | J21: 0 | K21: 0 | L21: 0 | M21: 0 | N21: 0 | O21: =+$E$8 -> April | P21: =+$G$8 -> 1 | Q21: =+$M$8 -> 36526 | R21: =+$M$9 -> 0.625 | S21: =IF(AND(OR(H21=0,H21=1),OR(I21=0,I21=1),OR(J21=0,J21=1),OR(K21=0,K21=1),OR(L21=0,L21=1),OR(N21=0,N21=1),OR(M21=0,M21=1)),0,1) -> 0 | T21: =IF(L21+N21>0,1,0) -> 0 | U21: =IF(SUM(H21:N21)>1,1,0) -> 0 | V21: =IF(AND(G21>0,SUM(H21:N21)=0),1,0) -> 0 | W21: =IF(H21>0,1,0) -> 0
A22: =COUNT($A$17:A21)+1 -> 6 | B22: =IF(D22=0," ",+$E$11) | C22: N | E22: =IF(ISERROR(VLOOKUP(D22,$C$80:$D$700,2)),"",VLOOKUP(D22,$C$80:$D$700,2)) | H22: 0 | I22: 0 | J22: 0 | K22: 0 | L22: 0 | M22: 0 | N22: 0 | O22: =+$E$8 -> April | P22: =+$G$8 -> 1 | Q22: =+$M$8 -> 36526 | R22: =+$M$9 -> 0.625 | S22: =IF(AND(OR(H22=0,H22=1),OR(I22=0,I22=1),OR(J22=0,J22=1),OR(K22=0,K22=1),OR(L22=0,L22=1),OR(N22=0,N22=1),OR(M22=0,M22=1)),0,1) -> 0 | T22: =IF(L22+N22>0,1,0) -> 0 | U22: =IF(SUM(H22:N22)>1,1,0) -> 0 | V22: =IF(AND(G22>0,SUM(H22:N22)=0),1,0) -> 0 | W22: =IF(H22>0,1,0) -> 0
A23: =COUNT($A$17:A22)+1 -> 7 | B23: =IF(D23=0," ",+$E$11) | C23: N | E23: =IF(ISERROR(VLOOKUP(D23,$C$80:$D$700,2)),"",VLOOKUP(D23,$C$80:$D$700,2)) | H23: 0 | I23: 0 | J23: 0 | K23: 0 | L23: 0 | M23: 0 | N23: 0 | O23: =+$E$8 -> April | P23: =+$G$8 -> 1 | Q23: =+$M$8 -> 36526 | R23: =+$M$9 -> 0.625 | S23: =IF(AND(OR(H23=0,H23=1),OR(I23=0,I23=1),OR(J23=0,J23=1),OR(K23=0,K23=1),OR(L23=0,L23=1),OR(N23=0,N23=1),OR(M23=0,M23=1)),0,1) -> 0 | T23: =IF(L23+N23>0,1,0) -> 0 | U23: =IF(SUM(H23:N23)>1,1,0) -> 0 | V23: =IF(AND(G23>0,SUM(H23:N23)=0),1,0) -> 0 | W23: =IF(H23>0,1,0) -> 0
A24: =COUNT($A$17:A23)+1 -> 8 | B24: =IF(D24=0," ",+$E$11) | C24: N | E24: =IF(ISERROR(VLOOKUP(D24,$C$80:$D$700,2)),"",VLOOKUP(D24,$C$80:$D$700,2)) | H24: 0 | I24: 0 | J24: 0 | K24: 0 | L24: 0 | M24: 0 | N24: 0 | O24: =+$E$8 -> April | P24: =+$G$8 -> 1 | Q24: =+$M$8 -> 36526 | R24: =+$M$9 -> 0.625 | S24: =IF(AND(OR(H24=0,H24=1),OR(I24=0,I24=1),OR(J24=0,J24=1),OR(K24=0,K24=1),OR(L24=0,L24=1),OR(N24=0,N24=1),OR(M24=0,M24=1)),0,1) -> 0 | T24: =IF(L24+N24>0,1,0) -> 0 | U24: =IF(SUM(H24:N24)>1,1,0) -> 0 | V24: =IF(AND(G24>0,SUM(H24:N24)=0),1,0) -> 0 | W24: =IF(H24>0,1,0) -> 0
I25: =IF(T25+S25+U25+V25>0,"WARNING:","") | J25: =IF(S25>0,"Values above must be 1's or 0's",IF(T25>0,"NE and Ontario are not participating. These must be 0's",IF(U25>0,"Choose one location only",IF(V25>0,"You must select a location","")))) | S25: =SUM(S17:S24) -> 0 | T25: =SUM(T17:T24) -> 0 | U25: =SUM(U17:U24) -> 0 | V25: =SUM(V17:V24) -> 0 | W25: =SUM(W17:W24) -> 0
A26: Instructions:
A27: * Rest of State - New York Control Area outside of New York City & Long Island
B28: Do Not Delete Yellow Row
B29: Do Not Enter Information
D30: Contact Name: | K30: Contact Phone#:
B32: Your Name | C32: =+'Mar OPP'!C32 -> Your Name Goes Here | J32: Contact Phone#: | L32: =+'Mar OPP'!L32 -> Your Phone # Here
F33: Comments:
B34: Company Name: | C34: =+'Mar OPP'!C34 -> Company
B35: Company Address: | C35: =+'Mar OPP'!C35 -> Address 1
C36: =+'Mar OPP'!C36 -> Address 2
C37: =+'Mar OPP'!C37 -> Address 3
C38: =+'Mar OPP'!C38 -> City, State Zip
B40: Contact E-Mail: | C40: =+'Mar OPP'!C40 -> your @ address here
A79: Short Name | B79: Logical | C79: PTID | D79: Resource Name
A80: 1stRoch | B80: Y | C80: 1 | D80: ISOStrpS
A81: 3mP&P | B81: N | C81: 2 | D81: ISOMoMAY
A82: AdvantEn | C82: 3 | D82: ISODfMAY
A83: AEPSysOp | C83: 4 | D83: ISOSuMay
A84: AESCreRe | C84: 5 | D84: ISOMoJUN
A85: AESEastE | C85: 6 | D85: ISODfJUN
A86: AESNuEn | C86: 7 | D86: ISOSuJun
...

Sheet Strip Award
A13: If you change the size of the table, MAKE SURE that you copy the contents of range B17:F17 to area B18:F (bottom)
A16: Offer# | B16: PTID# | C16: Minimum Price Offered [($/kW- 6 month) express to nearest $.01] | D16: Amount (MW) [expressed to nearest 0.1 MW] | E16: Loc. | F16: Amount (MW) Sold | G16: Market Clearing Price | H16: Sold Amount $ | I16: NYC Mitigated
A17: 1 | B17: =+'Offers-Strip'!D17 -> 0 | C17: =+'Offers-Strip'!F17 -> 0 | D17: =+'Offers-Strip'!G17 -> 0 | E17: =IF('Offers-Strip'!G17=0," ",IF('Offers-Strip'!H17=1,"NYC",IF('Offers-Strip'!I17=1,"LI",IF('Offers-Strip'!J17=1,"ROS",IF('Offers-Strip'!K17=1,"NE",IF('Offers-Strip'!L17=1,"NE",IF('Offers-Strip'!M17=1,"HQ",IF('Offers-Strip'!N17=1,"OH"," ")))))))) | H17: =F17*G17*1000 -> 0 | I17: =+'Offers-Strip'!C17 -> N
A18: =COUNT($A$17:A17)+1 -> 2 | B18: =+'Offers-Strip'!D18 -> 0 | C18: =+'Offers-Strip'!F18 -> 0 | D18: =+'Offers-Strip'!G18 -> 0 | E18: =IF('Offers-Strip'!G18=0," ",IF('Offers-Strip'!H18=1,"NYC",IF('Offers-Strip'!I18=1,"LI",IF('Offers-Strip'!J18=1,"ROS",IF('Offers-Strip'!K18=1,"NE",IF('Offers-Strip'!L18=1,"NE",IF('Offers-Strip'!M18=1,"HQ",IF('Offers-Strip'!N18=1,"OH"," ")))))))) | H18: =F18*G18*1000 -> 0 | I18: =+'Offers-Strip'!C18 -> N
A19: =COUNT($A$17:A18)+1 -> 3 | B19: =+'Offers-Strip'!D19 -> 0 | C19: =+'Offers-Strip'!F19 -> 0 | D19: =+'Offers-Strip'!G19 -> 0 | E19: =IF('Offers-Strip'!G19=0," ",IF('Offers-Strip'!H19=1,"NYC",IF('Offers-Strip'!I19=1,"LI",IF('Offers-Strip'!J19=1,"ROS",IF('Offers-Strip'!K19=1,"NE",IF('Offers-Strip'!L19=1,"NE",IF('Offers-Strip'!M19=1,"HQ",IF('Offers-Strip'!N19=1,"OH"," ")))))))) | H19: =F19*G19*1000 -> 0 | I19: =+'Offers-Strip'!C19 -> N
A20: =COUNT($A$17:A19)+1 -> 4 | B20: =+'Offers-Strip'!D20 -> 0 | C20: =+'Offers-Strip'!F20 -> 0 | D20: =+'Offers-Strip'!G20 -> 0 | E20: =IF('Offers-Strip'!G20=0," ",IF('Offers-Strip'!H20=1,"NYC",IF('Offers-Strip'!I20=1,"LI",IF('Offers-Strip'!J20=1,"ROS",IF('Offers-Strip'!K20=1,"NE",IF('Offers-Strip'!L20=1,"NE",IF('Offers-Strip'!M20=1,"HQ",IF('Offers-Strip'!N20=1,"OH"," ")))))))) | H20: =F20*G20*1000 -> 0 | I20: =+'Offers-Strip'!C20 -> N
A21: =COUNT($A$17:A20)+1 -> 5 | B21: =+'Offers-Strip'!D21 -> 0 | C21: =+'Offers-Strip'!F21 -> 0 | D21: =+'Offers-Strip'!G21 -> 0 | E21: =IF('Offers-Strip'!G21=0," ",IF('Offers-Strip'!H21=1,"NYC",IF('Offers-Strip'!I21=1,"LI",IF('Offers-Strip'!J21=1,"ROS",IF('Offers-Strip'!K21=1,"NE",IF('Offers-Strip'!L21=1,"NE",IF('Offers-Strip'!M21=1,"HQ",IF('Offers-Strip'!N21=1,"OH"," ")))))))) | H21: =F21*G21*1000 -> 0 | I21: =+'Offers-Strip'!C21 -> N
A22: =COUNT($A$17:A21)+1 -> 6 | B22: =+'Offers-Strip'!D22 -> 0 | C22: =+'Offers-Strip'!F22 -> 0 | D22: =+'Offers-Strip'!G22 -> 0 | E22: =IF('Offers-Strip'!G22=0," ",IF('Offers-Strip'!H22=1,"NYC",IF('Offers-Strip'!I22=1,"LI",IF('Offers-Strip'!J22=1,"ROS",IF('Offers-Strip'!K22=1,"NE",IF('Offers-Strip'!L22=1,"NE",IF('Offers-Strip'!M22=1,"HQ",IF('Offers-Strip'!N22=1,"OH"," ")))))))) | H22: =F22*G22*1000 -> 0 | I22: =+'Offers-Strip'!C22 -> N
A23: =COUNT($A$17:A22)+1 -> 7 | B23: =+'Offers-Strip'!D23 -> 0 | C23: =+'Offers-Strip'!F23 -> 0 | D23: =+'Offers-Strip'!G23 -> 0 | E23: =IF('Offers-Strip'!G23=0," ",IF('Offers-Strip'!H23=1,"NYC",IF('Offers-Strip'!I23=1,"LI",IF('Offers-Strip'!J23=1,"ROS",IF('Offers-Strip'!K23=1,"NE",IF('Offers-Strip'!L23=1,"NE",IF('Offers-Strip'!M23=1,"HQ",IF('Offers-Strip'!N23=1,"OH"," ")))))))) | H23: =F23*G23*1000 -> 0 | I23: =+'Offers-Strip'!C23 -> N
A24: =COUNT($A$17:A23)+1 -> 8 | B24: =+'Offers-Strip'!D24 -> 0 | C24: =+'Offers-Strip'!F24 -> 0 | D24: =+'Offers-Strip'!G24 -> 0 | E24: =IF('Offers-Strip'!G24=0," ",IF('Offers-Strip'!H24=1,"NYC",IF('Offers-Strip'!I24=1,"LI",IF('Offers-Strip'!J24=1,"ROS",IF('Offers-Strip'!K24=1,"NE",IF('Offers-Strip'!L24=1,"NE",IF('Offers-Strip'!M24=1,"HQ",IF('Offers-Strip'!N24=1,"OH"," ")))))))) | H24: =F24*G24*1000 -> 0 | I24: =+'Offers-Strip'!C24 -> N
C25: Period Purchased: | D25: =+'Offers-Strip'!E8 -> 0 | F25: Total Value Sold | H25: =SUM(H17:H24) -> 0

Sheet Monthly OPP Awards
A1: Delete Rows working from the last month and work yourself up to current. Deleting top down will cause errors.
A2: Insert Rows working from the last month and work yourself up to current. Inserting top down will cause errors.
I3: If you change the size of the table, MAKE SURE that you copy the contents of the
I4: first tabel row B:F to the end of the table area B:F
A5: Offer# | B5: PTID# | C5: Minimum Price Offered [($/kW- per month) express to nearest $.01] | D5: Amount (MW) [expressed to nearest 0.1 MW] | E5: Loc. | F5: Amount (MW) Sold | G5: Market Clearing Price | H5: Sold Amount $ | I5: NYC Mitigated
A6: 1 | B6: =+'Nov OPP'!D17 -> 0 | C6: =+'Nov OPP'!F17 -> 0 | D6: =+'Nov OPP'!G17 -> 0 | E6: =IF('Nov OPP'!G17=0," ",IF('Nov OPP'!H17=1,"NYC",IF('Nov OPP'!I17=1,"LI",IF('Nov OPP'!J17=1,"ROS",IF('Nov OPP'!K17=1,"NE",IF('Nov OPP'!L17=1,"NE",IF('Nov OPP'!M17=1,"HQ",IF('Nov OPP'!N17=1,"OH"," ")))))))) | H6: =F6*G6*1000 -> 0 | I6: =+'Nov OPP'!C17 -> N | J6: =+IF(+SUM(A6:A13)<SUM('Nov OPP'!$A$17:$A$24),"INSERT Rows",IF(SUM(A6:A13)>SUM('Nov OPP'!$A$17:$A$24)," DELETE Rows"," "))
A7: =COUNT($A$6:A6)+1 -> 2 | B7: =+'Nov OPP'!D18 -> 0 | C7: =+'Nov OPP'!F18 -> 0 | D7: =+'Nov OPP'!G18 -> 0 | E7: =IF('Nov OPP'!G18=0," ",IF('Nov OPP'!H18=1,"NYC",IF('Nov OPP'!I18=1,"LI",IF('Nov OPP'!J18=1,"ROS",IF('Nov OPP'!K18=1,"NE",IF('Nov OPP'!L18=1,"NE",IF('Nov OPP'!M18=1,"HQ",IF('Nov OPP'!N18=1,"OH"," ")))))))) | H7: =F7*G7*1000 -> 0 | I7: =+'Nov OPP'!C18 -> N
A8: =COUNT($A$6:A7)+1 -> 3 | B8: =+'Nov OPP'!D19 -> 0 | C8: =+'Nov OPP'!F19 -> 0 | D8: =+'Nov OPP'!G19 -> 0 | E8: =IF('Nov OPP'!G19=0," ",IF('Nov OPP'!H19=1,"NYC",IF('Nov OPP'!I19=1,"LI",IF('Nov OPP'!J19=1,"ROS",IF('Nov OPP'!K19=1,"NE",IF('Nov OPP'!L19=1,"NE",IF('Nov OPP'!M19=1,"HQ",IF('Nov OPP'!N19=1,"OH"," ")))))))) | H8: =F8*G8*1000 -> 0 | I8: =+'Nov OPP'!C19 -> N
A9: =COUNT($A$6:A8)+1 -> 4 | B9: =+'Nov OPP'!D20 -> 0 | C9: =+'Nov OPP'!F20 -> 0 | D9: =+'Nov OPP'!G20 -> 0 | E9: =IF('Nov OPP'!G20=0," ",IF('Nov OPP'!H20=1,"NYC",IF('Nov OPP'!I20=1,"LI",IF('Nov OPP'!J20=1,"ROS",IF('Nov OPP'!K20=1,"NE",IF('Nov OPP'!L20=1,"NE",IF('Nov OPP'!M20=1,"HQ",IF('Nov OPP'!N20=1,"OH"," ")))))))) | H9: =F9*G9*1000 -> 0 | I9: =+'Nov OPP'!C20 -> N
A10: =COUNT($A$6:A9)+1 -> 5 | B10: =+'Nov OPP'!D21 -> 0 | C10: =+'Nov OPP'!F21 -> 0 | D10: =+'Nov OPP'!G21 -> 0 | E10: =IF('Nov OPP'!G21=0," ",IF('Nov OPP'!H21=1,"NYC",IF('Nov OPP'!I21=1,"LI",IF('Nov OPP'!J21=1,"ROS",IF('Nov OPP'!K21=1,"NE",IF('Nov OPP'!L21=1,"NE",IF('Nov OPP'!M21=1,"HQ",IF('Nov OPP'!N21=1,"OH"," ")))))))) | H10: =F10*G10*1000 -> 0 | I10: =+'Nov OPP'!C21 -> N
A11: =COUNT($A$6:A10)+1 -> 6 | B11: =+'Nov OPP'!D22 -> 0 | C11: =+'Nov OPP'!F22 -> 0 | D11: =+'Nov OPP'!G22 -> 0 | E11: =IF('Nov OPP'!G22=0," ",IF('Nov OPP'!H22=1,"NYC",IF('Nov OPP'!I22=1,"LI",IF('Nov OPP'!J22=1,"ROS",IF('Nov OPP'!K22=1,"NE",IF('Nov OPP'!L22=1,"NE",IF('Nov OPP'!M22=1,"HQ",IF('Nov OPP'!N22=1,"OH"," ")))))))) | H11: =F11*G11*1000 -> 0 | I11: =+'Nov OPP'!C22 -> N
A12: =COUNT($A$6:A11)+1 -> 7 | B12: =+'Nov OPP'!D23 -> 0 | C12: =+'Nov OPP'!F23 -> 0 | D12: =+'Nov OPP'!G23 -> 0 | E12: =IF('Nov OPP'!G23=0," ",IF('Nov OPP'!H23=1,"NYC",IF('Nov OPP'!I23=1,"LI",IF('Nov OPP'!J23=1,"ROS",IF('Nov OPP'!K23=1,"NE",IF('Nov OPP'!L23=1,"NE",IF('Nov OPP'!M23=1,"HQ",IF('Nov OPP'!N23=1,"OH"," ")))))))) | H12: =F12*G12*1000 -> 0 | I12: =+'Nov OPP'!C23 -> N
A13: =COUNT($A$6:A12)+1 -> 8 | B13: =+'Nov OPP'!D24 -> 0 | C13: =+'Nov OPP'!F24 -> 0 | D13: =+'Nov OPP'!G24 -> 0 | E13: =IF('Nov OPP'!G24=0," ",IF('Nov OPP'!H24=1,"NYC",IF('Nov OPP'!I24=1,"LI",IF('Nov OPP'!J24=1,"ROS",IF('Nov OPP'!K24=1,"NE",IF('Nov OPP'!L24=1,"NE",IF('Nov OPP'!M24=1,"HQ",IF('Nov OPP'!N24=1,"OH"," ")))))))) | H13: =F13*G13*1000 -> 0 | I13: =+'Nov OPP'!C24 -> N
